package zollernextras.worldgen.upsidedown;

import java.util.Random;
import net.minecraft.init.Blocks;
import net.minecraft.world.World;
import net.minecraft.world.gen.feature.WorldGenerator;
import zollernextras.blocks.BlockList;
import zollernextras.lib.MainHelper;
import zollernextras.lib.Treasures;
import zollernextras.lib.ZEChestGenHooks;
import zollernextras.mobs.entities.boss.EntityShadowAlien;

public class WorldGenShadowShrine extends WorldGenerator {
	
	@Override
	public boolean generate(World world, Random rand, int i, int j, int k) {
		
		j -= 2;
		
		if (world.getBlock(i, j + 1, k) == Blocks.air) {
			return false;
		}
		
		world.setBlock(i + 0, j + 0, k + 0, BlockList.netherizedObsidian);
		world.setBlock(i + 0, j + 0, k + 1, BlockList.netherizedObsidian);
		world.setBlock(i + 0, j + 0, k + 2, BlockList.netherizedObsidian);
		world.setBlock(i + 0, j + 0, k + 3, BlockList.netherizedObsidian);
		world.setBlock(i + 0, j + 0, k + 4, BlockList.netherizedObsidian);
		world.setBlock(i + 0, j + 0, k + 5, BlockList.netherizedObsidian);
		world.setBlock(i + 0, j + 0, k + 6, BlockList.netherizedObsidian);
		world.setBlock(i + 0, j + 0, k + 7, BlockList.netherizedObsidian);
		world.setBlock(i + 0, j + 0, k + 8, BlockList.netherizedObsidian);
		world.setBlock(i + 0, j + 0, k + 9, BlockList.netherizedObsidian);
		world.setBlock(i + 0, j + 0, k + 10, BlockList.netherizedObsidian);
		world.setBlock(i + 0, j + 0, k + 11, BlockList.netherizedObsidian);
		world.setBlock(i + 0, j + 0, k + 12, BlockList.netherizedObsidian);
		world.setBlock(i + 0, j + 0, k + 13, BlockList.netherizedObsidian);
		world.setBlock(i + 0, j + 0, k + 14, BlockList.netherizedObsidian);
		world.setBlock(i + 0, j + 0, k + 15, BlockList.netherizedObsidian);
		world.setBlock(i + 0, j + 0, k + 16, BlockList.netherizedObsidian);
		world.setBlock(i + 0, j + 0, k + 17, BlockList.netherizedObsidian);
		world.setBlock(i + 1, j + 0, k + 0, BlockList.netherizedObsidian);
		world.setBlock(i + 1, j + 0, k + 1, Blocks.obsidian);
		world.setBlock(i + 1, j + 0, k + 2, Blocks.obsidian);
		world.setBlock(i + 1, j + 0, k + 3, Blocks.obsidian);
		world.setBlock(i + 1, j + 0, k + 4, Blocks.obsidian);
		world.setBlock(i + 1, j + 0, k + 5, Blocks.obsidian);
		world.setBlock(i + 1, j + 0, k + 6, Blocks.obsidian);
		world.setBlock(i + 1, j + 0, k + 7, Blocks.obsidian);
		world.setBlock(i + 1, j + 0, k + 8, Blocks.obsidian);
		world.setBlock(i + 1, j + 0, k + 9, Blocks.obsidian);
		world.setBlock(i + 1, j + 0, k + 10, Blocks.obsidian);
		world.setBlock(i + 1, j + 0, k + 11, Blocks.obsidian);
		world.setBlock(i + 1, j + 0, k + 12, Blocks.obsidian);
		world.setBlock(i + 1, j + 0, k + 13, Blocks.obsidian);
		world.setBlock(i + 1, j + 0, k + 14, Blocks.obsidian);
		world.setBlock(i + 1, j + 0, k + 15, Blocks.obsidian);
		world.setBlock(i + 1, j + 0, k + 16, Blocks.obsidian);
		world.setBlock(i + 1, j + 0, k + 17, BlockList.netherizedObsidian);
		world.setBlock(i + 1, j + 1, k + 1, BlockList.netherizedObsidian);
		world.setBlock(i + 1, j + 1, k + 2, BlockList.netherizedObsidian);
		world.setBlock(i + 1, j + 1, k + 3, BlockList.netherizedObsidian);
		world.setBlock(i + 1, j + 1, k + 4, BlockList.netherizedObsidian);
		world.setBlock(i + 1, j + 1, k + 5, BlockList.netherizedObsidian);
		world.setBlock(i + 1, j + 1, k + 6, BlockList.netherizedObsidian);
		world.setBlock(i + 1, j + 1, k + 7, BlockList.netherizedObsidian);
		world.setBlock(i + 1, j + 1, k + 8, BlockList.netherizedObsidian);
		world.setBlock(i + 1, j + 1, k + 9, BlockList.netherizedObsidian);
		world.setBlock(i + 1, j + 1, k + 10, BlockList.netherizedObsidian);
		world.setBlock(i + 1, j + 1, k + 11, BlockList.netherizedObsidian);
		world.setBlock(i + 1, j + 1, k + 12, BlockList.netherizedObsidian);
		world.setBlock(i + 1, j + 1, k + 13, BlockList.netherizedObsidian);
		world.setBlock(i + 1, j + 1, k + 14, BlockList.netherizedObsidian);
		world.setBlock(i + 1, j + 1, k + 15, BlockList.netherizedObsidian);
		world.setBlock(i + 1, j + 1, k + 16, BlockList.netherizedObsidian);
		world.setBlock(i + 2, j + 0, k + 0, BlockList.netherizedObsidian);
		world.setBlock(i + 2, j + 0, k + 1, Blocks.obsidian);
		world.setBlock(i + 2, j + 0, k + 2, Blocks.obsidian);
		world.setBlock(i + 2, j + 0, k + 3, Blocks.obsidian);
		world.setBlock(i + 2, j + 0, k + 4, Blocks.obsidian);
		world.setBlock(i + 2, j + 0, k + 5, Blocks.obsidian);
		world.setBlock(i + 2, j + 0, k + 6, Blocks.obsidian);
		world.setBlock(i + 2, j + 0, k + 7, Blocks.obsidian);
		world.setBlock(i + 2, j + 0, k + 8, Blocks.obsidian);
		world.setBlock(i + 2, j + 0, k + 9, Blocks.obsidian);
		world.setBlock(i + 2, j + 0, k + 10, Blocks.obsidian);
		world.setBlock(i + 2, j + 0, k + 11, Blocks.obsidian);
		world.setBlock(i + 2, j + 0, k + 12, Blocks.obsidian);
		world.setBlock(i + 2, j + 0, k + 13, Blocks.obsidian);
		world.setBlock(i + 2, j + 0, k + 14, Blocks.obsidian);
		world.setBlock(i + 2, j + 0, k + 15, Blocks.obsidian);
		world.setBlock(i + 2, j + 0, k + 16, Blocks.obsidian);
		world.setBlock(i + 2, j + 0, k + 17, BlockList.netherizedObsidian);
		world.setBlock(i + 2, j + 1, k + 1, BlockList.netherizedObsidian);
		world.setBlock(i + 2, j + 1, k + 16, BlockList.netherizedObsidian);
		world.setBlock(i + 2, j + 2, k + 2, BlockList.netherizedObsidian);
		world.setBlock(i + 2, j + 2, k + 3, BlockList.netherizedObsidian);
		world.setBlock(i + 2, j + 2, k + 4, BlockList.netherizedObsidian);
		world.setBlock(i + 2, j + 2, k + 5, BlockList.netherizedObsidian);
		world.setBlock(i + 2, j + 2, k + 6, BlockList.netherizedObsidian);
		world.setBlock(i + 2, j + 2, k + 7, BlockList.netherizedObsidian);
		world.setBlock(i + 2, j + 2, k + 8, BlockList.netherizedObsidian);
		world.setBlock(i + 2, j + 2, k + 9, BlockList.netherizedObsidian);
		world.setBlock(i + 2, j + 2, k + 10, BlockList.netherizedObsidian);
		world.setBlock(i + 2, j + 2, k + 11, BlockList.netherizedObsidian);
		world.setBlock(i + 2, j + 2, k + 12, BlockList.netherizedObsidian);
		world.setBlock(i + 2, j + 2, k + 13, BlockList.netherizedObsidian);
		world.setBlock(i + 2, j + 2, k + 14, BlockList.netherizedObsidian);
		world.setBlock(i + 2, j + 2, k + 15, BlockList.netherizedObsidian);
		world.setBlock(i + 3, j + 0, k + 0, BlockList.netherizedObsidian);
		world.setBlock(i + 3, j + 0, k + 1, Blocks.obsidian);
		world.setBlock(i + 3, j + 0, k + 2, Blocks.obsidian);
		world.setBlock(i + 3, j + 0, k + 3, Blocks.obsidian);
		world.setBlock(i + 3, j + 0, k + 4, Blocks.obsidian);
		world.setBlock(i + 3, j + 0, k + 5, Blocks.obsidian);
		world.setBlock(i + 3, j + 0, k + 6, Blocks.obsidian);
		world.setBlock(i + 3, j + 0, k + 7, Blocks.obsidian);
		world.setBlock(i + 3, j + 0, k + 8, Blocks.obsidian);
		world.setBlock(i + 3, j + 0, k + 9, Blocks.obsidian);
		world.setBlock(i + 3, j + 0, k + 10, Blocks.obsidian);
		world.setBlock(i + 3, j + 0, k + 11, Blocks.obsidian);
		world.setBlock(i + 3, j + 0, k + 12, Blocks.obsidian);
		world.setBlock(i + 3, j + 0, k + 13, Blocks.obsidian);
		world.setBlock(i + 3, j + 0, k + 14, Blocks.obsidian);
		world.setBlock(i + 3, j + 0, k + 15, Blocks.obsidian);
		world.setBlock(i + 3, j + 0, k + 16, Blocks.obsidian);
		world.setBlock(i + 3, j + 0, k + 17, BlockList.netherizedObsidian);
		world.setBlock(i + 3, j + 1, k + 1, BlockList.netherizedObsidian);
		world.setBlock(i + 3, j + 1, k + 16, BlockList.netherizedObsidian);
		world.setBlock(i + 3, j + 2, k + 2, BlockList.netherizedObsidian);
		world.setBlock(i + 3, j + 2, k + 15, BlockList.netherizedObsidian);
		world.setBlock(i + 3, j + 3, k + 3, BlockList.netherizedObsidian);
		world.setBlock(i + 3, j + 3, k + 4, BlockList.netherizedObsidian);
		world.setBlock(i + 3, j + 3, k + 5, BlockList.netherizedObsidian);
		world.setBlock(i + 3, j + 3, k + 6, BlockList.netherizedObsidian);
		world.setBlock(i + 3, j + 3, k + 7, BlockList.netherizedObsidian);
		world.setBlock(i + 3, j + 3, k + 8, BlockList.netherizedObsidian);
		world.setBlock(i + 3, j + 3, k + 9, BlockList.netherizedObsidian);
		world.setBlock(i + 3, j + 3, k + 10, BlockList.netherizedObsidian);
		world.setBlock(i + 3, j + 3, k + 11, BlockList.netherizedObsidian);
		world.setBlock(i + 3, j + 3, k + 12, BlockList.netherizedObsidian);
		world.setBlock(i + 3, j + 3, k + 13, BlockList.netherizedObsidian);
		world.setBlock(i + 3, j + 3, k + 14, BlockList.netherizedObsidian);
		world.setBlock(i + 4, j + 0, k + 0, BlockList.netherizedObsidian);
		world.setBlock(i + 4, j + 0, k + 1, Blocks.obsidian);
		world.setBlock(i + 4, j + 0, k + 2, Blocks.obsidian);
		world.setBlock(i + 4, j + 0, k + 3, Blocks.obsidian);
		world.setBlock(i + 4, j + 0, k + 4, Blocks.obsidian);
		world.setBlock(i + 4, j + 0, k + 5, Blocks.obsidian);
		world.setBlock(i + 4, j + 0, k + 6, Blocks.obsidian);
		world.setBlock(i + 4, j + 0, k + 7, Blocks.obsidian);
		world.setBlock(i + 4, j + 0, k + 8, Blocks.obsidian);
		world.setBlock(i + 4, j + 0, k + 9, Blocks.obsidian);
		world.setBlock(i + 4, j + 0, k + 10, Blocks.obsidian);
		world.setBlock(i + 4, j + 0, k + 11, Blocks.obsidian);
		world.setBlock(i + 4, j + 0, k + 12, Blocks.obsidian);
		world.setBlock(i + 4, j + 0, k + 13, Blocks.obsidian);
		world.setBlock(i + 4, j + 0, k + 14, Blocks.obsidian);
		world.setBlock(i + 4, j + 0, k + 15, Blocks.obsidian);
		world.setBlock(i + 4, j + 0, k + 16, Blocks.obsidian);
		world.setBlock(i + 4, j + 0, k + 17, BlockList.netherizedObsidian);
		world.setBlock(i + 4, j + 1, k + 1, BlockList.netherizedObsidian);
		world.setBlock(i + 4, j + 1, k + 16, BlockList.netherizedObsidian);
		world.setBlock(i + 4, j + 2, k + 2, BlockList.netherizedObsidian);
		world.setBlock(i + 4, j + 2, k + 15, BlockList.netherizedObsidian);
		world.setBlock(i + 4, j + 3, k + 3, BlockList.netherizedObsidian);
		world.setBlock(i + 4, j + 3, k + 14, BlockList.netherizedObsidian);
		world.setBlock(i + 4, j + 4, k + 4, BlockList.netherizedObsidian);
		world.setBlock(i + 4, j + 4, k + 5, BlockList.netherizedObsidian);
		world.setBlock(i + 4, j + 4, k + 6, BlockList.netherizedObsidian);
		world.setBlock(i + 4, j + 4, k + 7, BlockList.netherizedObsidian);
		world.setBlock(i + 4, j + 4, k + 8, BlockList.netherizedObsidian);
		world.setBlock(i + 4, j + 4, k + 9, BlockList.netherizedObsidian);
		world.setBlock(i + 4, j + 4, k + 10, BlockList.netherizedObsidian);
		world.setBlock(i + 4, j + 4, k + 11, BlockList.netherizedObsidian);
		world.setBlock(i + 4, j + 4, k + 12, BlockList.netherizedObsidian);
		world.setBlock(i + 4, j + 4, k + 13, BlockList.netherizedObsidian);
		world.setBlock(i + 4, j + 5, k + 4, BlockList.netherizedObsidian);
		world.setBlock(i + 4, j + 5, k + 5, BlockList.netherizedObsidian);
		world.setBlock(i + 4, j + 5, k + 6, BlockList.netherizedObsidian);
		world.setBlock(i + 4, j + 5, k + 7, BlockList.netherizedObsidian);
		world.setBlock(i + 4, j + 5, k + 8, BlockList.netherizedObsidian);
		world.setBlock(i + 4, j + 5, k + 9, BlockList.netherizedObsidian);
		world.setBlock(i + 4, j + 5, k + 10, BlockList.netherizedObsidian);
		world.setBlock(i + 4, j + 5, k + 11, BlockList.netherizedObsidian);
		world.setBlock(i + 4, j + 5, k + 12, BlockList.netherizedObsidian);
		world.setBlock(i + 4, j + 5, k + 13, BlockList.netherizedObsidian);
		world.setBlock(i + 4, j + 6, k + 4, BlockList.netherizedObsidian);
		world.setBlock(i + 4, j + 6, k + 5, BlockList.netherizedObsidian);
		world.setBlock(i + 4, j + 6, k + 6, BlockList.netherizedObsidian);
		world.setBlock(i + 4, j + 6, k + 7, BlockList.netherizedObsidian);
		world.setBlock(i + 4, j + 6, k + 8, BlockList.netherizedObsidian);
		world.setBlock(i + 4, j + 6, k + 9, BlockList.netherizedObsidian);
		world.setBlock(i + 4, j + 6, k + 10, BlockList.netherizedObsidian);
		world.setBlock(i + 4, j + 6, k + 11, BlockList.netherizedObsidian);
		world.setBlock(i + 4, j + 6, k + 12, BlockList.netherizedObsidian);
		world.setBlock(i + 4, j + 6, k + 13, BlockList.netherizedObsidian);
		world.setBlock(i + 4, j + 7, k + 4, BlockList.netherizedObsidian);
		world.setBlock(i + 4, j + 7, k + 5, BlockList.netherizedObsidian);
		world.setBlock(i + 4, j + 7, k + 6, BlockList.netherizedObsidian);
		world.setBlock(i + 4, j + 7, k + 7, BlockList.netherizedObsidian);
		world.setBlock(i + 4, j + 7, k + 8, BlockList.netherizedObsidian);
		world.setBlock(i + 4, j + 7, k + 9, BlockList.netherizedObsidian);
		world.setBlock(i + 4, j + 7, k + 10, BlockList.netherizedObsidian);
		world.setBlock(i + 4, j + 7, k + 11, BlockList.netherizedObsidian);
		world.setBlock(i + 4, j + 7, k + 12, BlockList.netherizedObsidian);
		world.setBlock(i + 4, j + 7, k + 13, BlockList.netherizedObsidian);
		world.setBlock(i + 4, j + 8, k + 4, BlockList.netherizedObsidian);
		world.setBlock(i + 4, j + 8, k + 5, BlockList.netherizedObsidian);
		world.setBlock(i + 4, j + 8, k + 6, BlockList.netherizedObsidian);
		world.setBlock(i + 4, j + 8, k + 7, BlockList.netherizedObsidian);
		world.setBlock(i + 4, j + 8, k + 8, BlockList.netherizedObsidian);
		world.setBlock(i + 4, j + 8, k + 9, BlockList.netherizedObsidian);
		world.setBlock(i + 4, j + 8, k + 10, BlockList.netherizedObsidian);
		world.setBlock(i + 4, j + 8, k + 11, BlockList.netherizedObsidian);
		world.setBlock(i + 4, j + 8, k + 12, BlockList.netherizedObsidian);
		world.setBlock(i + 4, j + 8, k + 13, BlockList.netherizedObsidian);
		world.setBlock(i + 4, j + 9, k + 4, BlockList.netherizedObsidian);
		world.setBlock(i + 4, j + 9, k + 5, BlockList.netherizedObsidian);
		world.setBlock(i + 4, j + 9, k + 6, BlockList.netherizedObsidian);
		world.setBlock(i + 4, j + 9, k + 7, BlockList.netherizedObsidian);
		world.setBlock(i + 4, j + 9, k + 8, BlockList.netherizedObsidian);
		world.setBlock(i + 4, j + 9, k + 9, BlockList.netherizedObsidian);
		world.setBlock(i + 4, j + 9, k + 10, BlockList.netherizedObsidian);
		world.setBlock(i + 4, j + 9, k + 11, BlockList.netherizedObsidian);
		world.setBlock(i + 4, j + 9, k + 12, BlockList.netherizedObsidian);
		world.setBlock(i + 4, j + 9, k + 13, BlockList.netherizedObsidian);
		world.setBlock(i + 5, j + 0, k + 0, BlockList.netherizedObsidian);
		world.setBlock(i + 5, j + 0, k + 1, Blocks.obsidian);
		world.setBlock(i + 5, j + 0, k + 2, Blocks.obsidian);
		world.setBlock(i + 5, j + 0, k + 3, Blocks.obsidian);
		world.setBlock(i + 5, j + 0, k + 4, Blocks.obsidian);
		world.setBlock(i + 5, j + 0, k + 5, Blocks.obsidian);
		world.setBlock(i + 5, j + 0, k + 6, Blocks.obsidian);
		world.setBlock(i + 5, j + 0, k + 7, Blocks.obsidian);
		world.setBlock(i + 5, j + 0, k + 8, Blocks.obsidian);
		world.setBlock(i + 5, j + 0, k + 9, Blocks.obsidian);
		world.setBlock(i + 5, j + 0, k + 10, Blocks.obsidian);
		world.setBlock(i + 5, j + 0, k + 11, Blocks.obsidian);
		world.setBlock(i + 5, j + 0, k + 12, Blocks.obsidian);
		world.setBlock(i + 5, j + 0, k + 13, Blocks.obsidian);
		world.setBlock(i + 5, j + 0, k + 14, Blocks.obsidian);
		world.setBlock(i + 5, j + 0, k + 15, Blocks.obsidian);
		world.setBlock(i + 5, j + 0, k + 16, Blocks.obsidian);
		world.setBlock(i + 5, j + 0, k + 17, BlockList.netherizedObsidian);
		world.setBlock(i + 5, j + 1, k + 1, BlockList.netherizedObsidian);
		int chestX = i + 5;
		int chestY = j + 1;
		int chestZ = k + 8;
		int chestRand = rand.nextInt(2);
		boolean isBigChest = chestRand == 1 ? true : false;
		String chestString = chestX + " " + chestY + " " + chestZ;
		Treasures.spawnChest(world, rand, chestX, chestY, chestZ, isBigChest,
				ZEChestGenHooks.ENDER_TOWER);
		world.setBlock(i + 5, j + 1, k + 16, BlockList.netherizedObsidian);
		world.setBlock(i + 5, j + 2, k + 2, BlockList.netherizedObsidian);
		world.setBlock(i + 5, j + 2, k + 15, BlockList.netherizedObsidian);
		world.setBlock(i + 5, j + 3, k + 3, BlockList.netherizedObsidian);
		world.setBlock(i + 5, j + 3, k + 14, BlockList.netherizedObsidian);
		world.setBlock(i + 5, j + 4, k + 4, BlockList.netherizedObsidian);
		world.setBlock(i + 5, j + 4, k + 13, BlockList.netherizedObsidian);
		world.setBlock(i + 5, j + 5, k + 4, BlockList.netherizedObsidian);
		world.setBlock(i + 5, j + 5, k + 13, BlockList.netherizedObsidian);
		world.setBlock(i + 5, j + 6, k + 4, BlockList.netherizedObsidian);
		world.setBlock(i + 5, j + 6, k + 13, BlockList.netherizedObsidian);
		world.setBlock(i + 5, j + 7, k + 4, BlockList.netherizedObsidian);
		world.setBlock(i + 5, j + 7, k + 13, BlockList.netherizedObsidian);
		world.setBlock(i + 5, j + 8, k + 4, BlockList.netherizedObsidian);
		world.setBlock(i + 5, j + 8, k + 13, BlockList.netherizedObsidian);
		world.setBlock(i + 5, j + 9, k + 4, BlockList.netherizedObsidian);
		world.setBlock(i + 5, j + 9, k + 13, BlockList.netherizedObsidian);
		world.setBlock(i + 5, j + 10, k + 5, BlockList.netherizedObsidian);
		world.setBlock(i + 5, j + 10, k + 6, BlockList.netherizedObsidian);
		world.setBlock(i + 5, j + 10, k + 7, BlockList.netherizedObsidian);
		world.setBlock(i + 5, j + 10, k + 8, BlockList.netherizedObsidian);
		world.setBlock(i + 5, j + 10, k + 9, BlockList.netherizedObsidian);
		world.setBlock(i + 5, j + 10, k + 10, BlockList.netherizedObsidian);
		world.setBlock(i + 5, j + 10, k + 11, BlockList.netherizedObsidian);
		world.setBlock(i + 5, j + 10, k + 12, BlockList.netherizedObsidian);
		world.setBlock(i + 6, j + 0, k + 0, BlockList.netherizedObsidian);
		world.setBlock(i + 6, j + 0, k + 1, Blocks.obsidian);
		world.setBlock(i + 6, j + 0, k + 2, Blocks.obsidian);
		world.setBlock(i + 6, j + 0, k + 3, Blocks.obsidian);
		world.setBlock(i + 6, j + 0, k + 4, Blocks.obsidian);
		world.setBlock(i + 6, j + 0, k + 5, Blocks.obsidian);
		world.setBlock(i + 6, j + 0, k + 6, Blocks.obsidian);
		world.setBlock(i + 6, j + 0, k + 7, Blocks.obsidian);
		world.setBlock(i + 6, j + 0, k + 8, Blocks.obsidian);
		world.setBlock(i + 6, j + 0, k + 9, Blocks.obsidian);
		world.setBlock(i + 6, j + 0, k + 10, Blocks.obsidian);
		world.setBlock(i + 6, j + 0, k + 11, Blocks.obsidian);
		world.setBlock(i + 6, j + 0, k + 12, Blocks.obsidian);
		world.setBlock(i + 6, j + 0, k + 13, Blocks.obsidian);
		world.setBlock(i + 6, j + 0, k + 14, Blocks.obsidian);
		world.setBlock(i + 6, j + 0, k + 15, Blocks.obsidian);
		world.setBlock(i + 6, j + 0, k + 16, Blocks.obsidian);
		world.setBlock(i + 6, j + 0, k + 17, BlockList.netherizedObsidian);
		world.setBlock(i + 6, j + 1, k + 1, BlockList.netherizedObsidian);
		world.setBlock(i + 6, j + 1, k + 16, BlockList.netherizedObsidian);
		world.setBlock(i + 6, j + 2, k + 2, BlockList.netherizedObsidian);
		world.setBlock(i + 6, j + 2, k + 15, BlockList.netherizedObsidian);
		world.setBlock(i + 6, j + 3, k + 3, BlockList.netherizedObsidian);
		world.setBlock(i + 6, j + 3, k + 14, BlockList.netherizedObsidian);
		world.setBlock(i + 6, j + 4, k + 4, BlockList.netherizedObsidian);
		world.setBlock(i + 6, j + 4, k + 13, BlockList.netherizedObsidian);
		world.setBlock(i + 6, j + 5, k + 4, BlockList.netherizedObsidian);
		world.setBlock(i + 6, j + 5, k + 13, BlockList.netherizedObsidian);
		world.setBlock(i + 6, j + 6, k + 4, BlockList.netherizedObsidian);
		world.setBlock(i + 6, j + 6, k + 13, BlockList.netherizedObsidian);
		world.setBlock(i + 6, j + 7, k + 4, BlockList.netherizedObsidian);
		world.setBlock(i + 6, j + 7, k + 13, BlockList.netherizedObsidian);
		world.setBlock(i + 6, j + 8, k + 4, BlockList.netherizedObsidian);
		world.setBlock(i + 6, j + 8, k + 13, BlockList.netherizedObsidian);
		world.setBlock(i + 6, j + 9, k + 4, BlockList.netherizedObsidian);
		world.setBlock(i + 6, j + 9, k + 13, BlockList.netherizedObsidian);
		world.setBlock(i + 6, j + 10, k + 5, BlockList.netherizedObsidian);
		world.setBlock(i + 6, j + 10, k + 6, BlockList.netherizedObsidian);
		world.setBlock(i + 6, j + 10, k + 7, BlockList.netherizedObsidian);
		world.setBlock(i + 6, j + 10, k + 8, BlockList.netherizedObsidian);
		world.setBlock(i + 6, j + 10, k + 9, BlockList.netherizedObsidian);
		world.setBlock(i + 6, j + 10, k + 10, BlockList.netherizedObsidian);
		world.setBlock(i + 6, j + 10, k + 11, BlockList.netherizedObsidian);
		world.setBlock(i + 6, j + 10, k + 12, BlockList.netherizedObsidian);
		world.setBlock(i + 7, j + 0, k + 0, BlockList.netherizedObsidian);
		world.setBlock(i + 7, j + 0, k + 1, Blocks.obsidian);
		world.setBlock(i + 7, j + 0, k + 2, Blocks.obsidian);
		world.setBlock(i + 7, j + 0, k + 3, Blocks.obsidian);
		world.setBlock(i + 7, j + 0, k + 4, Blocks.obsidian);
		world.setBlock(i + 7, j + 0, k + 5, Blocks.obsidian);
		world.setBlock(i + 7, j + 0, k + 6, Blocks.obsidian);
		world.setBlock(i + 7, j + 0, k + 7, Blocks.obsidian);
		world.setBlock(i + 7, j + 0, k + 8, Blocks.obsidian);
		world.setBlock(i + 7, j + 0, k + 9, Blocks.obsidian);
		world.setBlock(i + 7, j + 0, k + 10, Blocks.obsidian);
		world.setBlock(i + 7, j + 0, k + 11, Blocks.obsidian);
		world.setBlock(i + 7, j + 0, k + 12, Blocks.obsidian);
		world.setBlock(i + 7, j + 0, k + 13, Blocks.obsidian);
		world.setBlock(i + 7, j + 0, k + 14, Blocks.obsidian);
		world.setBlock(i + 7, j + 0, k + 15, Blocks.obsidian);
		world.setBlock(i + 7, j + 0, k + 16, Blocks.obsidian);
		world.setBlock(i + 7, j + 0, k + 17, BlockList.netherizedObsidian);
		world.setBlock(i + 7, j + 1, k + 1, BlockList.netherizedObsidian);
		world.setBlock(i + 7, j + 1, k + 16, BlockList.netherizedObsidian);
		world.setBlock(i + 7, j + 2, k + 2, BlockList.netherizedObsidian);
		world.setBlock(i + 7, j + 2, k + 15, BlockList.netherizedObsidian);
		world.setBlock(i + 7, j + 3, k + 3, BlockList.netherizedObsidian);
		world.setBlock(i + 7, j + 3, k + 14, BlockList.netherizedObsidian);
		world.setBlock(i + 7, j + 4, k + 4, BlockList.netherizedObsidian);
		world.setBlock(i + 7, j + 4, k + 13, BlockList.netherizedObsidian);
		world.setBlock(i + 7, j + 5, k + 4, BlockList.netherizedObsidian);
		world.setBlock(i + 7, j + 5, k + 13, BlockList.netherizedObsidian);
		world.setBlock(i + 7, j + 6, k + 4, BlockList.netherizedObsidian);
		world.setBlock(i + 7, j + 6, k + 13, BlockList.netherizedObsidian);
		world.setBlock(i + 7, j + 7, k + 4, BlockList.netherizedObsidian);
		world.setBlock(i + 7, j + 7, k + 13, BlockList.netherizedObsidian);
		world.setBlock(i + 7, j + 8, k + 4, BlockList.netherizedObsidian);
		world.setBlock(i + 7, j + 8, k + 13, BlockList.netherizedObsidian);
		world.setBlock(i + 7, j + 9, k + 4, BlockList.netherizedObsidian);
		world.setBlock(i + 7, j + 9, k + 13, BlockList.netherizedObsidian);
		world.setBlock(i + 7, j + 10, k + 5, BlockList.netherizedObsidian);
		world.setBlock(i + 7, j + 10, k + 6, BlockList.netherizedObsidian);
		world.setBlock(i + 7, j + 10, k + 7, BlockList.netherizedObsidian);
		world.setBlock(i + 7, j + 10, k + 8, BlockList.netherizedObsidian);
		world.setBlock(i + 7, j + 10, k + 9, BlockList.netherizedObsidian);
		world.setBlock(i + 7, j + 10, k + 10, BlockList.netherizedObsidian);
		world.setBlock(i + 7, j + 10, k + 11, BlockList.netherizedObsidian);
		world.setBlock(i + 7, j + 10, k + 12, BlockList.netherizedObsidian);
		world.setBlock(i + 8, j + 0, k + 0, BlockList.netherizedObsidian);
		world.setBlock(i + 8, j + 0, k + 1, Blocks.obsidian);
		world.setBlock(i + 8, j + 0, k + 2, Blocks.obsidian);
		world.setBlock(i + 8, j + 0, k + 3, Blocks.obsidian);
		world.setBlock(i + 8, j + 0, k + 4, Blocks.obsidian);
		world.setBlock(i + 8, j + 0, k + 5, Blocks.obsidian);
		world.setBlock(i + 8, j + 0, k + 6, Blocks.obsidian);
		world.setBlock(i + 8, j + 0, k + 7, Blocks.obsidian);
		world.setBlock(i + 8, j + 0, k + 8, Blocks.obsidian);
		world.setBlock(i + 8, j + 0, k + 9, Blocks.obsidian);
		world.setBlock(i + 8, j + 0, k + 10, Blocks.obsidian);
		world.setBlock(i + 8, j + 0, k + 11, Blocks.obsidian);
		world.setBlock(i + 8, j + 0, k + 12, Blocks.obsidian);
		world.setBlock(i + 8, j + 0, k + 13, Blocks.obsidian);
		world.setBlock(i + 8, j + 0, k + 14, Blocks.obsidian);
		world.setBlock(i + 8, j + 0, k + 15, Blocks.obsidian);
		world.setBlock(i + 8, j + 0, k + 16, Blocks.obsidian);
		world.setBlock(i + 8, j + 0, k + 17, BlockList.netherizedObsidian);
		world.setBlock(i + 8, j + 1, k + 1, BlockList.netherizedObsidian);
		world.setBlock(i + 8, j + 1, k + 16, BlockList.netherizedObsidian);
		world.setBlock(i + 8, j + 2, k + 2, BlockList.netherizedObsidian);
		world.setBlock(i + 8, j + 2, k + 15, BlockList.netherizedObsidian);
		world.setBlock(i + 8, j + 3, k + 3, BlockList.netherizedObsidian);
		world.setBlock(i + 8, j + 3, k + 14, BlockList.netherizedObsidian);
		world.setBlock(i + 8, j + 4, k + 4, BlockList.netherizedObsidian);
		world.setBlock(i + 8, j + 4, k + 13, BlockList.netherizedObsidian);
		world.setBlock(i + 8, j + 5, k + 4, BlockList.netherizedObsidian);
		world.setBlock(i + 8, j + 5, k + 13, BlockList.netherizedObsidian);
		world.setBlock(i + 8, j + 6, k + 4, BlockList.netherizedObsidian);
		world.setBlock(i + 8, j + 6, k + 13, BlockList.netherizedObsidian);
		world.setBlock(i + 8, j + 7, k + 4, BlockList.netherizedObsidian);
		world.setBlock(i + 8, j + 7, k + 13, BlockList.netherizedObsidian);
		world.setBlock(i + 8, j + 8, k + 4, BlockList.netherizedObsidian);
		world.setBlock(i + 8, j + 8, k + 13, BlockList.netherizedObsidian);
		world.setBlock(i + 8, j + 9, k + 4, BlockList.netherizedObsidian);
		world.setBlock(i + 8, j + 9, k + 13, BlockList.netherizedObsidian);
		world.setBlock(i + 8, j + 10, k + 5, BlockList.netherizedObsidian);
		world.setBlock(i + 8, j + 10, k + 6, BlockList.netherizedObsidian);
		world.setBlock(i + 8, j + 10, k + 7, BlockList.netherizedObsidian);
		world.setBlock(i + 8, j + 10, k + 8, BlockList.netherizedObsidian);
		world.setBlock(i + 8, j + 10, k + 9, BlockList.netherizedObsidian);
		world.setBlock(i + 8, j + 10, k + 10, BlockList.netherizedObsidian);
		world.setBlock(i + 8, j + 10, k + 11, BlockList.netherizedObsidian);
		world.setBlock(i + 8, j + 10, k + 12, BlockList.netherizedObsidian);
		world.setBlock(i + 9, j + 0, k + 0, BlockList.netherizedObsidian);
		world.setBlock(i + 9, j + 0, k + 1, Blocks.obsidian);
		world.setBlock(i + 9, j + 0, k + 2, Blocks.obsidian);
		world.setBlock(i + 9, j + 0, k + 3, Blocks.obsidian);
		world.setBlock(i + 9, j + 0, k + 4, Blocks.obsidian);
		world.setBlock(i + 9, j + 0, k + 5, Blocks.obsidian);
		world.setBlock(i + 9, j + 0, k + 6, Blocks.obsidian);
		world.setBlock(i + 9, j + 0, k + 7, Blocks.obsidian);
		world.setBlock(i + 9, j + 0, k + 8, Blocks.obsidian);
		world.setBlock(i + 9, j + 0, k + 9, Blocks.obsidian);
		world.setBlock(i + 9, j + 0, k + 10, Blocks.obsidian);
		world.setBlock(i + 9, j + 0, k + 11, Blocks.obsidian);
		world.setBlock(i + 9, j + 0, k + 12, Blocks.obsidian);
		world.setBlock(i + 9, j + 0, k + 13, Blocks.obsidian);
		world.setBlock(i + 9, j + 0, k + 14, Blocks.obsidian);
		world.setBlock(i + 9, j + 0, k + 15, Blocks.obsidian);
		world.setBlock(i + 9, j + 0, k + 16, Blocks.obsidian);
		world.setBlock(i + 9, j + 0, k + 17, BlockList.netherizedObsidian);
		world.setBlock(i + 9, j + 1, k + 1, BlockList.netherizedObsidian);
		world.setBlock(i + 9, j + 1, k + 16, BlockList.netherizedObsidian);
		world.setBlock(i + 9, j + 2, k + 2, BlockList.netherizedObsidian);
		world.setBlock(i + 9, j + 2, k + 15, BlockList.netherizedObsidian);
		world.setBlock(i + 9, j + 3, k + 3, BlockList.netherizedObsidian);
		world.setBlock(i + 9, j + 3, k + 14, BlockList.netherizedObsidian);
		world.setBlock(i + 9, j + 4, k + 4, BlockList.netherizedObsidian);
		world.setBlock(i + 9, j + 4, k + 13, BlockList.netherizedObsidian);
		world.setBlock(i + 9, j + 5, k + 4, BlockList.netherizedObsidian);
		world.setBlock(i + 9, j + 5, k + 13, BlockList.netherizedObsidian);
		world.setBlock(i + 9, j + 6, k + 4, BlockList.netherizedObsidian);
		world.setBlock(i + 9, j + 6, k + 13, BlockList.netherizedObsidian);
		world.setBlock(i + 9, j + 7, k + 4, BlockList.netherizedObsidian);
		world.setBlock(i + 9, j + 7, k + 13, BlockList.netherizedObsidian);
		world.setBlock(i + 9, j + 8, k + 4, BlockList.netherizedObsidian);
		world.setBlock(i + 9, j + 8, k + 13, BlockList.netherizedObsidian);
		world.setBlock(i + 9, j + 9, k + 4, BlockList.netherizedObsidian);
		world.setBlock(i + 9, j + 9, k + 13, BlockList.netherizedObsidian);
		world.setBlock(i + 9, j + 10, k + 5, BlockList.netherizedObsidian);
		world.setBlock(i + 9, j + 10, k + 6, BlockList.netherizedObsidian);
		world.setBlock(i + 9, j + 10, k + 7, BlockList.netherizedObsidian);
		world.setBlock(i + 9, j + 10, k + 8, BlockList.netherizedObsidian);
		world.setBlock(i + 9, j + 10, k + 9, BlockList.netherizedObsidian);
		world.setBlock(i + 9, j + 10, k + 10, BlockList.netherizedObsidian);
		world.setBlock(i + 9, j + 10, k + 11, BlockList.netherizedObsidian);
		world.setBlock(i + 9, j + 10, k + 12, BlockList.netherizedObsidian);
		world.setBlock(i + 10, j + 0, k + 0, BlockList.netherizedObsidian);
		world.setBlock(i + 10, j + 0, k + 1, Blocks.obsidian);
		world.setBlock(i + 10, j + 0, k + 2, Blocks.obsidian);
		world.setBlock(i + 10, j + 0, k + 3, Blocks.obsidian);
		world.setBlock(i + 10, j + 0, k + 4, Blocks.obsidian);
		world.setBlock(i + 10, j + 0, k + 5, Blocks.obsidian);
		world.setBlock(i + 10, j + 0, k + 6, Blocks.obsidian);
		world.setBlock(i + 10, j + 0, k + 7, Blocks.obsidian);
		world.setBlock(i + 10, j + 0, k + 8, Blocks.obsidian);
		world.setBlock(i + 10, j + 0, k + 9, Blocks.obsidian);
		world.setBlock(i + 10, j + 0, k + 10, Blocks.obsidian);
		world.setBlock(i + 10, j + 0, k + 11, Blocks.obsidian);
		world.setBlock(i + 10, j + 0, k + 12, Blocks.obsidian);
		world.setBlock(i + 10, j + 0, k + 13, Blocks.obsidian);
		world.setBlock(i + 10, j + 0, k + 14, Blocks.obsidian);
		world.setBlock(i + 10, j + 0, k + 15, Blocks.obsidian);
		world.setBlock(i + 10, j + 0, k + 16, Blocks.obsidian);
		world.setBlock(i + 10, j + 0, k + 17, BlockList.netherizedObsidian);
		world.setBlock(i + 10, j + 1, k + 1, BlockList.netherizedObsidian);
		world.setBlock(i + 10, j + 1, k + 16, BlockList.netherizedObsidian);
		world.setBlock(i + 10, j + 2, k + 2, BlockList.netherizedObsidian);
		world.setBlock(i + 10, j + 2, k + 15, BlockList.netherizedObsidian);
		world.setBlock(i + 10, j + 3, k + 3, BlockList.netherizedObsidian);
		world.setBlock(i + 10, j + 3, k + 14, BlockList.netherizedObsidian);
		world.setBlock(i + 10, j + 4, k + 4, BlockList.netherizedObsidian);
		world.setBlock(i + 10, j + 4, k + 13, BlockList.netherizedObsidian);
		world.setBlock(i + 10, j + 5, k + 4, BlockList.netherizedObsidian);
		world.setBlock(i + 10, j + 5, k + 13, BlockList.netherizedObsidian);
		world.setBlock(i + 10, j + 6, k + 4, BlockList.netherizedObsidian);
		world.setBlock(i + 10, j + 6, k + 13, BlockList.netherizedObsidian);
		world.setBlock(i + 10, j + 7, k + 4, BlockList.netherizedObsidian);
		world.setBlock(i + 10, j + 7, k + 13, BlockList.netherizedObsidian);
		world.setBlock(i + 10, j + 8, k + 4, BlockList.netherizedObsidian);
		world.setBlock(i + 10, j + 8, k + 13, BlockList.netherizedObsidian);
		world.setBlock(i + 10, j + 9, k + 4, BlockList.netherizedObsidian);
		world.setBlock(i + 10, j + 9, k + 13, BlockList.netherizedObsidian);
		world.setBlock(i + 10, j + 10, k + 5, BlockList.netherizedObsidian);
		world.setBlock(i + 10, j + 10, k + 6, BlockList.netherizedObsidian);
		world.setBlock(i + 10, j + 10, k + 7, BlockList.netherizedObsidian);
		world.setBlock(i + 10, j + 10, k + 8, BlockList.netherizedObsidian);
		world.setBlock(i + 10, j + 10, k + 9, BlockList.netherizedObsidian);
		world.setBlock(i + 10, j + 10, k + 10, BlockList.netherizedObsidian);
		world.setBlock(i + 10, j + 10, k + 11, BlockList.netherizedObsidian);
		world.setBlock(i + 10, j + 10, k + 12, BlockList.netherizedObsidian);
		world.setBlock(i + 11, j + 0, k + 0, BlockList.netherizedObsidian);
		world.setBlock(i + 11, j + 0, k + 1, Blocks.obsidian);
		world.setBlock(i + 11, j + 0, k + 2, Blocks.obsidian);
		world.setBlock(i + 11, j + 0, k + 3, Blocks.obsidian);
		world.setBlock(i + 11, j + 0, k + 4, Blocks.obsidian);
		world.setBlock(i + 11, j + 0, k + 5, Blocks.obsidian);
		world.setBlock(i + 11, j + 0, k + 6, Blocks.obsidian);
		world.setBlock(i + 11, j + 0, k + 7, Blocks.obsidian);
		world.setBlock(i + 11, j + 0, k + 8, Blocks.obsidian);
		world.setBlock(i + 11, j + 0, k + 9, Blocks.obsidian);
		world.setBlock(i + 11, j + 0, k + 10, Blocks.obsidian);
		world.setBlock(i + 11, j + 0, k + 11, Blocks.obsidian);
		world.setBlock(i + 11, j + 0, k + 12, Blocks.obsidian);
		world.setBlock(i + 11, j + 0, k + 13, Blocks.obsidian);
		world.setBlock(i + 11, j + 0, k + 14, Blocks.obsidian);
		world.setBlock(i + 11, j + 0, k + 15, Blocks.obsidian);
		world.setBlock(i + 11, j + 0, k + 16, Blocks.obsidian);
		world.setBlock(i + 11, j + 0, k + 17, BlockList.netherizedObsidian);
		world.setBlock(i + 11, j + 1, k + 1, BlockList.netherizedObsidian);
		world.setBlock(i + 11, j + 1, k + 16, BlockList.netherizedObsidian);
		world.setBlock(i + 11, j + 2, k + 2, BlockList.netherizedObsidian);
		world.setBlock(i + 11, j + 2, k + 15, BlockList.netherizedObsidian);
		world.setBlock(i + 11, j + 3, k + 3, BlockList.netherizedObsidian);
		world.setBlock(i + 11, j + 3, k + 14, BlockList.netherizedObsidian);
		world.setBlock(i + 11, j + 4, k + 4, BlockList.netherizedObsidian);
		world.setBlock(i + 11, j + 4, k + 13, BlockList.netherizedObsidian);
		world.setBlock(i + 11, j + 5, k + 4, BlockList.netherizedObsidian);
		world.setBlock(i + 11, j + 5, k + 13, BlockList.netherizedObsidian);
		world.setBlock(i + 11, j + 6, k + 4, BlockList.netherizedObsidian);
		world.setBlock(i + 11, j + 6, k + 13, BlockList.netherizedObsidian);
		world.setBlock(i + 11, j + 7, k + 4, BlockList.netherizedObsidian);
		world.setBlock(i + 11, j + 7, k + 13, BlockList.netherizedObsidian);
		world.setBlock(i + 11, j + 8, k + 4, BlockList.netherizedObsidian);
		world.setBlock(i + 11, j + 8, k + 13, BlockList.netherizedObsidian);
		world.setBlock(i + 11, j + 9, k + 4, BlockList.netherizedObsidian);
		world.setBlock(i + 11, j + 9, k + 13, BlockList.netherizedObsidian);
		world.setBlock(i + 11, j + 10, k + 5, BlockList.netherizedObsidian);
		world.setBlock(i + 11, j + 10, k + 6, BlockList.netherizedObsidian);
		world.setBlock(i + 11, j + 10, k + 7, BlockList.netherizedObsidian);
		world.setBlock(i + 11, j + 10, k + 8, BlockList.netherizedObsidian);
		world.setBlock(i + 11, j + 10, k + 9, BlockList.netherizedObsidian);
		world.setBlock(i + 11, j + 10, k + 10, BlockList.netherizedObsidian);
		world.setBlock(i + 11, j + 10, k + 11, BlockList.netherizedObsidian);
		world.setBlock(i + 11, j + 10, k + 12, BlockList.netherizedObsidian);
		world.setBlock(i + 12, j + 0, k + 0, BlockList.netherizedObsidian);
		world.setBlock(i + 12, j + 0, k + 1, Blocks.obsidian);
		world.setBlock(i + 12, j + 0, k + 2, Blocks.obsidian);
		world.setBlock(i + 12, j + 0, k + 3, Blocks.obsidian);
		world.setBlock(i + 12, j + 0, k + 4, Blocks.obsidian);
		world.setBlock(i + 12, j + 0, k + 5, Blocks.obsidian);
		world.setBlock(i + 12, j + 0, k + 6, Blocks.obsidian);
		world.setBlock(i + 12, j + 0, k + 7, Blocks.obsidian);
		world.setBlock(i + 12, j + 0, k + 8, Blocks.obsidian);
		world.setBlock(i + 12, j + 0, k + 9, Blocks.obsidian);
		world.setBlock(i + 12, j + 0, k + 10, Blocks.obsidian);
		world.setBlock(i + 12, j + 0, k + 11, Blocks.obsidian);
		world.setBlock(i + 12, j + 0, k + 12, Blocks.obsidian);
		world.setBlock(i + 12, j + 0, k + 13, Blocks.obsidian);
		world.setBlock(i + 12, j + 0, k + 14, Blocks.obsidian);
		world.setBlock(i + 12, j + 0, k + 15, Blocks.obsidian);
		world.setBlock(i + 12, j + 0, k + 16, Blocks.obsidian);
		world.setBlock(i + 12, j + 0, k + 17, BlockList.netherizedObsidian);
		world.setBlock(i + 12, j + 1, k + 1, BlockList.netherizedObsidian);
		world.setBlock(i + 12, j + 1, k + 16, BlockList.netherizedObsidian);
		world.setBlock(i + 12, j + 2, k + 2, BlockList.netherizedObsidian);
		world.setBlock(i + 12, j + 2, k + 15, BlockList.netherizedObsidian);
		world.setBlock(i + 12, j + 3, k + 3, BlockList.netherizedObsidian);
		world.setBlock(i + 12, j + 3, k + 14, BlockList.netherizedObsidian);
		world.setBlock(i + 12, j + 4, k + 4, BlockList.netherizedObsidian);
		world.setBlock(i + 12, j + 4, k + 13, BlockList.netherizedObsidian);
		world.setBlock(i + 12, j + 5, k + 4, BlockList.netherizedObsidian);
		world.setBlock(i + 12, j + 5, k + 13, BlockList.netherizedObsidian);
		world.setBlock(i + 12, j + 6, k + 4, BlockList.netherizedObsidian);
		world.setBlock(i + 12, j + 6, k + 13, BlockList.netherizedObsidian);
		world.setBlock(i + 12, j + 7, k + 4, BlockList.netherizedObsidian);
		world.setBlock(i + 12, j + 7, k + 13, BlockList.netherizedObsidian);
		world.setBlock(i + 12, j + 8, k + 4, BlockList.netherizedObsidian);
		world.setBlock(i + 12, j + 8, k + 13, BlockList.netherizedObsidian);
		world.setBlock(i + 12, j + 9, k + 4, BlockList.netherizedObsidian);
		world.setBlock(i + 12, j + 9, k + 13, BlockList.netherizedObsidian);
		world.setBlock(i + 12, j + 10, k + 5, BlockList.netherizedObsidian);
		world.setBlock(i + 12, j + 10, k + 6, BlockList.netherizedObsidian);
		world.setBlock(i + 12, j + 10, k + 7, BlockList.netherizedObsidian);
		world.setBlock(i + 12, j + 10, k + 8, BlockList.netherizedObsidian);
		world.setBlock(i + 12, j + 10, k + 9, BlockList.netherizedObsidian);
		world.setBlock(i + 12, j + 10, k + 10, BlockList.netherizedObsidian);
		world.setBlock(i + 12, j + 10, k + 11, BlockList.netherizedObsidian);
		world.setBlock(i + 12, j + 10, k + 12, BlockList.netherizedObsidian);
		world.setBlock(i + 13, j + 0, k + 0, BlockList.netherizedObsidian);
		world.setBlock(i + 13, j + 0, k + 1, Blocks.obsidian);
		world.setBlock(i + 13, j + 0, k + 2, Blocks.obsidian);
		world.setBlock(i + 13, j + 0, k + 3, Blocks.obsidian);
		world.setBlock(i + 13, j + 0, k + 4, Blocks.obsidian);
		world.setBlock(i + 13, j + 0, k + 5, Blocks.obsidian);
		world.setBlock(i + 13, j + 0, k + 6, Blocks.obsidian);
		world.setBlock(i + 13, j + 0, k + 7, Blocks.obsidian);
		world.setBlock(i + 13, j + 0, k + 8, Blocks.obsidian);
		world.setBlock(i + 13, j + 0, k + 9, Blocks.obsidian);
		world.setBlock(i + 13, j + 0, k + 10, Blocks.obsidian);
		world.setBlock(i + 13, j + 0, k + 11, Blocks.obsidian);
		world.setBlock(i + 13, j + 0, k + 12, Blocks.obsidian);
		world.setBlock(i + 13, j + 0, k + 13, Blocks.obsidian);
		world.setBlock(i + 13, j + 0, k + 14, Blocks.obsidian);
		world.setBlock(i + 13, j + 0, k + 15, Blocks.obsidian);
		world.setBlock(i + 13, j + 0, k + 16, Blocks.obsidian);
		world.setBlock(i + 13, j + 0, k + 17, BlockList.netherizedObsidian);
		world.setBlock(i + 13, j + 1, k + 1, BlockList.netherizedObsidian);
		world.setBlock(i + 13, j + 1, k + 16, BlockList.netherizedObsidian);
		world.setBlock(i + 13, j + 2, k + 2, BlockList.netherizedObsidian);
		world.setBlock(i + 13, j + 2, k + 15, BlockList.netherizedObsidian);
		world.setBlock(i + 13, j + 3, k + 3, BlockList.netherizedObsidian);
		world.setBlock(i + 13, j + 3, k + 14, BlockList.netherizedObsidian);
		world.setBlock(i + 13, j + 4, k + 4, BlockList.netherizedObsidian);
		world.setBlock(i + 13, j + 4, k + 13, BlockList.netherizedObsidian);
		world.setBlock(i + 13, j + 5, k + 4, BlockList.netherizedObsidian);
		world.setBlock(i + 13, j + 5, k + 13, BlockList.netherizedObsidian);
		world.setBlock(i + 13, j + 6, k + 4, BlockList.netherizedObsidian);
		world.setBlock(i + 13, j + 6, k + 13, BlockList.netherizedObsidian);
		world.setBlock(i + 13, j + 7, k + 4, BlockList.netherizedObsidian);
		world.setBlock(i + 13, j + 7, k + 13, BlockList.netherizedObsidian);
		world.setBlock(i + 13, j + 8, k + 4, BlockList.netherizedObsidian);
		world.setBlock(i + 13, j + 8, k + 13, BlockList.netherizedObsidian);
		world.setBlock(i + 13, j + 9, k + 4, BlockList.netherizedObsidian);
		world.setBlock(i + 13, j + 9, k + 13, BlockList.netherizedObsidian);
		world.setBlock(i + 13, j + 10, k + 5, BlockList.netherizedObsidian);
		world.setBlock(i + 13, j + 10, k + 6, BlockList.netherizedObsidian);
		world.setBlock(i + 13, j + 10, k + 7, BlockList.netherizedObsidian);
		world.setBlock(i + 13, j + 10, k + 8, BlockList.netherizedObsidian);
		world.setBlock(i + 13, j + 10, k + 9, BlockList.netherizedObsidian);
		world.setBlock(i + 13, j + 10, k + 10, BlockList.netherizedObsidian);
		world.setBlock(i + 13, j + 10, k + 11, BlockList.netherizedObsidian);
		world.setBlock(i + 13, j + 10, k + 12, BlockList.netherizedObsidian);
		world.setBlock(i + 14, j + 0, k + 0, BlockList.netherizedObsidian);
		world.setBlock(i + 14, j + 0, k + 1, Blocks.obsidian);
		world.setBlock(i + 14, j + 0, k + 2, Blocks.obsidian);
		world.setBlock(i + 14, j + 0, k + 3, Blocks.obsidian);
		world.setBlock(i + 14, j + 0, k + 4, Blocks.obsidian);
		world.setBlock(i + 14, j + 0, k + 5, Blocks.obsidian);
		world.setBlock(i + 14, j + 0, k + 6, Blocks.obsidian);
		world.setBlock(i + 14, j + 0, k + 7, Blocks.obsidian);
		world.setBlock(i + 14, j + 0, k + 8, Blocks.obsidian);
		world.setBlock(i + 14, j + 0, k + 9, Blocks.obsidian);
		world.setBlock(i + 14, j + 0, k + 10, Blocks.obsidian);
		world.setBlock(i + 14, j + 0, k + 11, Blocks.obsidian);
		world.setBlock(i + 14, j + 0, k + 12, Blocks.obsidian);
		world.setBlock(i + 14, j + 0, k + 13, Blocks.obsidian);
		world.setBlock(i + 14, j + 0, k + 14, Blocks.obsidian);
		world.setBlock(i + 14, j + 0, k + 15, Blocks.obsidian);
		world.setBlock(i + 14, j + 0, k + 16, Blocks.obsidian);
		world.setBlock(i + 14, j + 0, k + 17, BlockList.netherizedObsidian);
		world.setBlock(i + 14, j + 1, k + 1, BlockList.netherizedObsidian);
		world.setBlock(i + 14, j + 1, k + 16, BlockList.netherizedObsidian);
		world.setBlock(i + 14, j + 2, k + 2, BlockList.netherizedObsidian);
		world.setBlock(i + 14, j + 2, k + 15, BlockList.netherizedObsidian);
		world.setBlock(i + 14, j + 3, k + 3, BlockList.netherizedObsidian);
		world.setBlock(i + 14, j + 3, k + 14, BlockList.netherizedObsidian);
		world.setBlock(i + 14, j + 4, k + 4, BlockList.netherizedObsidian);
		world.setBlock(i + 14, j + 4, k + 5, BlockList.netherizedObsidian);
		world.setBlock(i + 14, j + 4, k + 6, BlockList.netherizedObsidian);
		world.setBlock(i + 14, j + 4, k + 7, BlockList.netherizedObsidian);
		world.setBlock(i + 14, j + 4, k + 9, BlockList.netherizedObsidian);
		world.setBlock(i + 14, j + 4, k + 10, BlockList.netherizedObsidian);
		world.setBlock(i + 14, j + 4, k + 11, BlockList.netherizedObsidian);
		world.setBlock(i + 14, j + 4, k + 12, BlockList.netherizedObsidian);
		world.setBlock(i + 14, j + 4, k + 13, BlockList.netherizedObsidian);
		world.setBlock(i + 14, j + 5, k + 4, BlockList.netherizedObsidian);
		world.setBlock(i + 14, j + 5, k + 5, BlockList.netherizedObsidian);
		world.setBlock(i + 14, j + 5, k + 6, BlockList.netherizedObsidian);
		world.setBlock(i + 14, j + 5, k + 7, BlockList.netherizedObsidian);
		world.setBlock(i + 14, j + 5, k + 9, BlockList.netherizedObsidian);
		world.setBlock(i + 14, j + 5, k + 10, BlockList.netherizedObsidian);
		world.setBlock(i + 14, j + 5, k + 11, BlockList.netherizedObsidian);
		world.setBlock(i + 14, j + 5, k + 12, BlockList.netherizedObsidian);
		world.setBlock(i + 14, j + 5, k + 13, BlockList.netherizedObsidian);
		world.setBlock(i + 14, j + 6, k + 4, BlockList.netherizedObsidian);
		world.setBlock(i + 14, j + 6, k + 5, BlockList.netherizedObsidian);
		world.setBlock(i + 14, j + 6, k + 6, BlockList.netherizedObsidian);
		world.setBlock(i + 14, j + 6, k + 7, BlockList.netherizedObsidian);
		world.setBlock(i + 14, j + 6, k + 8, BlockList.netherizedObsidian);
		world.setBlock(i + 14, j + 6, k + 9, BlockList.netherizedObsidian);
		world.setBlock(i + 14, j + 6, k + 10, BlockList.netherizedObsidian);
		world.setBlock(i + 14, j + 6, k + 11, BlockList.netherizedObsidian);
		world.setBlock(i + 14, j + 6, k + 12, BlockList.netherizedObsidian);
		world.setBlock(i + 14, j + 6, k + 13, BlockList.netherizedObsidian);
		world.setBlock(i + 14, j + 7, k + 4, BlockList.netherizedObsidian);
		world.setBlock(i + 14, j + 7, k + 5, BlockList.netherizedObsidian);
		world.setBlock(i + 14, j + 7, k + 6, BlockList.netherizedObsidian);
		world.setBlock(i + 14, j + 7, k + 7, BlockList.netherizedObsidian);
		world.setBlock(i + 14, j + 7, k + 8, BlockList.netherizedObsidian);
		world.setBlock(i + 14, j + 7, k + 9, BlockList.netherizedObsidian);
		world.setBlock(i + 14, j + 7, k + 10, BlockList.netherizedObsidian);
		world.setBlock(i + 14, j + 7, k + 11, BlockList.netherizedObsidian);
		world.setBlock(i + 14, j + 7, k + 12, BlockList.netherizedObsidian);
		world.setBlock(i + 14, j + 7, k + 13, BlockList.netherizedObsidian);
		world.setBlock(i + 14, j + 8, k + 4, BlockList.netherizedObsidian);
		world.setBlock(i + 14, j + 8, k + 5, BlockList.netherizedObsidian);
		world.setBlock(i + 14, j + 8, k + 6, BlockList.netherizedObsidian);
		world.setBlock(i + 14, j + 8, k + 7, BlockList.netherizedObsidian);
		world.setBlock(i + 14, j + 8, k + 8, BlockList.netherizedObsidian);
		world.setBlock(i + 14, j + 8, k + 9, BlockList.netherizedObsidian);
		world.setBlock(i + 14, j + 8, k + 10, BlockList.netherizedObsidian);
		world.setBlock(i + 14, j + 8, k + 11, BlockList.netherizedObsidian);
		world.setBlock(i + 14, j + 8, k + 12, BlockList.netherizedObsidian);
		world.setBlock(i + 14, j + 8, k + 13, BlockList.netherizedObsidian);
		world.setBlock(i + 14, j + 9, k + 4, BlockList.netherizedObsidian);
		world.setBlock(i + 14, j + 9, k + 5, BlockList.netherizedObsidian);
		world.setBlock(i + 14, j + 9, k + 6, BlockList.netherizedObsidian);
		world.setBlock(i + 14, j + 9, k + 7, BlockList.netherizedObsidian);
		world.setBlock(i + 14, j + 9, k + 8, BlockList.netherizedObsidian);
		world.setBlock(i + 14, j + 9, k + 9, BlockList.netherizedObsidian);
		world.setBlock(i + 14, j + 9, k + 10, BlockList.netherizedObsidian);
		world.setBlock(i + 14, j + 9, k + 11, BlockList.netherizedObsidian);
		world.setBlock(i + 14, j + 9, k + 12, BlockList.netherizedObsidian);
		world.setBlock(i + 14, j + 9, k + 13, BlockList.netherizedObsidian);
		world.setBlock(i + 15, j + 0, k + 0, BlockList.netherizedObsidian);
		world.setBlock(i + 15, j + 0, k + 1, Blocks.obsidian);
		world.setBlock(i + 15, j + 0, k + 2, Blocks.obsidian);
		world.setBlock(i + 15, j + 0, k + 3, Blocks.obsidian);
		world.setBlock(i + 15, j + 0, k + 4, Blocks.obsidian);
		world.setBlock(i + 15, j + 0, k + 5, Blocks.obsidian);
		world.setBlock(i + 15, j + 0, k + 6, Blocks.obsidian);
		world.setBlock(i + 15, j + 0, k + 7, Blocks.obsidian);
		world.setBlock(i + 15, j + 0, k + 8, Blocks.obsidian);
		world.setBlock(i + 15, j + 0, k + 9, Blocks.obsidian);
		world.setBlock(i + 15, j + 0, k + 10, Blocks.obsidian);
		world.setBlock(i + 15, j + 0, k + 11, Blocks.obsidian);
		world.setBlock(i + 15, j + 0, k + 12, Blocks.obsidian);
		world.setBlock(i + 15, j + 0, k + 13, Blocks.obsidian);
		world.setBlock(i + 15, j + 0, k + 14, Blocks.obsidian);
		world.setBlock(i + 15, j + 0, k + 15, Blocks.obsidian);
		world.setBlock(i + 15, j + 0, k + 16, Blocks.obsidian);
		world.setBlock(i + 15, j + 0, k + 17, BlockList.netherizedObsidian);
		world.setBlock(i + 15, j + 1, k + 1, BlockList.netherizedObsidian);
		world.setBlock(i + 15, j + 1, k + 16, BlockList.netherizedObsidian);
		world.setBlock(i + 15, j + 2, k + 2, BlockList.netherizedObsidian);
		world.setBlock(i + 15, j + 2, k + 15, BlockList.netherizedObsidian);
		world.setBlock(i + 15, j + 3, k + 3, BlockList.netherizedObsidian);
		world.setBlock(i + 15, j + 3, k + 4, BlockList.netherizedObsidian);
		world.setBlock(i + 15, j + 3, k + 5, BlockList.netherizedObsidian);
		world.setBlock(i + 15, j + 3, k + 6, BlockList.netherizedObsidian);
		world.setBlock(i + 15, j + 3, k + 7, BlockList.netherizedObsidian);
		world.setBlock(i + 15, j + 3, k + 8, BlockList.netherizedObsidian);
		world.setBlock(i + 15, j + 3, k + 9, BlockList.netherizedObsidian);
		world.setBlock(i + 15, j + 3, k + 10, BlockList.netherizedObsidian);
		world.setBlock(i + 15, j + 3, k + 11, BlockList.netherizedObsidian);
		world.setBlock(i + 15, j + 3, k + 12, BlockList.netherizedObsidian);
		world.setBlock(i + 15, j + 3, k + 13, BlockList.netherizedObsidian);
		world.setBlock(i + 15, j + 3, k + 14, BlockList.netherizedObsidian);
		world.setBlock(i + 16, j + 0, k + 0, BlockList.netherizedObsidian);
		world.setBlock(i + 16, j + 0, k + 1, Blocks.obsidian);
		world.setBlock(i + 16, j + 0, k + 2, Blocks.obsidian);
		world.setBlock(i + 16, j + 0, k + 3, Blocks.obsidian);
		world.setBlock(i + 16, j + 0, k + 4, Blocks.obsidian);
		world.setBlock(i + 16, j + 0, k + 5, Blocks.obsidian);
		world.setBlock(i + 16, j + 0, k + 6, Blocks.obsidian);
		world.setBlock(i + 16, j + 0, k + 7, Blocks.obsidian);
		world.setBlock(i + 16, j + 0, k + 8, Blocks.obsidian);
		world.setBlock(i + 16, j + 0, k + 9, Blocks.obsidian);
		world.setBlock(i + 16, j + 0, k + 10, Blocks.obsidian);
		world.setBlock(i + 16, j + 0, k + 11, Blocks.obsidian);
		world.setBlock(i + 16, j + 0, k + 12, Blocks.obsidian);
		world.setBlock(i + 16, j + 0, k + 13, Blocks.obsidian);
		world.setBlock(i + 16, j + 0, k + 14, Blocks.obsidian);
		world.setBlock(i + 16, j + 0, k + 15, Blocks.obsidian);
		world.setBlock(i + 16, j + 0, k + 16, Blocks.obsidian);
		world.setBlock(i + 16, j + 0, k + 17, BlockList.netherizedObsidian);
		world.setBlock(i + 16, j + 1, k + 1, BlockList.netherizedObsidian);
		world.setBlock(i + 16, j + 1, k + 16, BlockList.netherizedObsidian);
		world.setBlock(i + 16, j + 2, k + 2, BlockList.netherizedObsidian);
		world.setBlock(i + 16, j + 2, k + 3, BlockList.netherizedObsidian);
		world.setBlock(i + 16, j + 2, k + 4, BlockList.netherizedObsidian);
		world.setBlock(i + 16, j + 2, k + 5, BlockList.netherizedObsidian);
		world.setBlock(i + 16, j + 2, k + 6, BlockList.netherizedObsidian);
		world.setBlock(i + 16, j + 2, k + 7, BlockList.netherizedObsidian);
		world.setBlock(i + 16, j + 2, k + 8, BlockList.netherizedObsidian);
		world.setBlock(i + 16, j + 2, k + 9, BlockList.netherizedObsidian);
		world.setBlock(i + 16, j + 2, k + 10, BlockList.netherizedObsidian);
		world.setBlock(i + 16, j + 2, k + 11, BlockList.netherizedObsidian);
		world.setBlock(i + 16, j + 2, k + 12, BlockList.netherizedObsidian);
		world.setBlock(i + 16, j + 2, k + 13, BlockList.netherizedObsidian);
		world.setBlock(i + 16, j + 2, k + 14, BlockList.netherizedObsidian);
		world.setBlock(i + 16, j + 2, k + 15, BlockList.netherizedObsidian);
		world.setBlock(i + 17, j + 0, k + 0, BlockList.netherizedObsidian);
		world.setBlock(i + 17, j + 0, k + 1, Blocks.obsidian);
		world.setBlock(i + 17, j + 0, k + 2, Blocks.obsidian);
		world.setBlock(i + 17, j + 0, k + 3, Blocks.obsidian);
		world.setBlock(i + 17, j + 0, k + 4, Blocks.obsidian);
		world.setBlock(i + 17, j + 0, k + 5, Blocks.obsidian);
		world.setBlock(i + 17, j + 0, k + 6, Blocks.obsidian);
		world.setBlock(i + 17, j + 0, k + 7, Blocks.obsidian);
		world.setBlock(i + 17, j + 0, k + 8, Blocks.obsidian);
		world.setBlock(i + 17, j + 0, k + 9, Blocks.obsidian);
		world.setBlock(i + 17, j + 0, k + 10, Blocks.obsidian);
		world.setBlock(i + 17, j + 0, k + 11, Blocks.obsidian);
		world.setBlock(i + 17, j + 0, k + 12, Blocks.obsidian);
		world.setBlock(i + 17, j + 0, k + 13, Blocks.obsidian);
		world.setBlock(i + 17, j + 0, k + 14, Blocks.obsidian);
		world.setBlock(i + 17, j + 0, k + 15, Blocks.obsidian);
		world.setBlock(i + 17, j + 0, k + 16, Blocks.obsidian);
		world.setBlock(i + 17, j + 0, k + 17, BlockList.netherizedObsidian);
		world.setBlock(i + 17, j + 1, k + 1, BlockList.netherizedObsidian);
		world.setBlock(i + 17, j + 1, k + 2, BlockList.netherizedObsidian);
		world.setBlock(i + 17, j + 1, k + 3, BlockList.netherizedObsidian);
		world.setBlock(i + 17, j + 1, k + 4, BlockList.netherizedObsidian);
		world.setBlock(i + 17, j + 1, k + 5, BlockList.netherizedObsidian);
		world.setBlock(i + 17, j + 1, k + 6, BlockList.netherizedObsidian);
		world.setBlock(i + 17, j + 1, k + 7, BlockList.netherizedObsidian);
		world.setBlock(i + 17, j + 1, k + 8, BlockList.netherizedObsidian);
		world.setBlock(i + 17, j + 1, k + 9, BlockList.netherizedObsidian);
		world.setBlock(i + 17, j + 1, k + 10, BlockList.netherizedObsidian);
		world.setBlock(i + 17, j + 1, k + 11, BlockList.netherizedObsidian);
		world.setBlock(i + 17, j + 1, k + 12, BlockList.netherizedObsidian);
		world.setBlock(i + 17, j + 1, k + 13, BlockList.netherizedObsidian);
		world.setBlock(i + 17, j + 1, k + 14, BlockList.netherizedObsidian);
		world.setBlock(i + 17, j + 1, k + 15, BlockList.netherizedObsidian);
		world.setBlock(i + 17, j + 1, k + 16, BlockList.netherizedObsidian);
		world.setBlock(i + 18, j + 0, k + 0, BlockList.netherizedObsidian);
		world.setBlock(i + 18, j + 0, k + 1, BlockList.netherizedObsidian);
		world.setBlock(i + 18, j + 0, k + 2, BlockList.netherizedObsidian);
		world.setBlock(i + 18, j + 0, k + 3, BlockList.netherizedObsidian);
		world.setBlock(i + 18, j + 0, k + 4, BlockList.netherizedObsidian);
		world.setBlock(i + 18, j + 0, k + 5, BlockList.netherizedObsidian);
		world.setBlock(i + 18, j + 0, k + 6, BlockList.netherizedObsidian);
		world.setBlock(i + 18, j + 0, k + 7, BlockList.netherizedObsidian);
		world.setBlock(i + 18, j + 0, k + 8, BlockList.netherizedObsidian);
		world.setBlock(i + 18, j + 0, k + 9, BlockList.netherizedObsidian);
		world.setBlock(i + 18, j + 0, k + 10, BlockList.netherizedObsidian);
		world.setBlock(i + 18, j + 0, k + 11, BlockList.netherizedObsidian);
		world.setBlock(i + 18, j + 0, k + 12, BlockList.netherizedObsidian);
		world.setBlock(i + 18, j + 0, k + 13, BlockList.netherizedObsidian);
		world.setBlock(i + 18, j + 0, k + 14, BlockList.netherizedObsidian);
		world.setBlock(i + 18, j + 0, k + 15, BlockList.netherizedObsidian);
		world.setBlock(i + 18, j + 0, k + 16, BlockList.netherizedObsidian);
		world.setBlock(i + 18, j + 0, k + 17, BlockList.netherizedObsidian);
		
		if (!world.isRemote) {
			EntityShadowAlien shadowAlien = new EntityShadowAlien(world);
			shadowAlien.setLocationAndAngles(i + 8, j + 2, k + 8, 0, 0);
			world.spawnEntityInWorld(shadowAlien);
			MainHelper.Log("Shadow Alien spawned at: " + (i + 8) + " "
					+ (j + 2) + " " + (k + 8));
		}
		
		return true;
	}
}