package zollernextras.worldgen;

import java.util.Random;
import net.minecraft.block.Block;
import net.minecraft.init.Blocks;
import net.minecraft.world.World;
import net.minecraft.world.gen.feature.WorldGenerator;

public class WorldGenCastle extends WorldGenerator {
	
	protected Block[] GetValidSpawnBlocks() {
		return new Block[] { Blocks.air };
	}
	
	public boolean LocationIsValidSpawn(World world, int i, int j, int k) {
		int distanceToAir = 0;
		Block checkID = world.getBlock(i, j, k);
		
		while (checkID != Blocks.air) {
			distanceToAir++;
			checkID = world.getBlock(i, j + distanceToAir, k);
		}
		
		if (distanceToAir > 3) {
			return false;
		}
		j += distanceToAir - 1;
		
		Block blockID = world.getBlock(i, j, k);
		Block blockIDAbove = world.getBlock(i, j + 1, k);
		Block blockIDBelow = world.getBlock(i, j - 1, k);
		for (Block x : GetValidSpawnBlocks()) {
			if (blockIDAbove != Blocks.air) {
				return false;
			}
			if (blockID == x) {
				return true;
			} else if (blockID == Blocks.snow && blockIDBelow == x) {
				return true;
			}
		}
		return false;
	}
	
	public WorldGenCastle() {
	}
	
	@Override
	public boolean generate(World world, Random rand, int i, int j, int k) {
		world.setBlock(i + 0, j + 0, k + 0, Blocks.stonebrick);
		world.setBlock(i + 0, j + 0, k + 1, Blocks.stonebrick);
		world.setBlock(i + 0, j + 0, k + 2, Blocks.stonebrick);
		world.setBlock(i + 0, j + 0, k + 3, Blocks.stonebrick);
		world.setBlock(i + 0, j + 0, k + 4, Blocks.stonebrick);
		world.setBlock(i + 0, j + 0, k + 5, Blocks.stonebrick);
		world.setBlock(i + 0, j + 0, k + 6, Blocks.stonebrick);
		world.setBlock(i + 0, j + 0, k + 7, Blocks.stonebrick);
		world.setBlock(i + 0, j + 0, k + 8, Blocks.stonebrick);
		world.setBlock(i + 0, j + 0, k + 9, Blocks.stonebrick);
		world.setBlock(i + 0, j + 0, k + 10, Blocks.stonebrick);
		world.setBlock(i + 0, j + 0, k + 11, Blocks.stonebrick);
		world.setBlock(i + 0, j + 0, k + 12, Blocks.stonebrick);
		world.setBlock(i + 0, j + 0, k + 13, Blocks.stonebrick);
		world.setBlock(i + 0, j + 0, k + 14, Blocks.stonebrick);
		world.setBlock(i + 0, j + 0, k + 15, Blocks.stonebrick);// SPOT
		world.setBlock(i + 0, j + 1, k + 0, Blocks.stonebrick);
		world.setBlock(i + 0, j + 1, k + 1, Blocks.stonebrick);
		world.setBlock(i + 0, j + 1, k + 2, Blocks.stonebrick);
		world.setBlock(i + 0, j + 1, k + 3, Blocks.stonebrick);
		world.setBlock(i + 0, j + 1, k + 4, Blocks.stonebrick);
		world.setBlock(i + 0, j + 1, k + 5, Blocks.stonebrick);
		world.setBlock(i + 0, j + 1, k + 6, Blocks.stonebrick);
		world.setBlock(i + 0, j + 1, k + 7, Blocks.stonebrick);
		world.setBlock(i + 0, j + 1, k + 8, Blocks.stonebrick);
		world.setBlock(i + 0, j + 1, k + 9, Blocks.stonebrick);
		world.setBlock(i + 0, j + 1, k + 10, Blocks.stonebrick);
		world.setBlock(i + 0, j + 1, k + 11, Blocks.stonebrick);
		world.setBlock(i + 0, j + 1, k + 12, Blocks.stonebrick);
		world.setBlock(i + 0, j + 1, k + 13, Blocks.stonebrick);
		world.setBlock(i + 0, j + 1, k + 14, Blocks.stonebrick);
		world.setBlock(i + 0, j + 1, k + 15, Blocks.stonebrick);
		world.setBlock(i + 0, j + 2, k + 0, Blocks.stonebrick);
		world.setBlock(i + 0, j + 2, k + 1, Blocks.stonebrick);
		world.setBlock(i + 0, j + 2, k + 2, Blocks.stonebrick);
		world.setBlock(i + 0, j + 2, k + 3, Blocks.stonebrick);
		world.setBlock(i + 0, j + 2, k + 4, Blocks.stonebrick);
		world.setBlock(i + 0, j + 2, k + 5, Blocks.stonebrick);
		world.setBlock(i + 0, j + 2, k + 6, Blocks.stonebrick);
		world.setBlock(i + 0, j + 2, k + 7, Blocks.stonebrick);
		world.setBlock(i + 0, j + 2, k + 8, Blocks.stonebrick);
		world.setBlock(i + 0, j + 2, k + 9, Blocks.stonebrick);
		world.setBlock(i + 0, j + 2, k + 10, Blocks.stonebrick);
		world.setBlock(i + 0, j + 2, k + 11, Blocks.stonebrick);
		world.setBlock(i + 0, j + 2, k + 12, Blocks.stonebrick);
		world.setBlock(i + 0, j + 2, k + 13, Blocks.stonebrick);
		world.setBlock(i + 0, j + 2, k + 14, Blocks.stonebrick);
		world.setBlock(i + 0, j + 2, k + 15, Blocks.stonebrick);
		world.setBlock(i + 0, j + 3, k + 0, Blocks.stonebrick);
		world.setBlock(i + 0, j + 3, k + 1, Blocks.stonebrick);
		world.setBlock(i + 0, j + 3, k + 2, Blocks.stonebrick);
		world.setBlock(i + 0, j + 3, k + 3, Blocks.stonebrick);
		world.setBlock(i + 0, j + 3, k + 4, Blocks.stonebrick);
		world.setBlock(i + 0, j + 3, k + 5, Blocks.stonebrick);
		world.setBlock(i + 0, j + 3, k + 6, Blocks.stonebrick);
		world.setBlock(i + 0, j + 3, k + 7, Blocks.stonebrick);
		world.setBlock(i + 0, j + 3, k + 8, Blocks.stonebrick);
		world.setBlock(i + 0, j + 3, k + 9, Blocks.stonebrick);
		world.setBlock(i + 0, j + 3, k + 10, Blocks.stonebrick);
		world.setBlock(i + 0, j + 3, k + 11, Blocks.stonebrick);
		world.setBlock(i + 0, j + 3, k + 12, Blocks.stonebrick);
		world.setBlock(i + 0, j + 3, k + 13, Blocks.stonebrick);
		world.setBlock(i + 0, j + 3, k + 14, Blocks.stonebrick);
		world.setBlock(i + 0, j + 3, k + 15, Blocks.stonebrick);
		world.setBlock(i + 0, j + 4, k + 0, Blocks.stonebrick);
		world.setBlock(i + 0, j + 4, k + 1, Blocks.stonebrick);
		world.setBlock(i + 0, j + 4, k + 2, Blocks.stonebrick);
		world.setBlock(i + 0, j + 4, k + 3, Blocks.stonebrick);
		world.setBlock(i + 0, j + 4, k + 4, Blocks.stonebrick);
		world.setBlock(i + 0, j + 4, k + 5, Blocks.stonebrick);
		world.setBlock(i + 0, j + 4, k + 6, Blocks.stonebrick);
		world.setBlock(i + 0, j + 4, k + 7, Blocks.stonebrick);
		world.setBlock(i + 0, j + 4, k + 8, Blocks.stonebrick);
		world.setBlock(i + 0, j + 4, k + 9, Blocks.stonebrick);
		world.setBlock(i + 0, j + 4, k + 10, Blocks.stonebrick);
		world.setBlock(i + 0, j + 4, k + 11, Blocks.stonebrick);
		world.setBlock(i + 0, j + 4, k + 12, Blocks.stonebrick);
		world.setBlock(i + 0, j + 4, k + 13, Blocks.stonebrick);
		world.setBlock(i + 0, j + 4, k + 14, Blocks.stonebrick);
		world.setBlock(i + 0, j + 4, k + 15, Blocks.stonebrick);
		world.setBlock(i + 0, j + 5, k + 0, Blocks.stonebrick);
		world.setBlock(i + 0, j + 5, k + 1, Blocks.stonebrick);
		world.setBlock(i + 0, j + 5, k + 2, Blocks.stonebrick);
		world.setBlock(i + 0, j + 5, k + 3, Blocks.stonebrick);
		world.setBlock(i + 0, j + 5, k + 4, Blocks.stonebrick);
		world.setBlock(i + 0, j + 5, k + 5, Blocks.stonebrick);
		world.setBlock(i + 0, j + 5, k + 6, Blocks.stonebrick);
		world.setBlock(i + 0, j + 5, k + 7, Blocks.stonebrick);
		world.setBlock(i + 0, j + 5, k + 8, Blocks.stonebrick);
		world.setBlock(i + 0, j + 5, k + 9, Blocks.stonebrick);
		world.setBlock(i + 0, j + 5, k + 10, Blocks.stonebrick);
		world.setBlock(i + 0, j + 5, k + 11, Blocks.stonebrick);
		world.setBlock(i + 0, j + 5, k + 12, Blocks.stonebrick);
		world.setBlock(i + 0, j + 5, k + 13, Blocks.stonebrick);
		world.setBlock(i + 0, j + 5, k + 14, Blocks.stonebrick);
		world.setBlock(i + 0, j + 5, k + 15, Blocks.stonebrick);
		world.setBlock(i + 0, j + 6, k + 0, Blocks.stonebrick);
		world.setBlock(i + 0, j + 6, k + 1, Blocks.stonebrick);
		world.setBlock(i + 0, j + 6, k + 2, Blocks.stonebrick);
		world.setBlock(i + 0, j + 6, k + 3, Blocks.stonebrick);
		world.setBlock(i + 0, j + 6, k + 4, Blocks.stonebrick);
		world.setBlock(i + 0, j + 6, k + 5, Blocks.stonebrick);
		world.setBlock(i + 0, j + 6, k + 6, Blocks.stonebrick);
		world.setBlock(i + 0, j + 6, k + 7, Blocks.stonebrick);
		world.setBlock(i + 0, j + 6, k + 8, Blocks.stonebrick);
		world.setBlock(i + 0, j + 6, k + 9, Blocks.stonebrick);
		world.setBlock(i + 0, j + 6, k + 10, Blocks.stonebrick);
		world.setBlock(i + 0, j + 6, k + 11, Blocks.stonebrick);
		world.setBlock(i + 0, j + 6, k + 12, Blocks.stonebrick);
		world.setBlock(i + 0, j + 6, k + 13, Blocks.stonebrick);
		world.setBlock(i + 0, j + 6, k + 14, Blocks.stonebrick);
		world.setBlock(i + 0, j + 6, k + 15, Blocks.stonebrick);
		world.setBlock(i + 0, j + 7, k + 0, Blocks.stonebrick);
		world.setBlock(i + 0, j + 7, k + 1, Blocks.stonebrick);
		world.setBlock(i + 0, j + 7, k + 2, Blocks.stonebrick);
		world.setBlock(i + 0, j + 7, k + 3, Blocks.stonebrick);
		world.setBlock(i + 0, j + 7, k + 4, Blocks.stonebrick);
		world.setBlock(i + 0, j + 7, k + 5, Blocks.stonebrick);
		world.setBlock(i + 0, j + 7, k + 6, Blocks.stonebrick);
		world.setBlock(i + 0, j + 7, k + 7, Blocks.stonebrick);
		world.setBlock(i + 0, j + 7, k + 8, Blocks.stonebrick);
		world.setBlock(i + 0, j + 7, k + 9, Blocks.stonebrick);
		world.setBlock(i + 0, j + 7, k + 10, Blocks.stonebrick);
		world.setBlock(i + 0, j + 7, k + 11, Blocks.stonebrick);
		world.setBlock(i + 0, j + 7, k + 12, Blocks.stonebrick);
		world.setBlock(i + 0, j + 7, k + 13, Blocks.stonebrick);
		world.setBlock(i + 0, j + 7, k + 14, Blocks.stonebrick);
		world.setBlock(i + 0, j + 7, k + 15, Blocks.stonebrick);
		world.setBlock(i + 0, j + 8, k + 0, Blocks.stonebrick);
		world.setBlock(i + 0, j + 8, k + 1, Blocks.stonebrick);
		world.setBlock(i + 0, j + 8, k + 2, Blocks.stonebrick);
		world.setBlock(i + 0, j + 8, k + 3, Blocks.stonebrick);
		world.setBlock(i + 0, j + 8, k + 4, Blocks.stonebrick);
		world.setBlock(i + 0, j + 8, k + 5, Blocks.stonebrick);
		world.setBlock(i + 0, j + 8, k + 6, Blocks.stonebrick);
		world.setBlock(i + 0, j + 8, k + 7, Blocks.stonebrick);
		world.setBlock(i + 0, j + 8, k + 8, Blocks.stonebrick);
		world.setBlock(i + 0, j + 8, k + 9, Blocks.stonebrick);
		world.setBlock(i + 0, j + 8, k + 10, Blocks.stonebrick);
		world.setBlock(i + 0, j + 8, k + 11, Blocks.stonebrick);
		world.setBlock(i + 0, j + 8, k + 12, Blocks.stonebrick);
		world.setBlock(i + 0, j + 8, k + 13, Blocks.stonebrick);
		world.setBlock(i + 0, j + 8, k + 14, Blocks.stonebrick);
		world.setBlock(i + 0, j + 8, k + 15, Blocks.stonebrick);
		world.setBlock(i + 0, j + 9, k + 0, Blocks.stonebrick);
		world.setBlock(i + 0, j + 9, k + 1, Blocks.stonebrick);
		world.setBlock(i + 0, j + 9, k + 2, Blocks.stonebrick);
		world.setBlock(i + 0, j + 9, k + 3, Blocks.stonebrick);
		world.setBlock(i + 0, j + 9, k + 4, Blocks.stonebrick);
		world.setBlock(i + 0, j + 9, k + 5, Blocks.stonebrick);
		world.setBlock(i + 0, j + 9, k + 6, Blocks.stonebrick);
		world.setBlock(i + 0, j + 9, k + 7, Blocks.stonebrick);
		world.setBlock(i + 0, j + 9, k + 8, Blocks.stonebrick);
		world.setBlock(i + 0, j + 9, k + 9, Blocks.stonebrick);
		world.setBlock(i + 0, j + 9, k + 10, Blocks.stonebrick);
		world.setBlock(i + 0, j + 9, k + 11, Blocks.stonebrick);
		world.setBlock(i + 0, j + 9, k + 12, Blocks.stonebrick);
		world.setBlock(i + 0, j + 9, k + 13, Blocks.stonebrick);
		world.setBlock(i + 0, j + 9, k + 14, Blocks.stonebrick);
		world.setBlock(i + 0, j + 9, k + 15, Blocks.stonebrick);
		world.setBlock(i + 0, j + 10, k + 0, Blocks.stonebrick);
		world.setBlock(i + 0, j + 10, k + 1, Blocks.stonebrick);
		world.setBlock(i + 0, j + 10, k + 2, Blocks.stonebrick);
		world.setBlock(i + 0, j + 10, k + 3, Blocks.stonebrick);
		world.setBlock(i + 0, j + 10, k + 4, Blocks.stonebrick);
		world.setBlock(i + 0, j + 10, k + 5, Blocks.stonebrick);
		world.setBlock(i + 0, j + 10, k + 6, Blocks.stonebrick);
		world.setBlock(i + 0, j + 10, k + 7, Blocks.stonebrick);
		world.setBlock(i + 0, j + 10, k + 8, Blocks.stonebrick);
		world.setBlock(i + 0, j + 10, k + 9, Blocks.stonebrick);
		world.setBlock(i + 0, j + 10, k + 10, Blocks.stonebrick);
		world.setBlock(i + 0, j + 10, k + 11, Blocks.stonebrick);
		world.setBlock(i + 0, j + 10, k + 12, Blocks.stonebrick);
		world.setBlock(i + 0, j + 10, k + 13, Blocks.stonebrick);
		world.setBlock(i + 0, j + 10, k + 14, Blocks.stonebrick);
		world.setBlock(i + 0, j + 10, k + 15, Blocks.stonebrick);
		world.setBlock(i + 0, j + 11, k + 0, Blocks.stonebrick);
		world.setBlock(i + 0, j + 11, k + 1, Blocks.stonebrick);
		world.setBlock(i + 0, j + 11, k + 2, Blocks.stonebrick);
		world.setBlock(i + 0, j + 11, k + 3, Blocks.stonebrick);
		world.setBlock(i + 0, j + 11, k + 4, Blocks.stonebrick);
		world.setBlock(i + 0, j + 11, k + 5, Blocks.stonebrick);
		world.setBlock(i + 0, j + 11, k + 6, Blocks.stonebrick);
		world.setBlock(i + 0, j + 11, k + 7, Blocks.stonebrick);
		world.setBlock(i + 0, j + 11, k + 8, Blocks.stonebrick);
		world.setBlock(i + 0, j + 11, k + 9, Blocks.stonebrick);
		world.setBlock(i + 0, j + 11, k + 10, Blocks.stonebrick);
		world.setBlock(i + 0, j + 11, k + 11, Blocks.stonebrick);
		world.setBlock(i + 0, j + 11, k + 12, Blocks.stonebrick);
		world.setBlock(i + 0, j + 11, k + 13, Blocks.stonebrick);
		world.setBlock(i + 0, j + 11, k + 14, Blocks.stonebrick);
		world.setBlock(i + 0, j + 11, k + 15, Blocks.stonebrick);
		world.setBlock(i + 0, j + 12, k + 0, Blocks.stonebrick);
		world.setBlock(i + 0, j + 12, k + 1, Blocks.stonebrick);
		world.setBlock(i + 0, j + 12, k + 2, Blocks.stonebrick);
		world.setBlock(i + 0, j + 12, k + 3, Blocks.stonebrick);
		world.setBlock(i + 0, j + 12, k + 4, Blocks.stonebrick);
		world.setBlock(i + 0, j + 12, k + 5, Blocks.stonebrick);
		world.setBlock(i + 0, j + 12, k + 6, Blocks.stonebrick);
		world.setBlock(i + 0, j + 12, k + 7, Blocks.stonebrick);
		world.setBlock(i + 0, j + 12, k + 8, Blocks.stonebrick);
		world.setBlock(i + 0, j + 12, k + 9, Blocks.stonebrick);
		world.setBlock(i + 0, j + 12, k + 10, Blocks.stonebrick);
		world.setBlock(i + 0, j + 12, k + 11, Blocks.stonebrick);
		world.setBlock(i + 0, j + 12, k + 12, Blocks.stonebrick);
		world.setBlock(i + 0, j + 12, k + 13, Blocks.stonebrick);
		world.setBlock(i + 0, j + 12, k + 14, Blocks.stonebrick);
		world.setBlock(i + 0, j + 12, k + 15, Blocks.stonebrick);
		world.setBlock(i + 0, j + 13, k + 0, Blocks.stonebrick);
		world.setBlock(i + 0, j + 13, k + 1, Blocks.stonebrick);
		world.setBlock(i + 0, j + 13, k + 2, Blocks.stonebrick);
		world.setBlock(i + 0, j + 13, k + 3, Blocks.stonebrick);
		world.setBlock(i + 0, j + 13, k + 4, Blocks.stonebrick);
		world.setBlock(i + 0, j + 13, k + 5, Blocks.stonebrick);
		world.setBlock(i + 0, j + 13, k + 6, Blocks.stonebrick);
		world.setBlock(i + 0, j + 13, k + 7, Blocks.stonebrick);
		world.setBlock(i + 0, j + 13, k + 8, Blocks.stonebrick);
		world.setBlock(i + 0, j + 13, k + 9, Blocks.stonebrick);
		world.setBlock(i + 0, j + 13, k + 10, Blocks.stonebrick);
		world.setBlock(i + 0, j + 13, k + 11, Blocks.stonebrick);
		world.setBlock(i + 0, j + 13, k + 12, Blocks.stonebrick);
		world.setBlock(i + 0, j + 13, k + 13, Blocks.stonebrick);
		world.setBlock(i + 0, j + 13, k + 14, Blocks.stonebrick);
		world.setBlock(i + 0, j + 13, k + 15, Blocks.stonebrick);
		world.setBlock(i + 0, j + 14, k + 0, Blocks.stonebrick);
		world.setBlock(i + 0, j + 14, k + 1, Blocks.stonebrick);
		world.setBlock(i + 0, j + 14, k + 2, Blocks.stonebrick);
		world.setBlock(i + 0, j + 14, k + 3, Blocks.stonebrick);
		world.setBlock(i + 0, j + 14, k + 4, Blocks.stonebrick);
		world.setBlock(i + 0, j + 14, k + 5, Blocks.stonebrick);
		world.setBlock(i + 0, j + 14, k + 6, Blocks.stonebrick);
		world.setBlock(i + 0, j + 14, k + 7, Blocks.stonebrick);
		world.setBlock(i + 0, j + 14, k + 8, Blocks.stonebrick);
		world.setBlock(i + 0, j + 14, k + 9, Blocks.stonebrick);
		world.setBlock(i + 0, j + 14, k + 10, Blocks.stonebrick);
		world.setBlock(i + 0, j + 14, k + 11, Blocks.stonebrick);
		world.setBlock(i + 0, j + 14, k + 12, Blocks.stonebrick);
		world.setBlock(i + 0, j + 14, k + 13, Blocks.stonebrick);
		world.setBlock(i + 0, j + 14, k + 14, Blocks.stonebrick);
		world.setBlock(i + 0, j + 14, k + 15, Blocks.stonebrick);
		world.setBlock(i + 0, j + 15, k + 0, Blocks.stonebrick);
		world.setBlock(i + 0, j + 15, k + 1, Blocks.stonebrick);
		world.setBlock(i + 0, j + 15, k + 2, Blocks.stonebrick);
		world.setBlock(i + 0, j + 15, k + 3, Blocks.stonebrick);
		world.setBlock(i + 0, j + 15, k + 4, Blocks.stonebrick);
		world.setBlock(i + 0, j + 15, k + 5, Blocks.stonebrick);
		world.setBlock(i + 0, j + 15, k + 6, Blocks.stonebrick);
		world.setBlock(i + 0, j + 15, k + 7, Blocks.stonebrick);
		world.setBlock(i + 0, j + 15, k + 8, Blocks.stonebrick);
		world.setBlock(i + 0, j + 15, k + 9, Blocks.stonebrick);
		world.setBlock(i + 0, j + 15, k + 10, Blocks.stonebrick);
		world.setBlock(i + 0, j + 15, k + 11, Blocks.stonebrick);
		world.setBlock(i + 0, j + 15, k + 12, Blocks.stonebrick);
		world.setBlock(i + 0, j + 15, k + 13, Blocks.stonebrick);
		world.setBlock(i + 0, j + 15, k + 14, Blocks.stonebrick);
		world.setBlock(i + 0, j + 15, k + 15, Blocks.stonebrick);
		world.setBlock(i + 0, j + 16, k + 0, Blocks.stonebrick);
		world.setBlock(i + 0, j + 16, k + 1, Blocks.stonebrick);
		world.setBlock(i + 0, j + 16, k + 2, Blocks.stonebrick);
		world.setBlock(i + 0, j + 16, k + 3, Blocks.stonebrick);
		world.setBlock(i + 0, j + 16, k + 4, Blocks.stonebrick);
		world.setBlock(i + 0, j + 16, k + 5, Blocks.stonebrick);
		world.setBlock(i + 0, j + 16, k + 6, Blocks.stonebrick);
		world.setBlock(i + 0, j + 16, k + 7, Blocks.stonebrick);
		world.setBlock(i + 0, j + 16, k + 8, Blocks.stonebrick);
		world.setBlock(i + 0, j + 16, k + 9, Blocks.stonebrick);
		world.setBlock(i + 0, j + 16, k + 10, Blocks.stonebrick);
		world.setBlock(i + 0, j + 16, k + 11, Blocks.stonebrick);
		world.setBlock(i + 0, j + 16, k + 12, Blocks.stonebrick);
		world.setBlock(i + 0, j + 16, k + 13, Blocks.stonebrick);
		world.setBlock(i + 0, j + 16, k + 14, Blocks.stonebrick);
		world.setBlock(i + 0, j + 16, k + 15, Blocks.stonebrick);
		world.setBlock(i + 0, j + 17, k + 0, Blocks.stonebrick);
		world.setBlock(i + 0, j + 17, k + 1, Blocks.stonebrick);
		world.setBlock(i + 0, j + 17, k + 2, Blocks.stonebrick);
		world.setBlock(i + 0, j + 17, k + 3, Blocks.stonebrick);
		world.setBlock(i + 0, j + 17, k + 4, Blocks.stonebrick);
		world.setBlock(i + 0, j + 17, k + 5, Blocks.stonebrick);
		world.setBlock(i + 0, j + 17, k + 6, Blocks.stonebrick);
		world.setBlock(i + 0, j + 17, k + 7, Blocks.stonebrick);
		world.setBlock(i + 0, j + 17, k + 8, Blocks.stonebrick);
		world.setBlock(i + 0, j + 17, k + 9, Blocks.stonebrick);
		world.setBlock(i + 0, j + 17, k + 10, Blocks.stonebrick);
		world.setBlock(i + 0, j + 17, k + 11, Blocks.stonebrick);
		world.setBlock(i + 0, j + 17, k + 12, Blocks.stonebrick);
		world.setBlock(i + 0, j + 17, k + 13, Blocks.stonebrick);
		world.setBlock(i + 0, j + 17, k + 14, Blocks.stonebrick);
		world.setBlock(i + 0, j + 17, k + 15, Blocks.stonebrick);
		world.setBlock(i + 0, j + 18, k + 0, Blocks.stonebrick);
		world.setBlock(i + 0, j + 18, k + 1, Blocks.stonebrick);
		world.setBlock(i + 0, j + 18, k + 2, Blocks.air);
		world.setBlock(i + 0, j + 18, k + 3, Blocks.air);
		world.setBlock(i + 0, j + 18, k + 4, Blocks.air);
		world.setBlock(i + 0, j + 18, k + 5, Blocks.air);
		world.setBlock(i + 0, j + 18, k + 6, Blocks.air);
		world.setBlock(i + 0, j + 18, k + 7, Blocks.air);
		world.setBlock(i + 0, j + 18, k + 8, Blocks.air);
		world.setBlock(i + 0, j + 18, k + 9, Blocks.air);
		world.setBlock(i + 0, j + 18, k + 10, Blocks.air);
		world.setBlock(i + 0, j + 18, k + 11, Blocks.air);
		world.setBlock(i + 0, j + 18, k + 12, Blocks.air);
		world.setBlock(i + 0, j + 18, k + 13, Blocks.air);
		world.setBlock(i + 0, j + 18, k + 14, Blocks.stonebrick);
		world.setBlock(i + 0, j + 18, k + 15, Blocks.stonebrick);
		world.setBlock(i + 0, j + 19, k + 0, Blocks.stonebrick);
		world.setBlock(i + 0, j + 19, k + 1, Blocks.air);
		world.setBlock(i + 0, j + 19, k + 2, Blocks.air);
		world.setBlock(i + 0, j + 19, k + 3, Blocks.air);
		world.setBlock(i + 0, j + 19, k + 4, Blocks.air);
		world.setBlock(i + 0, j + 19, k + 5, Blocks.air);
		world.setBlock(i + 0, j + 19, k + 6, Blocks.air);
		world.setBlock(i + 0, j + 19, k + 7, Blocks.air);
		world.setBlock(i + 0, j + 19, k + 8, Blocks.air);
		world.setBlock(i + 0, j + 19, k + 9, Blocks.air);
		world.setBlock(i + 0, j + 19, k + 10, Blocks.air);
		world.setBlock(i + 0, j + 19, k + 11, Blocks.air);
		world.setBlock(i + 0, j + 19, k + 12, Blocks.air);
		world.setBlock(i + 0, j + 19, k + 13, Blocks.air);
		world.setBlock(i + 0, j + 19, k + 14, Blocks.air);
		world.setBlock(i + 0, j + 19, k + 15, Blocks.stonebrick);
		world.setBlock(i + 0, j + 20, k + 0, Blocks.stonebrick);// SPOT
		world.setBlock(i + 0, j + 20, k + 1, Blocks.air);
		world.setBlock(i + 0, j + 20, k + 2, Blocks.air);
		world.setBlock(i + 0, j + 20, k + 3, Blocks.air);
		world.setBlock(i + 0, j + 20, k + 4, Blocks.air);
		world.setBlock(i + 0, j + 20, k + 5, Blocks.air);
		world.setBlock(i + 0, j + 20, k + 6, Blocks.air);
		world.setBlock(i + 0, j + 20, k + 7, Blocks.air);
		world.setBlock(i + 0, j + 20, k + 8, Blocks.air);
		world.setBlock(i + 0, j + 20, k + 9, Blocks.air);
		world.setBlock(i + 0, j + 20, k + 10, Blocks.air);
		world.setBlock(i + 0, j + 20, k + 11, Blocks.air);
		world.setBlock(i + 0, j + 20, k + 12, Blocks.air);
		world.setBlock(i + 0, j + 20, k + 13, Blocks.air);
		world.setBlock(i + 0, j + 20, k + 14, Blocks.air);
		world.setBlock(i + 0, j + 20, k + 15, Blocks.air);
		world.setBlock(i + 1, j + 0, k + 0, Blocks.stonebrick);
		world.setBlock(i + 1, j + 0, k + 1, Blocks.stonebrick);
		world.setBlock(i + 1, j + 0, k + 2, Blocks.stonebrick);
		world.setBlock(i + 1, j + 0, k + 3, Blocks.stonebrick);
		world.setBlock(i + 1, j + 0, k + 4, Blocks.stonebrick);
		world.setBlock(i + 1, j + 0, k + 5, Blocks.stonebrick);
		world.setBlock(i + 1, j + 0, k + 6, Blocks.stonebrick);
		world.setBlock(i + 1, j + 0, k + 7, Blocks.stonebrick);
		world.setBlock(i + 1, j + 0, k + 8, Blocks.stonebrick);
		world.setBlock(i + 1, j + 0, k + 9, Blocks.stonebrick);
		world.setBlock(i + 1, j + 0, k + 10, Blocks.stonebrick);
		world.setBlock(i + 1, j + 0, k + 11, Blocks.stonebrick);
		world.setBlock(i + 1, j + 0, k + 12, Blocks.stonebrick);
		world.setBlock(i + 1, j + 0, k + 13, Blocks.stonebrick);
		world.setBlock(i + 1, j + 0, k + 14, Blocks.stonebrick);
		world.setBlock(i + 1, j + 0, k + 15, Blocks.stonebrick);
		world.setBlock(i + 1, j + 1, k + 0, Blocks.stonebrick);
		world.setBlock(i + 1, j + 1, k + 1, Blocks.air);
		world.setBlock(i + 1, j + 1, k + 2, Blocks.air);
		world.setBlock(i + 1, j + 1, k + 3, Blocks.air);
		world.setBlock(i + 1, j + 1, k + 4, Blocks.air);
		world.setBlock(i + 1, j + 1, k + 5, Blocks.air);
		world.setBlock(i + 1, j + 1, k + 6, Blocks.air);
		world.setBlock(i + 1, j + 1, k + 7, Blocks.air);
		world.setBlock(i + 1, j + 1, k + 8, Blocks.air);
		world.setBlock(i + 1, j + 1, k + 9, Blocks.air);
		world.setBlock(i + 1, j + 1, k + 10, Blocks.air);
		world.setBlock(i + 1, j + 1, k + 11, Blocks.air);
		world.setBlock(i + 1, j + 1, k + 12, Blocks.stone_brick_stairs);
		world.setBlock(i + 1, j + 1, k + 13, Blocks.air);
		world.setBlock(i + 1, j + 1, k + 14, Blocks.air);
		world.setBlock(i + 1, j + 1, k + 15, Blocks.stonebrick);
		world.setBlock(i + 1, j + 2, k + 0, Blocks.stonebrick);
		world.setBlock(i + 1, j + 2, k + 1, Blocks.air);
		world.setBlock(i + 1, j + 2, k + 2, Blocks.air);
		world.setBlock(i + 1, j + 2, k + 3, Blocks.air);
		world.setBlock(i + 1, j + 2, k + 4, Blocks.air);
		world.setBlock(i + 1, j + 2, k + 5, Blocks.air);
		world.setBlock(i + 1, j + 2, k + 6, Blocks.air);
		world.setBlock(i + 1, j + 2, k + 7, Blocks.air);
		world.setBlock(i + 1, j + 2, k + 8, Blocks.air);
		world.setBlock(i + 1, j + 2, k + 9, Blocks.air);
		world.setBlock(i + 1, j + 2, k + 10, Blocks.air);
		world.setBlock(i + 1, j + 2, k + 11, Blocks.stone_brick_stairs);
		world.setBlock(i + 1, j + 2, k + 12, Blocks.air);
		world.setBlock(i + 1, j + 2, k + 13, Blocks.air);
		world.setBlock(i + 1, j + 2, k + 14, Blocks.air);
		world.setBlock(i + 1, j + 2, k + 15, Blocks.stonebrick);
		world.setBlock(i + 1, j + 3, k + 0, Blocks.stonebrick);
		world.setBlock(i + 1, j + 3, k + 1, Blocks.air);
		world.setBlock(i + 1, j + 3, k + 2, Blocks.air);
		world.setBlock(i + 1, j + 3, k + 3, Blocks.air);
		world.setBlock(i + 1, j + 3, k + 4, Blocks.air);
		world.setBlock(i + 1, j + 3, k + 5, Blocks.air);
		world.setBlock(i + 1, j + 3, k + 6, Blocks.air);
		world.setBlock(i + 1, j + 3, k + 7, Blocks.air);
		world.setBlock(i + 1, j + 3, k + 8, Blocks.air);
		world.setBlock(i + 1, j + 3, k + 9, Blocks.air);
		world.setBlock(i + 1, j + 3, k + 10, Blocks.stone_brick_stairs);
		world.setBlock(i + 1, j + 3, k + 11, Blocks.air);
		world.setBlock(i + 1, j + 3, k + 12, Blocks.air);
		world.setBlock(i + 1, j + 3, k + 13, Blocks.air);
		world.setBlock(i + 1, j + 3, k + 14, Blocks.air);
		world.setBlock(i + 1, j + 3, k + 15, Blocks.stonebrick);
		world.setBlock(i + 1, j + 4, k + 0, Blocks.stonebrick);
		world.setBlock(i + 1, j + 4, k + 1, Blocks.stonebrick);
		world.setBlock(i + 1, j + 4, k + 2, Blocks.stonebrick);
		world.setBlock(i + 1, j + 4, k + 3, Blocks.stonebrick);
		world.setBlock(i + 1, j + 4, k + 4, Blocks.stonebrick);
		world.setBlock(i + 1, j + 4, k + 5, Blocks.stonebrick);
		world.setBlock(i + 1, j + 4, k + 6, Blocks.stonebrick);
		world.setBlock(i + 1, j + 4, k + 7, Blocks.stonebrick);
		world.setBlock(i + 1, j + 4, k + 8, Blocks.stonebrick);
		world.setBlock(i + 1, j + 4, k + 9, Blocks.stone_brick_stairs);
		world.setBlock(i + 1, j + 4, k + 10, Blocks.air);
		world.setBlock(i + 1, j + 4, k + 11, Blocks.air);
		world.setBlock(i + 1, j + 4, k + 12, Blocks.air);
		world.setBlock(i + 1, j + 4, k + 13, Blocks.stonebrick);
		world.setBlock(i + 1, j + 4, k + 14, Blocks.stonebrick);
		world.setBlock(i + 1, j + 4, k + 15, Blocks.stonebrick);
		world.setBlock(i + 1, j + 5, k + 0, Blocks.stonebrick);
		world.setBlock(i + 1, j + 5, k + 1, Blocks.air);
		world.setBlock(i + 1, j + 5, k + 2, Blocks.air);
		world.setBlock(i + 1, j + 5, k + 3, Blocks.air);
		world.setBlock(i + 1, j + 5, k + 4, Blocks.air);
		world.setBlock(i + 1, j + 5, k + 5, Blocks.air);
		world.setBlock(i + 1, j + 5, k + 6, Blocks.air);
		world.setBlock(i + 1, j + 5, k + 7, Blocks.air);
		world.setBlock(i + 1, j + 5, k + 8, Blocks.air);
		world.setBlock(i + 1, j + 5, k + 9, Blocks.air);
		world.setBlock(i + 1, j + 5, k + 10, Blocks.air);
		world.setBlock(i + 1, j + 5, k + 11, Blocks.air);
		world.setBlock(i + 1, j + 5, k + 12, Blocks.air);
		world.setBlock(i + 1, j + 5, k + 13, Blocks.air);
		world.setBlock(i + 1, j + 5, k + 14, Blocks.air);
		world.setBlock(i + 1, j + 5, k + 15, Blocks.stonebrick);
		world.setBlock(i + 1, j + 6, k + 0, Blocks.stonebrick);
		world.setBlock(i + 1, j + 6, k + 1, Blocks.air);
		world.setBlock(i + 1, j + 6, k + 2, Blocks.air);
		world.setBlock(i + 1, j + 6, k + 3, Blocks.air);
		world.setBlock(i + 1, j + 6, k + 4, Blocks.air);
		world.setBlock(i + 1, j + 6, k + 5, Blocks.air);
		world.setBlock(i + 1, j + 6, k + 6, Blocks.air);
		world.setBlock(i + 1, j + 6, k + 7, Blocks.air);
		world.setBlock(i + 1, j + 6, k + 8, Blocks.air);
		world.setBlock(i + 1, j + 6, k + 9, Blocks.air);
		world.setBlock(i + 1, j + 6, k + 10, Blocks.air);
		world.setBlock(i + 1, j + 6, k + 11, Blocks.air);
		world.setBlock(i + 1, j + 6, k + 12, Blocks.air);
		world.setBlock(i + 1, j + 6, k + 13, Blocks.air);
		world.setBlock(i + 1, j + 6, k + 14, Blocks.air);
		world.setBlock(i + 1, j + 6, k + 15, Blocks.stonebrick);
		world.setBlock(i + 1, j + 7, k + 0, Blocks.stonebrick);
		world.setBlock(i + 1, j + 7, k + 1, Blocks.air);
		world.setBlock(i + 1, j + 7, k + 2, Blocks.air);
		world.setBlock(i + 1, j + 7, k + 3, Blocks.air);
		world.setBlock(i + 1, j + 7, k + 4, Blocks.air);
		world.setBlock(i + 1, j + 7, k + 5, Blocks.air);
		world.setBlock(i + 1, j + 7, k + 6, Blocks.air);
		world.setBlock(i + 1, j + 7, k + 7, Blocks.air);
		world.setBlock(i + 1, j + 7, k + 8, Blocks.air);
		world.setBlock(i + 1, j + 7, k + 9, Blocks.air);
		world.setBlock(i + 1, j + 7, k + 10, Blocks.air);
		world.setBlock(i + 1, j + 7, k + 11, Blocks.air);
		world.setBlock(i + 1, j + 7, k + 12, Blocks.air);
		world.setBlock(i + 1, j + 7, k + 13, Blocks.air);
		world.setBlock(i + 1, j + 7, k + 14, Blocks.air);
		world.setBlock(i + 1, j + 7, k + 15, Blocks.stonebrick);
		world.setBlock(i + 1, j + 8, k + 0, Blocks.stonebrick);
		world.setBlock(i + 1, j + 8, k + 1, Blocks.stonebrick);
		world.setBlock(i + 1, j + 8, k + 2, Blocks.stonebrick);
		world.setBlock(i + 1, j + 8, k + 3, Blocks.stonebrick);
		world.setBlock(i + 1, j + 8, k + 4, Blocks.stonebrick);
		world.setBlock(i + 1, j + 8, k + 5, Blocks.stonebrick);
		world.setBlock(i + 1, j + 8, k + 6, Blocks.stonebrick);
		world.setBlock(i + 1, j + 8, k + 7, Blocks.stonebrick);
		world.setBlock(i + 1, j + 8, k + 8, Blocks.stonebrick);
		world.setBlock(i + 1, j + 8, k + 9, Blocks.stonebrick);
		world.setBlock(i + 1, j + 8, k + 10, Blocks.stonebrick);
		world.setBlock(i + 1, j + 8, k + 11, Blocks.stonebrick);
		world.setBlock(i + 1, j + 8, k + 12, Blocks.stonebrick);
		world.setBlock(i + 1, j + 8, k + 13, Blocks.stonebrick);
		world.setBlock(i + 1, j + 8, k + 14, Blocks.stonebrick);
		world.setBlock(i + 1, j + 8, k + 15, Blocks.stonebrick);
		world.setBlock(i + 1, j + 9, k + 0, Blocks.stonebrick);
		world.setBlock(i + 1, j + 9, k + 1, Blocks.air);
		world.setBlock(i + 1, j + 9, k + 2, Blocks.air);
		world.setBlock(i + 1, j + 9, k + 3, Blocks.air);
		world.setBlock(i + 1, j + 9, k + 4, Blocks.air);
		world.setBlock(i + 1, j + 9, k + 5, Blocks.air);
		world.setBlock(i + 1, j + 9, k + 6, Blocks.air);
		world.setBlock(i + 1, j + 9, k + 7, Blocks.stone_brick_stairs);
		world.setBlock(i + 1, j + 9, k + 8, Blocks.air);
		world.setBlock(i + 1, j + 9, k + 9, Blocks.air);
		world.setBlock(i + 1, j + 9, k + 10, Blocks.air);
		world.setBlock(i + 1, j + 9, k + 11, Blocks.air);
		world.setBlock(i + 1, j + 9, k + 12, Blocks.air);
		world.setBlock(i + 1, j + 9, k + 13, Blocks.air);
		world.setBlock(i + 1, j + 9, k + 14, Blocks.air);
		world.setBlock(i + 1, j + 9, k + 15, Blocks.stonebrick);
		world.setBlock(i + 1, j + 10, k + 0, Blocks.stonebrick);
		world.setBlock(i + 1, j + 10, k + 1, Blocks.air);
		world.setBlock(i + 1, j + 10, k + 2, Blocks.air);
		world.setBlock(i + 1, j + 10, k + 3, Blocks.air);
		world.setBlock(i + 1, j + 10, k + 4, Blocks.air);
		world.setBlock(i + 1, j + 10, k + 5, Blocks.air);
		world.setBlock(i + 1, j + 10, k + 6, Blocks.stone_brick_stairs);
		world.setBlock(i + 1, j + 10, k + 7, Blocks.air);
		world.setBlock(i + 1, j + 10, k + 8, Blocks.air);
		world.setBlock(i + 1, j + 10, k + 9, Blocks.air);
		world.setBlock(i + 1, j + 10, k + 10, Blocks.air);
		world.setBlock(i + 1, j + 10, k + 11, Blocks.air);
		world.setBlock(i + 1, j + 10, k + 12, Blocks.air);
		world.setBlock(i + 1, j + 10, k + 13, Blocks.air);
		world.setBlock(i + 1, j + 10, k + 14, Blocks.air);
		world.setBlock(i + 1, j + 10, k + 15, Blocks.stonebrick);
		world.setBlock(i + 1, j + 11, k + 0, Blocks.stonebrick);
		world.setBlock(i + 1, j + 11, k + 1, Blocks.air);
		world.setBlock(i + 1, j + 11, k + 2, Blocks.air);
		world.setBlock(i + 1, j + 11, k + 3, Blocks.air);
		world.setBlock(i + 1, j + 11, k + 4, Blocks.air);
		world.setBlock(i + 1, j + 11, k + 5, Blocks.stone_brick_stairs);
		world.setBlock(i + 1, j + 11, k + 6, Blocks.air);
		world.setBlock(i + 1, j + 11, k + 7, Blocks.air);
		world.setBlock(i + 1, j + 11, k + 8, Blocks.air);
		world.setBlock(i + 1, j + 11, k + 9, Blocks.air);
		world.setBlock(i + 1, j + 11, k + 10, Blocks.air);
		world.setBlock(i + 1, j + 11, k + 11, Blocks.air);
		world.setBlock(i + 1, j + 11, k + 12, Blocks.air);
		world.setBlock(i + 1, j + 11, k + 13, Blocks.air);
		world.setBlock(i + 1, j + 11, k + 14, Blocks.air);
		world.setBlock(i + 1, j + 11, k + 15, Blocks.stonebrick);
		world.setBlock(i + 1, j + 12, k + 0, Blocks.stonebrick);
		world.setBlock(i + 1, j + 12, k + 1, Blocks.bedrock);
		world.setBlock(i + 1, j + 12, k + 2, Blocks.bedrock);
		world.setBlock(i + 1, j + 12, k + 3, Blocks.bedrock);
		world.setBlock(i + 1, j + 12, k + 4, Blocks.stone_brick_stairs);
		world.setBlock(i + 1, j + 12, k + 5, Blocks.bedrock);
		world.setBlock(i + 1, j + 12, k + 6, Blocks.bedrock);
		world.setBlock(i + 1, j + 12, k + 7, Blocks.bedrock);
		world.setBlock(i + 1, j + 12, k + 8, Blocks.bedrock);
		world.setBlock(i + 1, j + 12, k + 9, Blocks.bedrock);
		world.setBlock(i + 1, j + 12, k + 10, Blocks.bedrock);
		world.setBlock(i + 1, j + 12, k + 11, Blocks.bedrock);
		world.setBlock(i + 1, j + 12, k + 12, Blocks.bedrock);
		world.setBlock(i + 1, j + 12, k + 13, Blocks.bedrock);
		world.setBlock(i + 1, j + 12, k + 14, Blocks.bedrock);
		world.setBlock(i + 1, j + 12, k + 15, Blocks.stonebrick);
		world.setBlock(i + 1, j + 13, k + 0, Blocks.stonebrick);
		world.setBlock(i + 1, j + 13, k + 1, Blocks.air);
		world.setBlock(i + 1, j + 13, k + 2, Blocks.air);
		world.setBlock(i + 1, j + 13, k + 3, Blocks.air);
		world.setBlock(i + 1, j + 13, k + 4, Blocks.air);
		world.setBlock(i + 1, j + 13, k + 5, Blocks.air);
		world.setBlock(i + 1, j + 13, k + 6, Blocks.air);
		world.setBlock(i + 1, j + 13, k + 7, Blocks.air);
		world.setBlock(i + 1, j + 13, k + 8, Blocks.air);
		world.setBlock(i + 1, j + 13, k + 9, Blocks.air);
		world.setBlock(i + 1, j + 13, k + 10, Blocks.air);
		world.setBlock(i + 1, j + 13, k + 11, Blocks.air);
		world.setBlock(i + 1, j + 13, k + 12, Blocks.air);
		world.setBlock(i + 1, j + 13, k + 13, Blocks.air);
		world.setBlock(i + 1, j + 13, k + 14, Blocks.air);
		world.setBlock(i + 1, j + 13, k + 15, Blocks.stonebrick);
		world.setBlock(i + 1, j + 14, k + 0, Blocks.stonebrick);
		world.setBlock(i + 1, j + 14, k + 1, Blocks.air);
		world.setBlock(i + 1, j + 14, k + 2, Blocks.air);
		world.setBlock(i + 1, j + 14, k + 3, Blocks.air);
		world.setBlock(i + 1, j + 14, k + 4, Blocks.air);
		world.setBlock(i + 1, j + 14, k + 5, Blocks.air);
		world.setBlock(i + 1, j + 14, k + 6, Blocks.air);
		world.setBlock(i + 1, j + 14, k + 7, Blocks.air);
		world.setBlock(i + 1, j + 14, k + 8, Blocks.air);
		world.setBlock(i + 1, j + 14, k + 9, Blocks.air);
		world.setBlock(i + 1, j + 14, k + 10, Blocks.air);
		world.setBlock(i + 1, j + 14, k + 11, Blocks.air);
		world.setBlock(i + 1, j + 14, k + 12, Blocks.air);
		world.setBlock(i + 1, j + 14, k + 13, Blocks.air);
		world.setBlock(i + 1, j + 14, k + 14, Blocks.air);
		world.setBlock(i + 1, j + 14, k + 15, Blocks.stonebrick);
		world.setBlock(i + 1, j + 15, k + 0, Blocks.stonebrick);
		world.setBlock(i + 1, j + 15, k + 1, Blocks.air);
		world.setBlock(i + 1, j + 15, k + 2, Blocks.air);
		world.setBlock(i + 1, j + 15, k + 3, Blocks.air);
		world.setBlock(i + 1, j + 15, k + 4, Blocks.air);
		world.setBlock(i + 1, j + 15, k + 5, Blocks.air);
		world.setBlock(i + 1, j + 15, k + 6, Blocks.air);
		world.setBlock(i + 1, j + 15, k + 7, Blocks.air);
		world.setBlock(i + 1, j + 15, k + 8, Blocks.air);
		world.setBlock(i + 1, j + 15, k + 9, Blocks.air);
		world.setBlock(i + 1, j + 15, k + 10, Blocks.air);
		world.setBlock(i + 1, j + 15, k + 11, Blocks.air);
		world.setBlock(i + 1, j + 15, k + 12, Blocks.air);
		world.setBlock(i + 1, j + 15, k + 13, Blocks.air);
		world.setBlock(i + 1, j + 15, k + 14, Blocks.air);
		world.setBlock(i + 1, j + 15, k + 15, Blocks.stonebrick);
		world.setBlock(i + 1, j + 16, k + 0, Blocks.stonebrick);
		world.setBlock(i + 1, j + 16, k + 1, Blocks.stonebrick);
		world.setBlock(i + 1, j + 16, k + 2, Blocks.stonebrick);
		world.setBlock(i + 1, j + 16, k + 3, Blocks.stonebrick);
		world.setBlock(i + 1, j + 16, k + 4, Blocks.stonebrick);
		world.setBlock(i + 1, j + 16, k + 5, Blocks.stonebrick);
		world.setBlock(i + 1, j + 16, k + 6, Blocks.stonebrick);
		world.setBlock(i + 1, j + 16, k + 7, Blocks.stonebrick);
		world.setBlock(i + 1, j + 16, k + 8, Blocks.stonebrick);
		world.setBlock(i + 1, j + 16, k + 9, Blocks.stonebrick);
		world.setBlock(i + 1, j + 16, k + 10, Blocks.stonebrick);
		world.setBlock(i + 1, j + 16, k + 11, Blocks.stonebrick);
		world.setBlock(i + 1, j + 16, k + 12, Blocks.stonebrick);
		world.setBlock(i + 1, j + 16, k + 13, Blocks.stonebrick);
		world.setBlock(i + 1, j + 16, k + 14, Blocks.stonebrick);
		world.setBlock(i + 1, j + 16, k + 15, Blocks.stonebrick);
		world.setBlock(i + 1, j + 17, k + 0, Blocks.stonebrick);
		world.setBlock(i + 1, j + 17, k + 1, Blocks.stonebrick);
		world.setBlock(i + 1, j + 17, k + 2, Blocks.stonebrick);
		world.setBlock(i + 1, j + 17, k + 3, Blocks.stonebrick);
		world.setBlock(i + 1, j + 17, k + 4, Blocks.stonebrick);
		world.setBlock(i + 1, j + 17, k + 5, Blocks.stonebrick);
		world.setBlock(i + 1, j + 17, k + 6, Blocks.stonebrick);
		world.setBlock(i + 1, j + 17, k + 7, Blocks.stonebrick);
		world.setBlock(i + 1, j + 17, k + 8, Blocks.stonebrick);
		world.setBlock(i + 1, j + 17, k + 9, Blocks.stonebrick);
		world.setBlock(i + 1, j + 17, k + 10, Blocks.stonebrick);
		world.setBlock(i + 1, j + 17, k + 11, Blocks.stonebrick);
		world.setBlock(i + 1, j + 17, k + 12, Blocks.stonebrick);
		world.setBlock(i + 1, j + 17, k + 13, Blocks.stonebrick);
		world.setBlock(i + 1, j + 17, k + 14, Blocks.stonebrick);
		world.setBlock(i + 1, j + 17, k + 15, Blocks.stonebrick);
		world.setBlock(i + 1, j + 18, k + 0, Blocks.stonebrick);
		world.setBlock(i + 1, j + 18, k + 1, Blocks.air);
		world.setBlock(i + 1, j + 18, k + 2, Blocks.air);
		world.setBlock(i + 1, j + 18, k + 3, Blocks.air);
		world.setBlock(i + 1, j + 18, k + 4, Blocks.air);
		world.setBlock(i + 1, j + 18, k + 5, Blocks.air);
		world.setBlock(i + 1, j + 18, k + 6, Blocks.air);
		world.setBlock(i + 1, j + 18, k + 7, Blocks.air);
		world.setBlock(i + 1, j + 18, k + 8, Blocks.air);
		world.setBlock(i + 1, j + 18, k + 9, Blocks.air);
		world.setBlock(i + 1, j + 18, k + 10, Blocks.air);
		world.setBlock(i + 1, j + 18, k + 11, Blocks.air);
		world.setBlock(i + 1, j + 18, k + 12, Blocks.air);
		world.setBlock(i + 1, j + 18, k + 13, Blocks.air);
		world.setBlock(i + 1, j + 18, k + 14, Blocks.air);
		world.setBlock(i + 1, j + 18, k + 15, Blocks.stonebrick);
		world.setBlock(i + 1, j + 19, k + 0, Blocks.air);
		world.setBlock(i + 1, j + 19, k + 1, Blocks.air);
		world.setBlock(i + 1, j + 19, k + 2, Blocks.air);
		world.setBlock(i + 1, j + 19, k + 3, Blocks.air);
		world.setBlock(i + 1, j + 19, k + 4, Blocks.air);
		world.setBlock(i + 1, j + 19, k + 5, Blocks.air);
		world.setBlock(i + 1, j + 19, k + 6, Blocks.air);
		world.setBlock(i + 1, j + 19, k + 7, Blocks.air);
		world.setBlock(i + 1, j + 19, k + 8, Blocks.air);
		world.setBlock(i + 1, j + 19, k + 9, Blocks.air);
		world.setBlock(i + 1, j + 19, k + 10, Blocks.air);
		world.setBlock(i + 1, j + 19, k + 11, Blocks.air);
		world.setBlock(i + 1, j + 19, k + 12, Blocks.air);
		world.setBlock(i + 1, j + 19, k + 13, Blocks.air);
		world.setBlock(i + 1, j + 19, k + 14, Blocks.air);
		world.setBlock(i + 1, j + 19, k + 15, Blocks.air);
		world.setBlock(i + 1, j + 20, k + 0, Blocks.air);
		world.setBlock(i + 1, j + 20, k + 1, Blocks.air);
		world.setBlock(i + 1, j + 20, k + 2, Blocks.air);
		world.setBlock(i + 1, j + 20, k + 3, Blocks.air);
		world.setBlock(i + 1, j + 20, k + 4, Blocks.air);
		world.setBlock(i + 1, j + 20, k + 5, Blocks.air);
		world.setBlock(i + 1, j + 20, k + 6, Blocks.air);
		world.setBlock(i + 1, j + 20, k + 7, Blocks.air);
		world.setBlock(i + 1, j + 20, k + 8, Blocks.air);
		world.setBlock(i + 1, j + 20, k + 9, Blocks.air);
		world.setBlock(i + 1, j + 20, k + 10, Blocks.air);
		world.setBlock(i + 1, j + 20, k + 11, Blocks.air);
		world.setBlock(i + 1, j + 20, k + 12, Blocks.air);
		world.setBlock(i + 1, j + 20, k + 13, Blocks.air);
		world.setBlock(i + 1, j + 20, k + 14, Blocks.air);
		world.setBlock(i + 1, j + 20, k + 15, Blocks.air);
		world.setBlock(i + 2, j + 0, k + 0, Blocks.stonebrick);
		world.setBlock(i + 2, j + 0, k + 1, Blocks.stonebrick);
		world.setBlock(i + 2, j + 0, k + 2, Blocks.stonebrick);
		world.setBlock(i + 2, j + 0, k + 3, Blocks.stonebrick);
		world.setBlock(i + 2, j + 0, k + 4, Blocks.stonebrick);
		world.setBlock(i + 2, j + 0, k + 5, Blocks.stonebrick);
		world.setBlock(i + 2, j + 0, k + 6, Blocks.stonebrick);
		world.setBlock(i + 2, j + 0, k + 7, Blocks.stonebrick);
		world.setBlock(i + 2, j + 0, k + 8, Blocks.stonebrick);
		world.setBlock(i + 2, j + 0, k + 9, Blocks.stonebrick);
		world.setBlock(i + 2, j + 0, k + 10, Blocks.stonebrick);
		world.setBlock(i + 2, j + 0, k + 11, Blocks.stonebrick);
		world.setBlock(i + 2, j + 0, k + 12, Blocks.stonebrick);
		world.setBlock(i + 2, j + 0, k + 13, Blocks.stonebrick);
		world.setBlock(i + 2, j + 0, k + 14, Blocks.stonebrick);
		world.setBlock(i + 2, j + 0, k + 15, Blocks.stonebrick);
		world.setBlock(i + 2, j + 1, k + 0, Blocks.stonebrick);
		world.setBlock(i + 2, j + 1, k + 1, Blocks.air);
		world.setBlock(i + 2, j + 1, k + 2, Blocks.air);
		world.setBlock(i + 2, j + 1, k + 3, Blocks.air);
		world.setBlock(i + 2, j + 1, k + 4, Blocks.air);
		world.setBlock(i + 2, j + 1, k + 5, Blocks.air);
		world.setBlock(i + 2, j + 1, k + 6, Blocks.air);
		world.setBlock(i + 2, j + 1, k + 7, Blocks.air);
		world.setBlock(i + 2, j + 1, k + 8, Blocks.air);
		world.setBlock(i + 2, j + 1, k + 9, Blocks.air);
		world.setBlock(i + 2, j + 1, k + 10, Blocks.air);
		world.setBlock(i + 2, j + 1, k + 11, Blocks.air);
		world.setBlock(i + 2, j + 1, k + 12, Blocks.air);
		world.setBlock(i + 2, j + 1, k + 13, Blocks.air);
		world.setBlock(i + 2, j + 1, k + 14, Blocks.air);
		world.setBlock(i + 2, j + 1, k + 15, Blocks.stonebrick);
		world.setBlock(i + 2, j + 2, k + 0, Blocks.stonebrick);
		world.setBlock(i + 2, j + 2, k + 1, Blocks.air);
		world.setBlock(i + 2, j + 2, k + 2, Blocks.air);
		world.setBlock(i + 2, j + 2, k + 3, Blocks.air);
		world.setBlock(i + 2, j + 2, k + 4, Blocks.air);
		world.setBlock(i + 2, j + 2, k + 5, Blocks.air);
		world.setBlock(i + 2, j + 2, k + 6, Blocks.air);
		world.setBlock(i + 2, j + 2, k + 7, Blocks.air);
		world.setBlock(i + 2, j + 2, k + 8, Blocks.air);
		world.setBlock(i + 2, j + 2, k + 9, Blocks.air);
		world.setBlock(i + 2, j + 2, k + 10, Blocks.air);
		world.setBlock(i + 2, j + 2, k + 11, Blocks.air);
		world.setBlock(i + 2, j + 2, k + 12, Blocks.air);
		world.setBlock(i + 2, j + 2, k + 13, Blocks.air);
		world.setBlock(i + 2, j + 2, k + 14, Blocks.air);
		world.setBlock(i + 2, j + 2, k + 15, Blocks.stonebrick);
		world.setBlock(i + 2, j + 3, k + 0, Blocks.stonebrick);
		world.setBlock(i + 2, j + 3, k + 1, Blocks.air);
		world.setBlock(i + 2, j + 3, k + 2, Blocks.air);
		world.setBlock(i + 2, j + 3, k + 3, Blocks.air);
		world.setBlock(i + 2, j + 3, k + 4, Blocks.air);
		world.setBlock(i + 2, j + 3, k + 5, Blocks.air);
		world.setBlock(i + 2, j + 3, k + 6, Blocks.air);
		world.setBlock(i + 2, j + 3, k + 7, Blocks.air);
		world.setBlock(i + 2, j + 3, k + 8, Blocks.air);
		world.setBlock(i + 2, j + 3, k + 9, Blocks.air);
		world.setBlock(i + 2, j + 3, k + 10, Blocks.air);
		world.setBlock(i + 2, j + 3, k + 11, Blocks.air);
		world.setBlock(i + 2, j + 3, k + 12, Blocks.air);
		world.setBlock(i + 2, j + 3, k + 13, Blocks.air);
		world.setBlock(i + 2, j + 3, k + 14, Blocks.air);
		world.setBlock(i + 2, j + 3, k + 15, Blocks.stonebrick);
		world.setBlock(i + 2, j + 4, k + 0, Blocks.stonebrick);
		world.setBlock(i + 2, j + 4, k + 1, Blocks.stonebrick);
		world.setBlock(i + 2, j + 4, k + 2, Blocks.stonebrick);
		world.setBlock(i + 2, j + 4, k + 3, Blocks.stonebrick);
		world.setBlock(i + 2, j + 4, k + 4, Blocks.stonebrick);
		world.setBlock(i + 2, j + 4, k + 5, Blocks.stonebrick);
		world.setBlock(i + 2, j + 4, k + 6, Blocks.stonebrick);
		world.setBlock(i + 2, j + 4, k + 7, Blocks.stonebrick);
		world.setBlock(i + 2, j + 4, k + 8, Blocks.stonebrick);
		world.setBlock(i + 2, j + 4, k + 9, Blocks.stonebrick);
		world.setBlock(i + 2, j + 4, k + 10, Blocks.stonebrick);
		world.setBlock(i + 2, j + 4, k + 11, Blocks.stonebrick);
		world.setBlock(i + 2, j + 4, k + 12, Blocks.stonebrick);
		world.setBlock(i + 2, j + 4, k + 13, Blocks.stonebrick);
		world.setBlock(i + 2, j + 4, k + 14, Blocks.stonebrick);
		world.setBlock(i + 2, j + 4, k + 15, Blocks.stonebrick);
		world.setBlock(i + 2, j + 5, k + 0, Blocks.stonebrick);
		world.setBlock(i + 2, j + 5, k + 1, Blocks.stonebrick);
		world.setBlock(i + 2, j + 5, k + 2, Blocks.stonebrick);
		world.setBlock(i + 2, j + 5, k + 3, Blocks.stonebrick);
		world.setBlock(i + 2, j + 5, k + 4, Blocks.stonebrick);
		world.setBlock(i + 2, j + 5, k + 5, Blocks.stonebrick);
		world.setBlock(i + 2, j + 5, k + 6, Blocks.stonebrick);
		world.setBlock(i + 2, j + 5, k + 7, Blocks.stonebrick);
		world.setBlock(i + 2, j + 5, k + 8, Blocks.air);
		world.setBlock(i + 2, j + 5, k + 9, Blocks.air);
		world.setBlock(i + 2, j + 5, k + 10, Blocks.air);
		world.setBlock(i + 2, j + 5, k + 11, Blocks.air);
		world.setBlock(i + 2, j + 5, k + 12, Blocks.air);
		world.setBlock(i + 2, j + 5, k + 13, Blocks.air);
		world.setBlock(i + 2, j + 5, k + 14, Blocks.air);
		world.setBlock(i + 2, j + 5, k + 15, Blocks.stonebrick);
		world.setBlock(i + 2, j + 6, k + 0, Blocks.stonebrick);
		world.setBlock(i + 2, j + 6, k + 1, Blocks.stonebrick);
		world.setBlock(i + 2, j + 6, k + 2, Blocks.stonebrick);
		world.setBlock(i + 2, j + 6, k + 3, Blocks.stonebrick);
		world.setBlock(i + 2, j + 6, k + 4, Blocks.stonebrick);
		world.setBlock(i + 2, j + 6, k + 5, Blocks.stonebrick);
		world.setBlock(i + 2, j + 6, k + 6, Blocks.stonebrick);
		world.setBlock(i + 2, j + 6, k + 7, Blocks.stonebrick);
		world.setBlock(i + 2, j + 6, k + 8, Blocks.air);
		world.setBlock(i + 2, j + 6, k + 9, Blocks.air);
		world.setBlock(i + 2, j + 6, k + 10, Blocks.air);
		world.setBlock(i + 2, j + 6, k + 11, Blocks.air);
		world.setBlock(i + 2, j + 6, k + 12, Blocks.air);
		world.setBlock(i + 2, j + 6, k + 13, Blocks.air);
		world.setBlock(i + 2, j + 6, k + 14, Blocks.air);
		world.setBlock(i + 2, j + 6, k + 15, Blocks.stonebrick);
		world.setBlock(i + 2, j + 7, k + 0, Blocks.stonebrick);
		world.setBlock(i + 2, j + 7, k + 1, Blocks.stonebrick);
		world.setBlock(i + 2, j + 7, k + 2, Blocks.stonebrick);
		world.setBlock(i + 2, j + 7, k + 3, Blocks.stonebrick);
		world.setBlock(i + 2, j + 7, k + 4, Blocks.stonebrick);
		world.setBlock(i + 2, j + 7, k + 5, Blocks.stonebrick);
		world.setBlock(i + 2, j + 7, k + 6, Blocks.stonebrick);
		world.setBlock(i + 2, j + 7, k + 7, Blocks.stonebrick);
		world.setBlock(i + 2, j + 7, k + 8, Blocks.air);
		world.setBlock(i + 2, j + 7, k + 9, Blocks.air);
		world.setBlock(i + 2, j + 7, k + 10, Blocks.air);
		world.setBlock(i + 2, j + 7, k + 11, Blocks.air);
		world.setBlock(i + 2, j + 7, k + 12, Blocks.air);
		world.setBlock(i + 2, j + 7, k + 13, Blocks.air);
		world.setBlock(i + 2, j + 7, k + 14, Blocks.air);
		world.setBlock(i + 2, j + 7, k + 15, Blocks.stonebrick);
		world.setBlock(i + 2, j + 8, k + 0, Blocks.stonebrick);
		world.setBlock(i + 2, j + 8, k + 1, Blocks.stonebrick);
		world.setBlock(i + 2, j + 8, k + 2, Blocks.stonebrick);
		world.setBlock(i + 2, j + 8, k + 3, Blocks.stonebrick);
		world.setBlock(i + 2, j + 8, k + 4, Blocks.stonebrick);
		world.setBlock(i + 2, j + 8, k + 5, Blocks.stonebrick);
		world.setBlock(i + 2, j + 8, k + 6, Blocks.stonebrick);
		world.setBlock(i + 2, j + 8, k + 7, Blocks.stonebrick);
		world.setBlock(i + 2, j + 8, k + 8, Blocks.stonebrick);
		world.setBlock(i + 2, j + 8, k + 9, Blocks.stonebrick);
		world.setBlock(i + 2, j + 8, k + 10, Blocks.stonebrick);
		world.setBlock(i + 2, j + 8, k + 11, Blocks.stonebrick);
		world.setBlock(i + 2, j + 8, k + 12, Blocks.stonebrick);
		world.setBlock(i + 2, j + 8, k + 13, Blocks.stonebrick);
		world.setBlock(i + 2, j + 8, k + 14, Blocks.stonebrick);
		world.setBlock(i + 2, j + 8, k + 15, Blocks.stonebrick);
		world.setBlock(i + 2, j + 9, k + 0, Blocks.stonebrick);
		world.setBlock(i + 2, j + 9, k + 1, Blocks.air);
		world.setBlock(i + 2, j + 9, k + 2, Blocks.air);
		world.setBlock(i + 2, j + 9, k + 3, Blocks.air);
		world.setBlock(i + 2, j + 9, k + 4, Blocks.air);
		world.setBlock(i + 2, j + 9, k + 5, Blocks.air);
		world.setBlock(i + 2, j + 9, k + 6, Blocks.air);
		world.setBlock(i + 2, j + 9, k + 7, Blocks.air);
		world.setBlock(i + 2, j + 9, k + 8, Blocks.air);
		world.setBlock(i + 2, j + 9, k + 9, Blocks.air);
		world.setBlock(i + 2, j + 9, k + 10, Blocks.air);
		world.setBlock(i + 2, j + 9, k + 11, Blocks.air);
		world.setBlock(i + 2, j + 9, k + 12, Blocks.air);
		world.setBlock(i + 2, j + 9, k + 13, Blocks.air);
		world.setBlock(i + 2, j + 9, k + 14, Blocks.air);
		world.setBlock(i + 2, j + 9, k + 15, Blocks.stonebrick);
		world.setBlock(i + 2, j + 10, k + 0, Blocks.stonebrick);
		world.setBlock(i + 2, j + 10, k + 1, Blocks.air);
		world.setBlock(i + 2, j + 10, k + 2, Blocks.air);
		world.setBlock(i + 2, j + 10, k + 3, Blocks.air);
		world.setBlock(i + 2, j + 10, k + 4, Blocks.air);
		world.setBlock(i + 2, j + 10, k + 5, Blocks.air);
		world.setBlock(i + 2, j + 10, k + 6, Blocks.air);
		world.setBlock(i + 2, j + 10, k + 7, Blocks.air);
		world.setBlock(i + 2, j + 10, k + 8, Blocks.air);
		world.setBlock(i + 2, j + 10, k + 9, Blocks.air);
		world.setBlock(i + 2, j + 10, k + 10, Blocks.air);
		world.setBlock(i + 2, j + 10, k + 11, Blocks.air);
		world.setBlock(i + 2, j + 10, k + 12, Blocks.air);
		world.setBlock(i + 2, j + 10, k + 13, Blocks.air);
		world.setBlock(i + 2, j + 10, k + 14, Blocks.air);
		world.setBlock(i + 2, j + 10, k + 15, Blocks.stonebrick);
		world.setBlock(i + 2, j + 11, k + 0, Blocks.stonebrick);
		world.setBlock(i + 2, j + 11, k + 1, Blocks.air);
		world.setBlock(i + 2, j + 11, k + 2, Blocks.air);
		world.setBlock(i + 2, j + 11, k + 3, Blocks.air);
		world.setBlock(i + 2, j + 11, k + 4, Blocks.air);
		world.setBlock(i + 2, j + 11, k + 5, Blocks.air);
		world.setBlock(i + 2, j + 11, k + 6, Blocks.air);
		world.setBlock(i + 2, j + 11, k + 7, Blocks.air);
		world.setBlock(i + 2, j + 11, k + 8, Blocks.air);
		world.setBlock(i + 2, j + 11, k + 9, Blocks.air);
		world.setBlock(i + 2, j + 11, k + 10, Blocks.air);
		world.setBlock(i + 2, j + 11, k + 11, Blocks.air);
		world.setBlock(i + 2, j + 11, k + 12, Blocks.air);
		world.setBlock(i + 2, j + 11, k + 13, Blocks.air);
		world.setBlock(i + 2, j + 11, k + 14, Blocks.air);
		world.setBlock(i + 2, j + 11, k + 15, Blocks.stonebrick);
		world.setBlock(i + 2, j + 12, k + 0, Blocks.stonebrick);
		world.setBlock(i + 2, j + 12, k + 1, Blocks.bedrock);
		world.setBlock(i + 2, j + 12, k + 2, Blocks.bedrock);
		world.setBlock(i + 2, j + 12, k + 3, Blocks.bedrock);
		world.setBlock(i + 2, j + 12, k + 4, Blocks.bedrock);
		world.setBlock(i + 2, j + 12, k + 5, Blocks.bedrock);
		world.setBlock(i + 2, j + 12, k + 6, Blocks.bedrock);
		world.setBlock(i + 2, j + 12, k + 7, Blocks.bedrock);
		world.setBlock(i + 2, j + 12, k + 8, Blocks.bedrock);
		world.setBlock(i + 2, j + 12, k + 9, Blocks.bedrock);
		world.setBlock(i + 2, j + 12, k + 10, Blocks.bedrock);
		world.setBlock(i + 2, j + 12, k + 11, Blocks.bedrock);
		world.setBlock(i + 2, j + 12, k + 12, Blocks.bedrock);
		world.setBlock(i + 2, j + 12, k + 13, Blocks.bedrock);
		world.setBlock(i + 2, j + 12, k + 14, Blocks.bedrock);
		world.setBlock(i + 2, j + 12, k + 15, Blocks.stonebrick);
		world.setBlock(i + 2, j + 13, k + 0, Blocks.stonebrick);
		world.setBlock(i + 2, j + 13, k + 1, Blocks.air);
		world.setBlock(i + 2, j + 13, k + 2, Blocks.air);
		world.setBlock(i + 2, j + 13, k + 3, Blocks.air);
		world.setBlock(i + 2, j + 13, k + 4, Blocks.air);
		world.setBlock(i + 2, j + 13, k + 5, Blocks.air);
		world.setBlock(i + 2, j + 13, k + 6, Blocks.air);
		world.setBlock(i + 2, j + 13, k + 7, Blocks.air);
		world.setBlock(i + 2, j + 13, k + 8, Blocks.air);
		world.setBlock(i + 2, j + 13, k + 9, Blocks.air);
		world.setBlock(i + 2, j + 13, k + 10, Blocks.air);
		world.setBlock(i + 2, j + 13, k + 11, Blocks.air);
		world.setBlock(i + 2, j + 13, k + 12, Blocks.air);
		world.setBlock(i + 2, j + 13, k + 13, Blocks.air);
		world.setBlock(i + 2, j + 13, k + 14, Blocks.air);
		world.setBlock(i + 2, j + 13, k + 15, Blocks.stonebrick);
		world.setBlock(i + 2, j + 14, k + 0, Blocks.stonebrick);
		world.setBlock(i + 2, j + 14, k + 1, Blocks.air);
		world.setBlock(i + 2, j + 14, k + 2, Blocks.air);
		world.setBlock(i + 2, j + 14, k + 3, Blocks.air);
		world.setBlock(i + 2, j + 14, k + 4, Blocks.air);
		world.setBlock(i + 2, j + 14, k + 5, Blocks.air);
		world.setBlock(i + 2, j + 14, k + 6, Blocks.air);
		world.setBlock(i + 2, j + 14, k + 7, Blocks.air);
		world.setBlock(i + 2, j + 14, k + 8, Blocks.air);
		world.setBlock(i + 2, j + 14, k + 9, Blocks.air);
		world.setBlock(i + 2, j + 14, k + 10, Blocks.air);
		world.setBlock(i + 2, j + 14, k + 11, Blocks.air);
		world.setBlock(i + 2, j + 14, k + 12, Blocks.air);
		world.setBlock(i + 2, j + 14, k + 13, Blocks.air);
		world.setBlock(i + 2, j + 14, k + 14, Blocks.air);
		world.setBlock(i + 2, j + 14, k + 15, Blocks.stonebrick);
		world.setBlock(i + 2, j + 15, k + 0, Blocks.stonebrick);
		world.setBlock(i + 2, j + 15, k + 1, Blocks.air);
		world.setBlock(i + 2, j + 15, k + 2, Blocks.air);
		world.setBlock(i + 2, j + 15, k + 3, Blocks.air);
		world.setBlock(i + 2, j + 15, k + 4, Blocks.air);
		world.setBlock(i + 2, j + 15, k + 5, Blocks.air);
		world.setBlock(i + 2, j + 15, k + 6, Blocks.air);
		world.setBlock(i + 2, j + 15, k + 7, Blocks.air);
		world.setBlock(i + 2, j + 15, k + 8, Blocks.air);
		world.setBlock(i + 2, j + 15, k + 9, Blocks.air);
		world.setBlock(i + 2, j + 15, k + 10, Blocks.air);
		world.setBlock(i + 2, j + 15, k + 11, Blocks.air);
		world.setBlock(i + 2, j + 15, k + 12, Blocks.air);
		world.setBlock(i + 2, j + 15, k + 13, Blocks.air);
		world.setBlock(i + 2, j + 15, k + 14, Blocks.air);
		world.setBlock(i + 2, j + 15, k + 15, Blocks.stonebrick);
		world.setBlock(i + 2, j + 16, k + 0, Blocks.stonebrick);
		world.setBlock(i + 2, j + 16, k + 1, Blocks.stonebrick);
		world.setBlock(i + 2, j + 16, k + 2, Blocks.stonebrick);
		world.setBlock(i + 2, j + 16, k + 3, Blocks.stonebrick);
		world.setBlock(i + 2, j + 16, k + 4, Blocks.stonebrick);
		world.setBlock(i + 2, j + 16, k + 5, Blocks.stonebrick);
		world.setBlock(i + 2, j + 16, k + 6, Blocks.stonebrick);
		world.setBlock(i + 2, j + 16, k + 7, Blocks.stonebrick);
		world.setBlock(i + 2, j + 16, k + 8, Blocks.stonebrick);
		world.setBlock(i + 2, j + 16, k + 9, Blocks.stonebrick);
		world.setBlock(i + 2, j + 16, k + 10, Blocks.stonebrick);
		world.setBlock(i + 2, j + 16, k + 11, Blocks.stonebrick);
		world.setBlock(i + 2, j + 16, k + 12, Blocks.stonebrick);
		world.setBlock(i + 2, j + 16, k + 13, Blocks.stonebrick);
		world.setBlock(i + 2, j + 16, k + 14, Blocks.stonebrick);
		world.setBlock(i + 2, j + 16, k + 15, Blocks.stonebrick);
		world.setBlock(i + 2, j + 17, k + 0, Blocks.stonebrick);
		world.setBlock(i + 2, j + 17, k + 1, Blocks.stonebrick);
		world.setBlock(i + 2, j + 17, k + 2, Blocks.stonebrick);
		world.setBlock(i + 2, j + 17, k + 3, Blocks.stonebrick);
		world.setBlock(i + 2, j + 17, k + 4, Blocks.stonebrick);
		world.setBlock(i + 2, j + 17, k + 5, Blocks.stonebrick);
		world.setBlock(i + 2, j + 17, k + 6, Blocks.stonebrick);
		world.setBlock(i + 2, j + 17, k + 7, Blocks.stonebrick);
		world.setBlock(i + 2, j + 17, k + 8, Blocks.stonebrick);
		world.setBlock(i + 2, j + 17, k + 9, Blocks.stonebrick);
		world.setBlock(i + 2, j + 17, k + 10, Blocks.stonebrick);
		world.setBlock(i + 2, j + 17, k + 11, Blocks.stonebrick);
		world.setBlock(i + 2, j + 17, k + 12, Blocks.stonebrick);
		world.setBlock(i + 2, j + 17, k + 13, Blocks.stonebrick);
		world.setBlock(i + 2, j + 17, k + 14, Blocks.stonebrick);
		world.setBlock(i + 2, j + 17, k + 15, Blocks.stonebrick);
		world.setBlock(i + 2, j + 18, k + 0, Blocks.air);
		world.setBlock(i + 2, j + 18, k + 1, Blocks.air);
		world.setBlock(i + 2, j + 18, k + 2, Blocks.air);
		world.setBlock(i + 2, j + 18, k + 3, Blocks.air);
		world.setBlock(i + 2, j + 18, k + 4, Blocks.air);
		world.setBlock(i + 2, j + 18, k + 5, Blocks.air);
		world.setBlock(i + 2, j + 18, k + 6, Blocks.air);
		world.setBlock(i + 2, j + 18, k + 7, Blocks.air);
		world.setBlock(i + 2, j + 18, k + 8, Blocks.air);
		world.setBlock(i + 2, j + 18, k + 9, Blocks.air);
		world.setBlock(i + 2, j + 18, k + 10, Blocks.air);
		world.setBlock(i + 2, j + 18, k + 11, Blocks.air);
		world.setBlock(i + 2, j + 18, k + 12, Blocks.air);
		world.setBlock(i + 2, j + 18, k + 13, Blocks.air);
		world.setBlock(i + 2, j + 18, k + 14, Blocks.air);
		world.setBlock(i + 2, j + 18, k + 15, Blocks.air);
		world.setBlock(i + 2, j + 19, k + 0, Blocks.air);
		world.setBlock(i + 2, j + 19, k + 1, Blocks.air);
		world.setBlock(i + 2, j + 19, k + 2, Blocks.air);
		world.setBlock(i + 2, j + 19, k + 3, Blocks.air);
		world.setBlock(i + 2, j + 19, k + 4, Blocks.air);
		world.setBlock(i + 2, j + 19, k + 5, Blocks.air);
		world.setBlock(i + 2, j + 19, k + 6, Blocks.air);
		world.setBlock(i + 2, j + 19, k + 7, Blocks.air);
		world.setBlock(i + 2, j + 19, k + 8, Blocks.air);
		world.setBlock(i + 2, j + 19, k + 9, Blocks.air);
		world.setBlock(i + 2, j + 19, k + 10, Blocks.air);
		world.setBlock(i + 2, j + 19, k + 11, Blocks.air);
		world.setBlock(i + 2, j + 19, k + 12, Blocks.air);
		world.setBlock(i + 2, j + 19, k + 13, Blocks.air);
		world.setBlock(i + 2, j + 19, k + 14, Blocks.air);
		world.setBlock(i + 2, j + 19, k + 15, Blocks.air);
		world.setBlock(i + 2, j + 20, k + 0, Blocks.air);
		world.setBlock(i + 2, j + 20, k + 1, Blocks.air);
		world.setBlock(i + 2, j + 20, k + 2, Blocks.air);
		world.setBlock(i + 2, j + 20, k + 3, Blocks.air);
		world.setBlock(i + 2, j + 20, k + 4, Blocks.air);
		world.setBlock(i + 2, j + 20, k + 5, Blocks.air);
		world.setBlock(i + 2, j + 20, k + 6, Blocks.air);
		world.setBlock(i + 2, j + 20, k + 7, Blocks.air);
		world.setBlock(i + 2, j + 20, k + 8, Blocks.air);
		world.setBlock(i + 2, j + 20, k + 9, Blocks.air);
		world.setBlock(i + 2, j + 20, k + 10, Blocks.air);
		world.setBlock(i + 2, j + 20, k + 11, Blocks.air);
		world.setBlock(i + 2, j + 20, k + 12, Blocks.air);
		world.setBlock(i + 2, j + 20, k + 13, Blocks.air);
		world.setBlock(i + 2, j + 20, k + 14, Blocks.air);
		world.setBlock(i + 2, j + 20, k + 15, Blocks.air);
		world.setBlock(i + 3, j + 0, k + 0, Blocks.stonebrick);
		world.setBlock(i + 3, j + 0, k + 1, Blocks.stonebrick);
		world.setBlock(i + 3, j + 0, k + 2, Blocks.stonebrick);
		world.setBlock(i + 3, j + 0, k + 3, Blocks.stonebrick);
		world.setBlock(i + 3, j + 0, k + 4, Blocks.stonebrick);
		world.setBlock(i + 3, j + 0, k + 5, Blocks.stonebrick);
		world.setBlock(i + 3, j + 0, k + 6, Blocks.stonebrick);
		world.setBlock(i + 3, j + 0, k + 7, Blocks.stonebrick);
		world.setBlock(i + 3, j + 0, k + 8, Blocks.stonebrick);
		world.setBlock(i + 3, j + 0, k + 9, Blocks.stonebrick);
		world.setBlock(i + 3, j + 0, k + 10, Blocks.stonebrick);
		world.setBlock(i + 3, j + 0, k + 11, Blocks.stonebrick);
		world.setBlock(i + 3, j + 0, k + 12, Blocks.stonebrick);
		world.setBlock(i + 3, j + 0, k + 13, Blocks.stonebrick);
		world.setBlock(i + 3, j + 0, k + 14, Blocks.stonebrick);
		world.setBlock(i + 3, j + 0, k + 15, Blocks.stonebrick);
		world.setBlock(i + 3, j + 1, k + 0, Blocks.stonebrick);
		world.setBlock(i + 3, j + 1, k + 1, Blocks.air);
		world.setBlock(i + 3, j + 1, k + 2, Blocks.air);
		world.setBlock(i + 3, j + 1, k + 3, Blocks.air);
		world.setBlock(i + 3, j + 1, k + 4, Blocks.stonebrick);
		world.setBlock(i + 3, j + 1, k + 5, Blocks.stonebrick);
		world.setBlock(i + 3, j + 1, k + 6, Blocks.stonebrick);
		world.setBlock(i + 3, j + 1, k + 7, Blocks.stonebrick);
		world.setBlock(i + 3, j + 1, k + 8, Blocks.stonebrick);
		world.setBlock(i + 3, j + 1, k + 9, Blocks.stonebrick);
		world.setBlock(i + 3, j + 1, k + 10, Blocks.stonebrick);
		world.setBlock(i + 3, j + 1, k + 11, Blocks.stonebrick);
		world.setBlock(i + 3, j + 1, k + 12, Blocks.stonebrick);
		world.setBlock(i + 3, j + 1, k + 13, Blocks.stonebrick);
		world.setBlock(i + 3, j + 1, k + 15, Blocks.stonebrick);
		world.setBlock(i + 3, j + 2, k + 0, Blocks.stonebrick);
		world.setBlock(i + 3, j + 2, k + 1, Blocks.air);
		world.setBlock(i + 3, j + 2, k + 2, Blocks.air);
		world.setBlock(i + 3, j + 2, k + 3, Blocks.air);
		world.setBlock(i + 3, j + 2, k + 4, Blocks.stonebrick);
		world.setBlock(i + 3, j + 2, k + 5, Blocks.stonebrick);
		world.setBlock(i + 3, j + 2, k + 6, Blocks.stonebrick);
		world.setBlock(i + 3, j + 2, k + 7, Blocks.stonebrick);
		world.setBlock(i + 3, j + 2, k + 8, Blocks.stonebrick);
		world.setBlock(i + 3, j + 2, k + 9, Blocks.stonebrick);
		world.setBlock(i + 3, j + 2, k + 10, Blocks.stonebrick);
		world.setBlock(i + 3, j + 2, k + 11, Blocks.stonebrick);
		world.setBlock(i + 3, j + 2, k + 12, Blocks.stonebrick);
		world.setBlock(i + 3, j + 2, k + 13, Blocks.stonebrick);
		world.setBlock(i + 3, j + 2, k + 15, Blocks.stonebrick);
		world.setBlock(i + 3, j + 3, k + 0, Blocks.stonebrick);
		world.setBlock(i + 3, j + 3, k + 1, Blocks.air);
		world.setBlock(i + 3, j + 3, k + 2, Blocks.air);
		world.setBlock(i + 3, j + 3, k + 3, Blocks.air);
		world.setBlock(i + 3, j + 3, k + 4, Blocks.stonebrick);
		world.setBlock(i + 3, j + 3, k + 5, Blocks.stonebrick);
		world.setBlock(i + 3, j + 3, k + 6, Blocks.stonebrick);
		world.setBlock(i + 3, j + 3, k + 7, Blocks.stonebrick);
		world.setBlock(i + 3, j + 3, k + 8, Blocks.stonebrick);
		world.setBlock(i + 3, j + 3, k + 9, Blocks.stonebrick);
		world.setBlock(i + 3, j + 3, k + 10, Blocks.stonebrick);
		world.setBlock(i + 3, j + 3, k + 11, Blocks.stonebrick);
		world.setBlock(i + 3, j + 3, k + 12, Blocks.stonebrick);
		world.setBlock(i + 3, j + 3, k + 13, Blocks.stonebrick);
		world.setBlock(i + 3, j + 3, k + 14, Blocks.stonebrick);
		world.setBlock(i + 3, j + 3, k + 15, Blocks.stonebrick);
		world.setBlock(i + 3, j + 4, k + 0, Blocks.stonebrick);
		world.setBlock(i + 3, j + 4, k + 1, Blocks.stonebrick);
		world.setBlock(i + 3, j + 4, k + 2, Blocks.stonebrick);
		world.setBlock(i + 3, j + 4, k + 3, Blocks.stonebrick);
		world.setBlock(i + 3, j + 4, k + 4, Blocks.stonebrick);
		world.setBlock(i + 3, j + 4, k + 5, Blocks.stonebrick);
		world.setBlock(i + 3, j + 4, k + 6, Blocks.stonebrick);
		world.setBlock(i + 3, j + 4, k + 7, Blocks.stonebrick);
		world.setBlock(i + 3, j + 4, k + 8, Blocks.stonebrick);
		world.setBlock(i + 3, j + 4, k + 9, Blocks.stonebrick);
		world.setBlock(i + 3, j + 4, k + 10, Blocks.stonebrick);
		world.setBlock(i + 3, j + 4, k + 11, Blocks.stonebrick);
		world.setBlock(i + 3, j + 4, k + 12, Blocks.stonebrick);
		world.setBlock(i + 3, j + 4, k + 13, Blocks.stonebrick);
		world.setBlock(i + 3, j + 4, k + 14, Blocks.stonebrick);
		world.setBlock(i + 3, j + 4, k + 15, Blocks.stonebrick);
		world.setBlock(i + 3, j + 5, k + 0, Blocks.stonebrick);
		world.setBlock(i + 3, j + 5, k + 1, Blocks.redstone_block);// MOB
		// SPAWNER
		world.setBlock(i + 3, j + 5, k + 2, Blocks.air);
		world.setBlock(i + 3, j + 5, k + 3, Blocks.air);
		world.setBlock(i + 3, j + 5, k + 4, Blocks.air);
		world.setBlock(i + 3, j + 5, k + 5, Blocks.air);
		world.setBlock(i + 3, j + 5, k + 6, Blocks.air);
		world.setBlock(i + 3, j + 5, k + 7, Blocks.stonebrick);
		world.setBlock(i + 3, j + 5, k + 8, Blocks.air);
		world.setBlock(i + 3, j + 5, k + 9, Blocks.air);
		world.setBlock(i + 3, j + 5, k + 10, Blocks.air);
		world.setBlock(i + 3, j + 5, k + 11, Blocks.air);
		world.setBlock(i + 3, j + 5, k + 12, Blocks.air);
		world.setBlock(i + 3, j + 5, k + 13, Blocks.air);
		world.setBlock(i + 3, j + 5, k + 14, Blocks.air);
		world.setBlock(i + 3, j + 5, k + 15, Blocks.stonebrick);
		world.setBlock(i + 3, j + 6, k + 0, Blocks.stonebrick);
		world.setBlock(i + 3, j + 6, k + 1, Blocks.air);
		world.setBlock(i + 3, j + 6, k + 2, Blocks.air);
		world.setBlock(i + 3, j + 6, k + 3, Blocks.air);
		world.setBlock(i + 3, j + 6, k + 4, Blocks.air);
		world.setBlock(i + 3, j + 6, k + 5, Blocks.air);
		world.setBlock(i + 3, j + 6, k + 6, Blocks.air);
		world.setBlock(i + 3, j + 6, k + 7, Blocks.stonebrick);
		world.setBlock(i + 3, j + 6, k + 8, Blocks.air);
		world.setBlock(i + 3, j + 6, k + 9, Blocks.air);
		world.setBlock(i + 3, j + 6, k + 10, Blocks.air);
		world.setBlock(i + 3, j + 6, k + 11, Blocks.air);
		world.setBlock(i + 3, j + 6, k + 12, Blocks.air);
		world.setBlock(i + 3, j + 6, k + 13, Blocks.air);
		world.setBlock(i + 3, j + 6, k + 14, Blocks.air);
		world.setBlock(i + 3, j + 6, k + 15, Blocks.stonebrick);
		world.setBlock(i + 3, j + 7, k + 0, Blocks.stonebrick);
		world.setBlock(i + 3, j + 7, k + 1, Blocks.air);
		world.setBlock(i + 3, j + 7, k + 2, Blocks.air);
		world.setBlock(i + 3, j + 7, k + 3, Blocks.air);
		world.setBlock(i + 3, j + 7, k + 4, Blocks.air);
		world.setBlock(i + 3, j + 7, k + 5, Blocks.air);
		world.setBlock(i + 3, j + 7, k + 6, Blocks.air);
		world.setBlock(i + 3, j + 7, k + 7, Blocks.stonebrick);
		world.setBlock(i + 3, j + 7, k + 8, Blocks.air);
		world.setBlock(i + 3, j + 7, k + 9, Blocks.air);
		world.setBlock(i + 3, j + 7, k + 10, Blocks.air);
		world.setBlock(i + 3, j + 7, k + 11, Blocks.air);
		world.setBlock(i + 3, j + 7, k + 12, Blocks.air);
		world.setBlock(i + 3, j + 7, k + 13, Blocks.air);
		world.setBlock(i + 3, j + 7, k + 14, Blocks.air);
		world.setBlock(i + 3, j + 7, k + 15, Blocks.stonebrick);
		world.setBlock(i + 3, j + 8, k + 0, Blocks.stonebrick);
		world.setBlock(i + 3, j + 8, k + 1, Blocks.stonebrick);
		world.setBlock(i + 3, j + 8, k + 2, Blocks.stonebrick);
		world.setBlock(i + 3, j + 8, k + 3, Blocks.stonebrick);
		world.setBlock(i + 3, j + 8, k + 4, Blocks.stonebrick);
		world.setBlock(i + 3, j + 8, k + 5, Blocks.stonebrick);
		world.setBlock(i + 3, j + 8, k + 6, Blocks.stonebrick);
		world.setBlock(i + 3, j + 8, k + 7, Blocks.stonebrick);
		world.setBlock(i + 3, j + 8, k + 8, Blocks.stonebrick);
		world.setBlock(i + 3, j + 8, k + 9, Blocks.stonebrick);
		world.setBlock(i + 3, j + 8, k + 10, Blocks.stonebrick);
		world.setBlock(i + 3, j + 8, k + 11, Blocks.stonebrick);
		world.setBlock(i + 3, j + 8, k + 12, Blocks.stonebrick);
		world.setBlock(i + 3, j + 8, k + 13, Blocks.stonebrick);
		world.setBlock(i + 3, j + 8, k + 14, Blocks.stonebrick);
		world.setBlock(i + 3, j + 8, k + 15, Blocks.stonebrick);
		world.setBlock(i + 3, j + 9, k + 0, Blocks.stonebrick);
		world.setBlock(i + 3, j + 9, k + 1, Blocks.air);
		world.setBlock(i + 3, j + 9, k + 2, Blocks.air);
		world.setBlock(i + 3, j + 9, k + 3, Blocks.air);
		world.setBlock(i + 3, j + 9, k + 4, Blocks.air);
		world.setBlock(i + 3, j + 9, k + 5, Blocks.air);
		world.setBlock(i + 3, j + 9, k + 6, Blocks.air);
		world.setBlock(i + 3, j + 9, k + 7, Blocks.air);
		world.setBlock(i + 3, j + 9, k + 8, Blocks.air);
		world.setBlock(i + 3, j + 9, k + 9, Blocks.air);
		world.setBlock(i + 3, j + 9, k + 10, Blocks.air);
		world.setBlock(i + 3, j + 9, k + 11, Blocks.air);
		world.setBlock(i + 3, j + 9, k + 12, Blocks.air);
		world.setBlock(i + 3, j + 9, k + 13, Blocks.air);
		world.setBlock(i + 3, j + 9, k + 14, Blocks.air);
		world.setBlock(i + 3, j + 9, k + 15, Blocks.stonebrick);
		world.setBlock(i + 3, j + 10, k + 0, Blocks.stonebrick);
		world.setBlock(i + 3, j + 10, k + 1, Blocks.air);
		world.setBlock(i + 3, j + 10, k + 2, Blocks.air);
		world.setBlock(i + 3, j + 10, k + 3, Blocks.air);
		world.setBlock(i + 3, j + 10, k + 4, Blocks.air);
		world.setBlock(i + 3, j + 10, k + 5, Blocks.air);
		world.setBlock(i + 3, j + 10, k + 6, Blocks.air);
		world.setBlock(i + 3, j + 10, k + 7, Blocks.air);
		world.setBlock(i + 3, j + 10, k + 8, Blocks.air);
		world.setBlock(i + 3, j + 10, k + 9, Blocks.air);
		world.setBlock(i + 3, j + 10, k + 10, Blocks.air);
		world.setBlock(i + 3, j + 10, k + 11, Blocks.air);
		world.setBlock(i + 3, j + 10, k + 12, Blocks.air);
		world.setBlock(i + 3, j + 10, k + 13, Blocks.air);
		world.setBlock(i + 3, j + 10, k + 14, Blocks.air);
		world.setBlock(i + 3, j + 10, k + 15, Blocks.stonebrick);
		world.setBlock(i + 3, j + 11, k + 0, Blocks.stonebrick);
		world.setBlock(i + 3, j + 11, k + 1, Blocks.air);
		world.setBlock(i + 3, j + 11, k + 2, Blocks.air);
		world.setBlock(i + 3, j + 11, k + 3, Blocks.air);
		world.setBlock(i + 3, j + 11, k + 4, Blocks.air);
		world.setBlock(i + 3, j + 11, k + 5, Blocks.air);
		world.setBlock(i + 3, j + 11, k + 6, Blocks.air);
		world.setBlock(i + 3, j + 11, k + 7, Blocks.air);
		world.setBlock(i + 3, j + 11, k + 8, Blocks.air);
		world.setBlock(i + 3, j + 11, k + 9, Blocks.air);
		world.setBlock(i + 3, j + 11, k + 10, Blocks.air);
		world.setBlock(i + 3, j + 11, k + 11, Blocks.air);
		world.setBlock(i + 3, j + 11, k + 12, Blocks.air);
		world.setBlock(i + 3, j + 11, k + 13, Blocks.air);
		world.setBlock(i + 3, j + 11, k + 14, Blocks.air);
		world.setBlock(i + 3, j + 11, k + 15, Blocks.stonebrick);
		world.setBlock(i + 3, j + 12, k + 0, Blocks.stonebrick);
		world.setBlock(i + 3, j + 12, k + 1, Blocks.bedrock);
		world.setBlock(i + 3, j + 12, k + 2, Blocks.bedrock);
		world.setBlock(i + 3, j + 12, k + 3, Blocks.bedrock);
		world.setBlock(i + 3, j + 12, k + 4, Blocks.bedrock);
		world.setBlock(i + 3, j + 12, k + 5, Blocks.bedrock);
		world.setBlock(i + 3, j + 12, k + 6, Blocks.bedrock);
		world.setBlock(i + 3, j + 12, k + 7, Blocks.bedrock);
		world.setBlock(i + 3, j + 12, k + 8, Blocks.bedrock);
		world.setBlock(i + 3, j + 12, k + 9, Blocks.bedrock);
		world.setBlock(i + 3, j + 12, k + 10, Blocks.bedrock);
		world.setBlock(i + 3, j + 12, k + 11, Blocks.bedrock);
		world.setBlock(i + 3, j + 12, k + 12, Blocks.bedrock);
		world.setBlock(i + 3, j + 12, k + 13, Blocks.bedrock);
		world.setBlock(i + 3, j + 12, k + 14, Blocks.bedrock);
		world.setBlock(i + 3, j + 12, k + 15, Blocks.stonebrick);
		world.setBlock(i + 3, j + 13, k + 0, Blocks.stonebrick);
		world.setBlock(i + 3, j + 13, k + 1, Blocks.air);
		world.setBlock(i + 3, j + 13, k + 2, Blocks.air);
		world.setBlock(i + 3, j + 13, k + 3, Blocks.air);
		world.setBlock(i + 3, j + 13, k + 4, Blocks.air);
		world.setBlock(i + 3, j + 13, k + 5, Blocks.air);
		world.setBlock(i + 3, j + 13, k + 6, Blocks.air);
		world.setBlock(i + 3, j + 13, k + 7, Blocks.air);
		world.setBlock(i + 3, j + 13, k + 8, Blocks.air);
		world.setBlock(i + 3, j + 13, k + 9, Blocks.air);
		world.setBlock(i + 3, j + 13, k + 11, Blocks.air);
		world.setBlock(i + 3, j + 13, k + 12, Blocks.air);
		world.setBlock(i + 3, j + 13, k + 13, Blocks.air);
		world.setBlock(i + 3, j + 13, k + 14, Blocks.air);
		world.setBlock(i + 3, j + 13, k + 15, Blocks.stonebrick);
		world.setBlock(i + 3, j + 14, k + 0, Blocks.stonebrick);
		world.setBlock(i + 3, j + 14, k + 1, Blocks.air);
		world.setBlock(i + 3, j + 14, k + 2, Blocks.air);
		world.setBlock(i + 3, j + 14, k + 3, Blocks.air);
		world.setBlock(i + 3, j + 14, k + 4, Blocks.air);
		world.setBlock(i + 3, j + 14, k + 5, Blocks.air);
		world.setBlock(i + 3, j + 14, k + 6, Blocks.air);
		world.setBlock(i + 3, j + 14, k + 7, Blocks.air);
		world.setBlock(i + 3, j + 14, k + 8, Blocks.air);
		world.setBlock(i + 3, j + 14, k + 9, Blocks.air);
		world.setBlock(i + 3, j + 14, k + 10, Blocks.air);
		world.setBlock(i + 3, j + 14, k + 11, Blocks.air);
		world.setBlock(i + 3, j + 14, k + 12, Blocks.air);
		world.setBlock(i + 3, j + 14, k + 13, Blocks.air);
		world.setBlock(i + 3, j + 14, k + 14, Blocks.air);
		world.setBlock(i + 3, j + 14, k + 15, Blocks.stonebrick);
		world.setBlock(i + 3, j + 15, k + 0, Blocks.stonebrick);
		world.setBlock(i + 3, j + 15, k + 1, Blocks.air);
		world.setBlock(i + 3, j + 15, k + 2, Blocks.air);
		world.setBlock(i + 3, j + 15, k + 3, Blocks.air);
		world.setBlock(i + 3, j + 15, k + 4, Blocks.air);
		world.setBlock(i + 3, j + 15, k + 5, Blocks.air);
		world.setBlock(i + 3, j + 15, k + 6, Blocks.air);
		world.setBlock(i + 3, j + 15, k + 7, Blocks.air);
		world.setBlock(i + 3, j + 15, k + 8, Blocks.air);
		world.setBlock(i + 3, j + 15, k + 9, Blocks.air);
		world.setBlock(i + 3, j + 15, k + 10, Blocks.air);
		world.setBlock(i + 3, j + 15, k + 11, Blocks.air);
		world.setBlock(i + 3, j + 15, k + 12, Blocks.air);
		world.setBlock(i + 3, j + 15, k + 13, Blocks.air);
		world.setBlock(i + 3, j + 15, k + 14, Blocks.air);
		world.setBlock(i + 3, j + 15, k + 15, Blocks.stonebrick);
		world.setBlock(i + 3, j + 16, k + 0, Blocks.stonebrick);
		world.setBlock(i + 3, j + 16, k + 1, Blocks.stonebrick);
		world.setBlock(i + 3, j + 16, k + 2, Blocks.stonebrick);
		world.setBlock(i + 3, j + 16, k + 3, Blocks.stonebrick);
		world.setBlock(i + 3, j + 16, k + 4, Blocks.stonebrick);
		world.setBlock(i + 3, j + 16, k + 5, Blocks.stonebrick);
		world.setBlock(i + 3, j + 16, k + 6, Blocks.stonebrick);
		world.setBlock(i + 3, j + 16, k + 7, Blocks.stonebrick);
		world.setBlock(i + 3, j + 16, k + 8, Blocks.stonebrick);
		world.setBlock(i + 3, j + 16, k + 9, Blocks.stonebrick);
		world.setBlock(i + 3, j + 16, k + 10, Blocks.stonebrick);
		world.setBlock(i + 3, j + 16, k + 11, Blocks.stonebrick);
		world.setBlock(i + 3, j + 16, k + 12, Blocks.stonebrick);
		world.setBlock(i + 3, j + 16, k + 13, Blocks.stonebrick);
		world.setBlock(i + 3, j + 16, k + 14, Blocks.stonebrick);
		world.setBlock(i + 3, j + 16, k + 15, Blocks.stonebrick);
		world.setBlock(i + 3, j + 17, k + 0, Blocks.stonebrick);
		world.setBlock(i + 3, j + 17, k + 1, Blocks.stonebrick);
		world.setBlock(i + 3, j + 17, k + 2, Blocks.stonebrick);
		world.setBlock(i + 3, j + 17, k + 3, Blocks.stonebrick);
		world.setBlock(i + 3, j + 17, k + 4, Blocks.stonebrick);
		world.setBlock(i + 3, j + 17, k + 5, Blocks.stonebrick);
		world.setBlock(i + 3, j + 17, k + 6, Blocks.stonebrick);
		world.setBlock(i + 3, j + 17, k + 7, Blocks.stonebrick);
		world.setBlock(i + 3, j + 17, k + 8, Blocks.stonebrick);
		world.setBlock(i + 3, j + 17, k + 9, Blocks.stonebrick);
		world.setBlock(i + 3, j + 17, k + 10, Blocks.stonebrick);
		world.setBlock(i + 3, j + 17, k + 11, Blocks.stonebrick);
		world.setBlock(i + 3, j + 17, k + 12, Blocks.stonebrick);
		world.setBlock(i + 3, j + 17, k + 13, Blocks.stonebrick);
		world.setBlock(i + 3, j + 17, k + 14, Blocks.stonebrick);
		world.setBlock(i + 3, j + 17, k + 15, Blocks.stonebrick);
		world.setBlock(i + 3, j + 18, k + 0, Blocks.air);
		world.setBlock(i + 3, j + 18, k + 1, Blocks.air);
		world.setBlock(i + 3, j + 18, k + 2, Blocks.air);
		world.setBlock(i + 3, j + 18, k + 3, Blocks.air);
		world.setBlock(i + 3, j + 18, k + 4, Blocks.air);
		world.setBlock(i + 3, j + 18, k + 5, Blocks.air);
		world.setBlock(i + 3, j + 18, k + 6, Blocks.air);
		world.setBlock(i + 3, j + 18, k + 7, Blocks.air);
		world.setBlock(i + 3, j + 18, k + 8, Blocks.air);
		world.setBlock(i + 3, j + 18, k + 9, Blocks.air);
		world.setBlock(i + 3, j + 18, k + 10, Blocks.air);
		world.setBlock(i + 3, j + 18, k + 11, Blocks.air);
		world.setBlock(i + 3, j + 18, k + 12, Blocks.air);
		world.setBlock(i + 3, j + 18, k + 13, Blocks.air);
		world.setBlock(i + 3, j + 18, k + 14, Blocks.air);
		world.setBlock(i + 3, j + 18, k + 15, Blocks.air);
		world.setBlock(i + 3, j + 19, k + 0, Blocks.air);
		world.setBlock(i + 3, j + 19, k + 1, Blocks.air);
		world.setBlock(i + 3, j + 19, k + 2, Blocks.air);
		world.setBlock(i + 3, j + 19, k + 3, Blocks.air);
		world.setBlock(i + 3, j + 19, k + 4, Blocks.air);
		world.setBlock(i + 3, j + 19, k + 5, Blocks.air);
		world.setBlock(i + 3, j + 19, k + 6, Blocks.air);
		world.setBlock(i + 3, j + 19, k + 7, Blocks.air);
		world.setBlock(i + 3, j + 19, k + 8, Blocks.air);
		world.setBlock(i + 3, j + 19, k + 9, Blocks.air);
		world.setBlock(i + 3, j + 19, k + 10, Blocks.air);
		world.setBlock(i + 3, j + 19, k + 11, Blocks.air);
		world.setBlock(i + 3, j + 19, k + 12, Blocks.air);
		world.setBlock(i + 3, j + 19, k + 13, Blocks.air);
		world.setBlock(i + 3, j + 19, k + 14, Blocks.air);
		world.setBlock(i + 3, j + 19, k + 15, Blocks.air);
		world.setBlock(i + 3, j + 20, k + 0, Blocks.air);
		world.setBlock(i + 3, j + 20, k + 1, Blocks.air);
		world.setBlock(i + 3, j + 20, k + 2, Blocks.air);
		world.setBlock(i + 3, j + 20, k + 3, Blocks.air);
		world.setBlock(i + 3, j + 20, k + 4, Blocks.air);
		world.setBlock(i + 3, j + 20, k + 5, Blocks.air);
		world.setBlock(i + 3, j + 20, k + 6, Blocks.air);
		world.setBlock(i + 3, j + 20, k + 7, Blocks.air);
		world.setBlock(i + 3, j + 20, k + 8, Blocks.air);
		world.setBlock(i + 3, j + 20, k + 9, Blocks.air);
		world.setBlock(i + 3, j + 20, k + 10, Blocks.air);
		world.setBlock(i + 3, j + 20, k + 11, Blocks.air);
		world.setBlock(i + 3, j + 20, k + 12, Blocks.air);
		world.setBlock(i + 3, j + 20, k + 13, Blocks.air);
		world.setBlock(i + 3, j + 20, k + 14, Blocks.air);
		world.setBlock(i + 3, j + 20, k + 15, Blocks.air);
		world.setBlock(i + 4, j + 0, k + 0, Blocks.stonebrick);
		world.setBlock(i + 4, j + 0, k + 1, Blocks.stonebrick);
		world.setBlock(i + 4, j + 0, k + 2, Blocks.stonebrick);
		world.setBlock(i + 4, j + 0, k + 3, Blocks.stonebrick);
		world.setBlock(i + 4, j + 0, k + 4, Blocks.stonebrick);
		world.setBlock(i + 4, j + 0, k + 5, Blocks.stonebrick);
		world.setBlock(i + 4, j + 0, k + 6, Blocks.stonebrick);
		world.setBlock(i + 4, j + 0, k + 7, Blocks.stonebrick);
		world.setBlock(i + 4, j + 0, k + 8, Blocks.stonebrick);
		world.setBlock(i + 4, j + 0, k + 9, Blocks.stonebrick);
		world.setBlock(i + 4, j + 0, k + 10, Blocks.stonebrick);
		world.setBlock(i + 4, j + 0, k + 11, Blocks.stonebrick);
		world.setBlock(i + 4, j + 0, k + 12, Blocks.stonebrick);
		world.setBlock(i + 4, j + 0, k + 13, Blocks.stonebrick);
		world.setBlock(i + 4, j + 0, k + 14, Blocks.stonebrick);
		world.setBlock(i + 4, j + 0, k + 15, Blocks.stonebrick);
		world.setBlock(i + 4, j + 1, k + 0, Blocks.stonebrick);
		world.setBlock(i + 4, j + 1, k + 1, Blocks.air);
		world.setBlock(i + 4, j + 1, k + 2, Blocks.air);
		world.setBlock(i + 4, j + 1, k + 3, Blocks.air);
		world.setBlock(i + 4, j + 1, k + 4, Blocks.stonebrick);
		world.setBlock(i + 4, j + 1, k + 5, Blocks.air);
		world.setBlock(i + 4, j + 1, k + 6, Blocks.air);
		world.setBlock(i + 4, j + 1, k + 7, Blocks.air);
		world.setBlock(i + 4, j + 1, k + 8, Blocks.air);
		world.setBlock(i + 4, j + 1, k + 9, Blocks.air);
		world.setBlock(i + 4, j + 1, k + 10, Blocks.air);
		world.setBlock(i + 4, j + 1, k + 11, Blocks.air);
		world.setBlock(i + 4, j + 1, k + 12, Blocks.air);
		world.setBlock(i + 4, j + 1, k + 13, Blocks.air);
		world.setBlock(i + 4, j + 1, k + 14, Blocks.air);
		world.setBlock(i + 4, j + 1, k + 15, Blocks.stonebrick);
		world.setBlock(i + 4, j + 2, k + 0, Blocks.stonebrick);
		world.setBlock(i + 4, j + 2, k + 1, Blocks.air);
		world.setBlock(i + 4, j + 2, k + 2, Blocks.air);
		world.setBlock(i + 4, j + 2, k + 3, Blocks.air);
		world.setBlock(i + 4, j + 2, k + 4, Blocks.stonebrick);
		world.setBlock(i + 4, j + 2, k + 5, Blocks.air);
		world.setBlock(i + 4, j + 2, k + 6, Blocks.air);
		world.setBlock(i + 4, j + 2, k + 7, Blocks.air);
		world.setBlock(i + 4, j + 2, k + 8, Blocks.air);
		world.setBlock(i + 4, j + 2, k + 9, Blocks.air);
		world.setBlock(i + 4, j + 2, k + 10, Blocks.air);
		world.setBlock(i + 4, j + 2, k + 11, Blocks.air);
		world.setBlock(i + 4, j + 2, k + 12, Blocks.air);
		world.setBlock(i + 4, j + 2, k + 13, Blocks.air);
		world.setBlock(i + 4, j + 2, k + 14, Blocks.air);
		world.setBlock(i + 4, j + 2, k + 15, Blocks.stonebrick);
		world.setBlock(i + 4, j + 3, k + 0, Blocks.stonebrick);
		world.setBlock(i + 4, j + 3, k + 1, Blocks.air);
		world.setBlock(i + 4, j + 3, k + 2, Blocks.air);
		world.setBlock(i + 4, j + 3, k + 3, Blocks.air);
		world.setBlock(i + 4, j + 3, k + 4, Blocks.stonebrick);
		world.setBlock(i + 4, j + 3, k + 5, Blocks.air);
		world.setBlock(i + 4, j + 3, k + 6, Blocks.air);
		world.setBlock(i + 4, j + 3, k + 7, Blocks.air);
		world.setBlock(i + 4, j + 3, k + 8, Blocks.air);
		world.setBlock(i + 4, j + 3, k + 9, Blocks.air);
		world.setBlock(i + 4, j + 3, k + 10, Blocks.air);
		world.setBlock(i + 4, j + 3, k + 11, Blocks.air);
		world.setBlock(i + 4, j + 3, k + 12, Blocks.air);
		world.setBlock(i + 4, j + 3, k + 13, Blocks.air);
		world.setBlock(i + 4, j + 3, k + 14, Blocks.air);
		world.setBlock(i + 4, j + 3, k + 15, Blocks.stonebrick);
		world.setBlock(i + 4, j + 4, k + 0, Blocks.stonebrick);
		world.setBlock(i + 4, j + 4, k + 1, Blocks.stonebrick);
		world.setBlock(i + 4, j + 4, k + 2, Blocks.stonebrick);
		world.setBlock(i + 4, j + 4, k + 3, Blocks.stonebrick);
		world.setBlock(i + 4, j + 4, k + 4, Blocks.stonebrick);
		world.setBlock(i + 4, j + 4, k + 5, Blocks.stonebrick);
		world.setBlock(i + 4, j + 4, k + 6, Blocks.stonebrick);
		world.setBlock(i + 4, j + 4, k + 7, Blocks.stonebrick);
		world.setBlock(i + 4, j + 4, k + 8, Blocks.stonebrick);
		world.setBlock(i + 4, j + 4, k + 9, Blocks.stonebrick);
		world.setBlock(i + 4, j + 4, k + 10, Blocks.stonebrick);
		world.setBlock(i + 4, j + 4, k + 11, Blocks.stonebrick);
		world.setBlock(i + 4, j + 4, k + 12, Blocks.stonebrick);
		world.setBlock(i + 4, j + 4, k + 13, Blocks.stonebrick);
		world.setBlock(i + 4, j + 4, k + 14, Blocks.stonebrick);
		world.setBlock(i + 4, j + 4, k + 15, Blocks.stonebrick);
		world.setBlock(i + 4, j + 5, k + 0, Blocks.stonebrick);
		world.setBlock(i + 4, j + 5, k + 1, Blocks.air);
		world.setBlock(i + 4, j + 5, k + 2, Blocks.air);
		world.setBlock(i + 4, j + 5, k + 3, Blocks.air);
		world.setBlock(i + 4, j + 5, k + 4, Blocks.air);
		world.setBlock(i + 4, j + 5, k + 5, Blocks.air);
		world.setBlock(i + 4, j + 5, k + 6, Blocks.air);
		world.setBlock(i + 4, j + 5, k + 7, Blocks.stonebrick);
		world.setBlock(i + 4, j + 5, k + 8, Blocks.air);
		world.setBlock(i + 4, j + 5, k + 9, Blocks.air);
		world.setBlock(i + 4, j + 5, k + 10, Blocks.air);
		world.setBlock(i + 4, j + 5, k + 11, Blocks.air);
		world.setBlock(i + 4, j + 5, k + 12, Blocks.air);
		world.setBlock(i + 4, j + 5, k + 13, Blocks.air);
		world.setBlock(i + 4, j + 5, k + 14, Blocks.air);
		world.setBlock(i + 4, j + 5, k + 15, Blocks.stonebrick);
		world.setBlock(i + 4, j + 6, k + 0, Blocks.stonebrick);
		world.setBlock(i + 4, j + 6, k + 1, Blocks.air);
		world.setBlock(i + 4, j + 6, k + 2, Blocks.air);
		world.setBlock(i + 4, j + 6, k + 3, Blocks.air);
		world.setBlock(i + 4, j + 6, k + 4, Blocks.air);
		world.setBlock(i + 4, j + 6, k + 5, Blocks.air);
		world.setBlock(i + 4, j + 6, k + 6, Blocks.air);
		world.setBlock(i + 4, j + 6, k + 7, Blocks.stonebrick);
		world.setBlock(i + 4, j + 6, k + 8, Blocks.air);
		world.setBlock(i + 4, j + 6, k + 9, Blocks.air);
		world.setBlock(i + 4, j + 6, k + 10, Blocks.air);
		world.setBlock(i + 4, j + 6, k + 11, Blocks.air);
		world.setBlock(i + 4, j + 6, k + 12, Blocks.air);
		world.setBlock(i + 4, j + 6, k + 13, Blocks.air);
		world.setBlock(i + 4, j + 6, k + 14, Blocks.air);
		world.setBlock(i + 4, j + 6, k + 15, Blocks.stonebrick);
		world.setBlock(i + 4, j + 7, k + 0, Blocks.stonebrick);
		world.setBlock(i + 4, j + 7, k + 1, Blocks.air);
		world.setBlock(i + 4, j + 7, k + 2, Blocks.air);
		world.setBlock(i + 4, j + 7, k + 3, Blocks.air);
		world.setBlock(i + 4, j + 7, k + 4, Blocks.air);
		world.setBlock(i + 4, j + 7, k + 5, Blocks.air);
		world.setBlock(i + 4, j + 7, k + 6, Blocks.air);
		world.setBlock(i + 4, j + 7, k + 7, Blocks.stonebrick);
		world.setBlock(i + 4, j + 7, k + 8, Blocks.air);
		world.setBlock(i + 4, j + 7, k + 9, Blocks.air);
		world.setBlock(i + 4, j + 7, k + 10, Blocks.air);
		world.setBlock(i + 4, j + 7, k + 11, Blocks.air);
		world.setBlock(i + 4, j + 7, k + 12, Blocks.air);
		world.setBlock(i + 4, j + 7, k + 13, Blocks.air);
		world.setBlock(i + 4, j + 7, k + 14, Blocks.air);
		world.setBlock(i + 4, j + 7, k + 15, Blocks.stonebrick);
		world.setBlock(i + 4, j + 8, k + 0, Blocks.stonebrick);
		world.setBlock(i + 4, j + 8, k + 1, Blocks.stonebrick);
		world.setBlock(i + 4, j + 8, k + 2, Blocks.stonebrick);
		world.setBlock(i + 4, j + 8, k + 3, Blocks.stonebrick);
		world.setBlock(i + 4, j + 8, k + 4, Blocks.stonebrick);
		world.setBlock(i + 4, j + 8, k + 5, Blocks.stonebrick);
		world.setBlock(i + 4, j + 8, k + 6, Blocks.stonebrick);
		world.setBlock(i + 4, j + 8, k + 7, Blocks.stonebrick);
		world.setBlock(i + 4, j + 8, k + 8, Blocks.stonebrick);
		world.setBlock(i + 4, j + 8, k + 9, Blocks.stonebrick);
		world.setBlock(i + 4, j + 8, k + 10, Blocks.stonebrick);
		world.setBlock(i + 4, j + 8, k + 11, Blocks.stonebrick);
		world.setBlock(i + 4, j + 8, k + 12, Blocks.stonebrick);
		world.setBlock(i + 4, j + 8, k + 13, Blocks.stonebrick);
		world.setBlock(i + 4, j + 8, k + 14, Blocks.stonebrick);
		world.setBlock(i + 4, j + 8, k + 15, Blocks.stonebrick);
		world.setBlock(i + 4, j + 9, k + 0, Blocks.stonebrick);
		world.setBlock(i + 4, j + 9, k + 1, Blocks.air);
		world.setBlock(i + 4, j + 9, k + 2, Blocks.air);
		world.setBlock(i + 4, j + 9, k + 3, Blocks.air);
		world.setBlock(i + 4, j + 9, k + 4, Blocks.air);
		world.setBlock(i + 4, j + 9, k + 5, Blocks.air);
		world.setBlock(i + 4, j + 9, k + 6, Blocks.air);
		world.setBlock(i + 4, j + 9, k + 7, Blocks.air);
		world.setBlock(i + 4, j + 9, k + 8, Blocks.air);
		world.setBlock(i + 4, j + 9, k + 9, Blocks.air);
		world.setBlock(i + 4, j + 9, k + 10, Blocks.air);
		world.setBlock(i + 4, j + 9, k + 11, Blocks.air);
		world.setBlock(i + 4, j + 9, k + 12, Blocks.air);
		world.setBlock(i + 4, j + 9, k + 13, Blocks.air);
		world.setBlock(i + 4, j + 9, k + 14, Blocks.air);
		
		generate2(world, rand, i, j, k);
		return true;
	}
	
	public boolean generate2(World world, Random rand, int i, int j, int k) {
		world.setBlock(i + 4, j + 9, k + 15, Blocks.stonebrick);
		world.setBlock(i + 4, j + 10, k + 0, Blocks.stonebrick);
		world.setBlock(i + 4, j + 10, k + 1, Blocks.air);
		world.setBlock(i + 4, j + 10, k + 2, Blocks.air);
		world.setBlock(i + 4, j + 10, k + 3, Blocks.air);
		world.setBlock(i + 4, j + 10, k + 4, Blocks.air);
		world.setBlock(i + 4, j + 10, k + 5, Blocks.air);
		world.setBlock(i + 4, j + 10, k + 6, Blocks.air);
		world.setBlock(i + 4, j + 10, k + 7, Blocks.air);
		world.setBlock(i + 4, j + 10, k + 8, Blocks.air);
		world.setBlock(i + 4, j + 10, k + 9, Blocks.air);
		world.setBlock(i + 4, j + 10, k + 10, Blocks.air);
		world.setBlock(i + 4, j + 10, k + 11, Blocks.air);
		world.setBlock(i + 4, j + 10, k + 12, Blocks.air);
		world.setBlock(i + 4, j + 10, k + 13, Blocks.air);
		world.setBlock(i + 4, j + 10, k + 14, Blocks.air);
		world.setBlock(i + 4, j + 10, k + 15, Blocks.stonebrick);
		world.setBlock(i + 4, j + 11, k + 0, Blocks.stonebrick);
		world.setBlock(i + 4, j + 11, k + 1, Blocks.air);
		world.setBlock(i + 4, j + 11, k + 2, Blocks.air);
		world.setBlock(i + 4, j + 11, k + 3, Blocks.air);
		world.setBlock(i + 4, j + 11, k + 4, Blocks.air);
		world.setBlock(i + 4, j + 11, k + 5, Blocks.air);
		world.setBlock(i + 4, j + 11, k + 6, Blocks.air);
		world.setBlock(i + 4, j + 11, k + 7, Blocks.air);
		world.setBlock(i + 4, j + 11, k + 8, Blocks.air);
		world.setBlock(i + 4, j + 11, k + 9, Blocks.air);
		world.setBlock(i + 4, j + 11, k + 10, Blocks.air);
		world.setBlock(i + 4, j + 11, k + 11, Blocks.air);
		world.setBlock(i + 4, j + 11, k + 12, Blocks.air);
		world.setBlock(i + 4, j + 11, k + 13, Blocks.air);
		world.setBlock(i + 4, j + 11, k + 14, Blocks.air);
		world.setBlock(i + 4, j + 11, k + 15, Blocks.stonebrick);
		world.setBlock(i + 4, j + 12, k + 0, Blocks.stonebrick);
		world.setBlock(i + 4, j + 12, k + 1, Blocks.bedrock);
		world.setBlock(i + 4, j + 12, k + 2, Blocks.bedrock);
		world.setBlock(i + 4, j + 12, k + 3, Blocks.bedrock);
		world.setBlock(i + 4, j + 12, k + 4, Blocks.bedrock);
		world.setBlock(i + 4, j + 12, k + 5, Blocks.bedrock);
		world.setBlock(i + 4, j + 12, k + 6, Blocks.bedrock);
		world.setBlock(i + 4, j + 12, k + 7, Blocks.bedrock);
		world.setBlock(i + 4, j + 12, k + 8, Blocks.bedrock);
		world.setBlock(i + 4, j + 12, k + 9, Blocks.bedrock);
		world.setBlock(i + 4, j + 12, k + 10, Blocks.bedrock);
		world.setBlock(i + 4, j + 12, k + 11, Blocks.bedrock);
		world.setBlock(i + 4, j + 12, k + 12, Blocks.bedrock);
		world.setBlock(i + 4, j + 12, k + 13, Blocks.bedrock);
		world.setBlock(i + 4, j + 12, k + 14, Blocks.bedrock);
		world.setBlock(i + 4, j + 12, k + 15, Blocks.stonebrick);
		world.setBlock(i + 4, j + 13, k + 0, Blocks.stonebrick);
		world.setBlock(i + 4, j + 13, k + 1, Blocks.bedrock);
		world.setBlock(i + 4, j + 13, k + 2, Blocks.bedrock);
		world.setBlock(i + 4, j + 13, k + 3, Blocks.bedrock);
		world.setBlock(i + 4, j + 13, k + 4, Blocks.bedrock);
		world.setBlock(i + 4, j + 13, k + 5, Blocks.bedrock);
		world.setBlock(i + 4, j + 13, k + 6, Blocks.bedrock);
		world.setBlock(i + 4, j + 13, k + 7, Blocks.bedrock);
		world.setBlock(i + 4, j + 13, k + 8, Blocks.bedrock);
		world.setBlock(i + 4, j + 13, k + 9, Blocks.bedrock);
		world.setBlock(i + 4, j + 13, k + 11, Blocks.bedrock);
		world.setBlock(i + 4, j + 13, k + 12, Blocks.bedrock);
		world.setBlock(i + 4, j + 13, k + 13, Blocks.bedrock);
		world.setBlock(i + 4, j + 13, k + 14, Blocks.bedrock);
		world.setBlock(i + 4, j + 13, k + 15, Blocks.stonebrick);
		world.setBlock(i + 4, j + 14, k + 0, Blocks.stonebrick);
		world.setBlock(i + 4, j + 14, k + 1, Blocks.bedrock);
		world.setBlock(i + 4, j + 14, k + 2, Blocks.bedrock);
		world.setBlock(i + 4, j + 14, k + 3, Blocks.bedrock);
		world.setBlock(i + 4, j + 14, k + 4, Blocks.bedrock);
		world.setBlock(i + 4, j + 14, k + 5, Blocks.bedrock);
		world.setBlock(i + 4, j + 14, k + 6, Blocks.bedrock);
		world.setBlock(i + 4, j + 14, k + 7, Blocks.bedrock);
		world.setBlock(i + 4, j + 14, k + 8, Blocks.bedrock);
		world.setBlock(i + 4, j + 14, k + 9, Blocks.bedrock);
		world.setBlock(i + 4, j + 14, k + 11, Blocks.bedrock);
		world.setBlock(i + 4, j + 14, k + 12, Blocks.bedrock);
		world.setBlock(i + 4, j + 14, k + 13, Blocks.bedrock);
		world.setBlock(i + 4, j + 14, k + 14, Blocks.bedrock);
		world.setBlock(i + 4, j + 14, k + 15, Blocks.stonebrick);
		world.setBlock(i + 4, j + 15, k + 0, Blocks.stonebrick);
		world.setBlock(i + 4, j + 15, k + 1, Blocks.bedrock);
		world.setBlock(i + 4, j + 15, k + 2, Blocks.bedrock);
		world.setBlock(i + 4, j + 15, k + 3, Blocks.bedrock);
		world.setBlock(i + 4, j + 15, k + 4, Blocks.bedrock);
		world.setBlock(i + 4, j + 15, k + 5, Blocks.bedrock);
		world.setBlock(i + 4, j + 15, k + 6, Blocks.bedrock);
		world.setBlock(i + 4, j + 15, k + 7, Blocks.bedrock);
		world.setBlock(i + 4, j + 15, k + 8, Blocks.bedrock);
		world.setBlock(i + 4, j + 15, k + 9, Blocks.bedrock);
		world.setBlock(i + 4, j + 15, k + 10, Blocks.bedrock);
		world.setBlock(i + 4, j + 15, k + 11, Blocks.bedrock);
		world.setBlock(i + 4, j + 15, k + 12, Blocks.bedrock);
		world.setBlock(i + 4, j + 15, k + 13, Blocks.bedrock);
		world.setBlock(i + 4, j + 15, k + 14, Blocks.bedrock);
		world.setBlock(i + 4, j + 15, k + 15, Blocks.stonebrick);
		world.setBlock(i + 4, j + 16, k + 0, Blocks.stonebrick);
		world.setBlock(i + 4, j + 16, k + 1, Blocks.bedrock);
		world.setBlock(i + 4, j + 16, k + 2, Blocks.bedrock);
		world.setBlock(i + 4, j + 16, k + 3, Blocks.bedrock);
		world.setBlock(i + 4, j + 16, k + 4, Blocks.bedrock);
		world.setBlock(i + 4, j + 16, k + 5, Blocks.bedrock);
		world.setBlock(i + 4, j + 16, k + 6, Blocks.bedrock);
		world.setBlock(i + 4, j + 16, k + 7, Blocks.bedrock);
		world.setBlock(i + 4, j + 16, k + 8, Blocks.bedrock);
		world.setBlock(i + 4, j + 16, k + 9, Blocks.bedrock);
		world.setBlock(i + 4, j + 16, k + 10, Blocks.bedrock);
		world.setBlock(i + 4, j + 16, k + 11, Blocks.bedrock);
		world.setBlock(i + 4, j + 16, k + 12, Blocks.bedrock);
		world.setBlock(i + 4, j + 16, k + 13, Blocks.bedrock);
		world.setBlock(i + 4, j + 16, k + 14, Blocks.bedrock);
		world.setBlock(i + 4, j + 16, k + 15, Blocks.stonebrick);
		world.setBlock(i + 4, j + 17, k + 0, Blocks.stonebrick);
		world.setBlock(i + 4, j + 17, k + 1, Blocks.stonebrick);
		world.setBlock(i + 4, j + 17, k + 2, Blocks.stonebrick);
		world.setBlock(i + 4, j + 17, k + 3, Blocks.stonebrick);
		world.setBlock(i + 4, j + 17, k + 4, Blocks.stonebrick);
		world.setBlock(i + 4, j + 17, k + 5, Blocks.stonebrick);
		world.setBlock(i + 4, j + 17, k + 6, Blocks.stonebrick);
		world.setBlock(i + 4, j + 17, k + 7, Blocks.stonebrick);
		world.setBlock(i + 4, j + 17, k + 8, Blocks.stonebrick);
		world.setBlock(i + 4, j + 17, k + 9, Blocks.stonebrick);
		world.setBlock(i + 4, j + 17, k + 10, Blocks.stonebrick);
		world.setBlock(i + 4, j + 17, k + 11, Blocks.stonebrick);
		world.setBlock(i + 4, j + 17, k + 12, Blocks.stonebrick);
		world.setBlock(i + 4, j + 17, k + 13, Blocks.stonebrick);
		world.setBlock(i + 4, j + 17, k + 14, Blocks.stonebrick);
		world.setBlock(i + 4, j + 17, k + 15, Blocks.stonebrick);
		world.setBlock(i + 4, j + 18, k + 0, Blocks.air);
		world.setBlock(i + 4, j + 18, k + 1, Blocks.air);
		world.setBlock(i + 4, j + 18, k + 2, Blocks.air);
		world.setBlock(i + 4, j + 18, k + 3, Blocks.air);
		world.setBlock(i + 4, j + 18, k + 4, Blocks.air);
		world.setBlock(i + 4, j + 18, k + 5, Blocks.air);
		world.setBlock(i + 4, j + 18, k + 6, Blocks.air);
		world.setBlock(i + 4, j + 18, k + 7, Blocks.air);
		world.setBlock(i + 4, j + 18, k + 8, Blocks.air);
		world.setBlock(i + 4, j + 18, k + 9, Blocks.air);
		world.setBlock(i + 4, j + 18, k + 10, Blocks.air);
		world.setBlock(i + 4, j + 18, k + 11, Blocks.air);
		world.setBlock(i + 4, j + 18, k + 12, Blocks.air);
		world.setBlock(i + 4, j + 18, k + 13, Blocks.air);
		world.setBlock(i + 4, j + 18, k + 14, Blocks.air);
		world.setBlock(i + 4, j + 18, k + 15, Blocks.air);
		world.setBlock(i + 4, j + 19, k + 0, Blocks.air);
		world.setBlock(i + 4, j + 19, k + 1, Blocks.air);
		world.setBlock(i + 4, j + 19, k + 2, Blocks.air);
		world.setBlock(i + 4, j + 19, k + 3, Blocks.air);
		world.setBlock(i + 4, j + 19, k + 4, Blocks.air);
		world.setBlock(i + 4, j + 19, k + 5, Blocks.air);
		world.setBlock(i + 4, j + 19, k + 6, Blocks.air);
		world.setBlock(i + 4, j + 19, k + 7, Blocks.air);
		world.setBlock(i + 4, j + 19, k + 8, Blocks.air);
		world.setBlock(i + 4, j + 19, k + 9, Blocks.air);
		world.setBlock(i + 4, j + 19, k + 10, Blocks.air);
		world.setBlock(i + 4, j + 19, k + 11, Blocks.air);
		world.setBlock(i + 4, j + 19, k + 12, Blocks.air);
		world.setBlock(i + 4, j + 19, k + 13, Blocks.air);
		world.setBlock(i + 4, j + 19, k + 14, Blocks.air);
		world.setBlock(i + 4, j + 19, k + 15, Blocks.air);
		world.setBlock(i + 4, j + 20, k + 0, Blocks.air);
		world.setBlock(i + 4, j + 20, k + 1, Blocks.air);
		world.setBlock(i + 4, j + 20, k + 2, Blocks.air);
		world.setBlock(i + 4, j + 20, k + 3, Blocks.air);
		world.setBlock(i + 4, j + 20, k + 4, Blocks.air);
		world.setBlock(i + 4, j + 20, k + 5, Blocks.air);
		world.setBlock(i + 4, j + 20, k + 6, Blocks.air);
		world.setBlock(i + 4, j + 20, k + 7, Blocks.air);
		world.setBlock(i + 4, j + 20, k + 8, Blocks.air);
		world.setBlock(i + 4, j + 20, k + 9, Blocks.air);
		world.setBlock(i + 4, j + 20, k + 10, Blocks.air);
		world.setBlock(i + 4, j + 20, k + 11, Blocks.air);
		world.setBlock(i + 4, j + 20, k + 12, Blocks.air);
		world.setBlock(i + 4, j + 20, k + 13, Blocks.air);
		world.setBlock(i + 4, j + 20, k + 14, Blocks.air);
		world.setBlock(i + 4, j + 20, k + 15, Blocks.air);
		world.setBlock(i + 5, j + 0, k + 0, Blocks.stonebrick);
		world.setBlock(i + 5, j + 0, k + 1, Blocks.stonebrick);
		world.setBlock(i + 5, j + 0, k + 2, Blocks.stonebrick);
		world.setBlock(i + 5, j + 0, k + 3, Blocks.stonebrick);
		world.setBlock(i + 5, j + 0, k + 4, Blocks.stonebrick);
		world.setBlock(i + 5, j + 0, k + 5, Blocks.stonebrick);
		world.setBlock(i + 5, j + 0, k + 6, Blocks.stonebrick);
		world.setBlock(i + 5, j + 0, k + 7, Blocks.stonebrick);
		world.setBlock(i + 5, j + 0, k + 8, Blocks.stonebrick);
		world.setBlock(i + 5, j + 0, k + 9, Blocks.stonebrick);
		world.setBlock(i + 5, j + 0, k + 10, Blocks.stonebrick);
		world.setBlock(i + 5, j + 0, k + 11, Blocks.stonebrick);
		world.setBlock(i + 5, j + 0, k + 12, Blocks.stonebrick);
		world.setBlock(i + 5, j + 0, k + 13, Blocks.stonebrick);
		world.setBlock(i + 5, j + 0, k + 14, Blocks.stonebrick);
		world.setBlock(i + 5, j + 0, k + 15, Blocks.stonebrick);
		world.setBlock(i + 5, j + 1, k + 0, Blocks.stonebrick);
		world.setBlock(i + 5, j + 1, k + 1, Blocks.air);
		world.setBlock(i + 5, j + 1, k + 2, Blocks.air);
		world.setBlock(i + 5, j + 1, k + 3, Blocks.air);
		world.setBlock(i + 5, j + 1, k + 4, Blocks.stonebrick);
		world.setBlock(i + 5, j + 1, k + 5, Blocks.wool);
		world.setBlock(i + 5, j + 1, k + 6, Blocks.air);
		world.setBlock(i + 5, j + 1, k + 7, Blocks.air);
		world.setBlock(i + 5, j + 1, k + 8, Blocks.air);
		world.setBlock(i + 5, j + 1, k + 9, Blocks.air);
		world.setBlock(i + 5, j + 1, k + 10, Blocks.air);
		world.setBlock(i + 5, j + 1, k + 11, Blocks.air);
		world.setBlock(i + 5, j + 1, k + 12, Blocks.air);
		world.setBlock(i + 5, j + 1, k + 13, Blocks.air);
		world.setBlock(i + 5, j + 1, k + 14, Blocks.air);
		world.setBlock(i + 5, j + 1, k + 15, Blocks.stonebrick);
		world.setBlock(i + 5, j + 2, k + 0, Blocks.stonebrick);
		world.setBlock(i + 5, j + 2, k + 1, Blocks.air);
		world.setBlock(i + 5, j + 2, k + 2, Blocks.air);
		world.setBlock(i + 5, j + 2, k + 3, Blocks.air);
		world.setBlock(i + 5, j + 2, k + 4, Blocks.stonebrick);
		world.setBlock(i + 5, j + 2, k + 5, Blocks.wool);
		world.setBlock(i + 5, j + 2, k + 6, Blocks.air);
		world.setBlock(i + 5, j + 2, k + 7, Blocks.air);
		world.setBlock(i + 5, j + 2, k + 8, Blocks.air);
		world.setBlock(i + 5, j + 2, k + 9, Blocks.air);
		world.setBlock(i + 5, j + 2, k + 10, Blocks.air);
		world.setBlock(i + 5, j + 2, k + 11, Blocks.air);
		world.setBlock(i + 5, j + 2, k + 12, Blocks.air);
		world.setBlock(i + 5, j + 2, k + 13, Blocks.air);
		world.setBlock(i + 5, j + 2, k + 14, Blocks.air);
		world.setBlock(i + 5, j + 2, k + 15, Blocks.stonebrick);
		world.setBlock(i + 5, j + 3, k + 0, Blocks.stonebrick);
		world.setBlock(i + 5, j + 3, k + 1, Blocks.air);
		world.setBlock(i + 5, j + 3, k + 2, Blocks.air);
		world.setBlock(i + 5, j + 3, k + 3, Blocks.air);
		world.setBlock(i + 5, j + 3, k + 4, Blocks.stonebrick);
		world.setBlock(i + 5, j + 3, k + 5, Blocks.wool);
		world.setBlock(i + 5, j + 3, k + 6, Blocks.air);
		world.setBlock(i + 5, j + 3, k + 7, Blocks.air);
		world.setBlock(i + 5, j + 3, k + 8, Blocks.air);
		world.setBlock(i + 5, j + 3, k + 9, Blocks.air);
		world.setBlock(i + 5, j + 3, k + 10, Blocks.air);
		world.setBlock(i + 5, j + 3, k + 11, Blocks.air);
		world.setBlock(i + 5, j + 3, k + 12, Blocks.air);
		world.setBlock(i + 5, j + 3, k + 13, Blocks.air);
		world.setBlock(i + 5, j + 3, k + 14, Blocks.air);
		world.setBlock(i + 5, j + 3, k + 15, Blocks.stonebrick);
		world.setBlock(i + 5, j + 4, k + 0, Blocks.stonebrick);
		world.setBlock(i + 5, j + 4, k + 1, Blocks.stonebrick);
		world.setBlock(i + 5, j + 4, k + 2, Blocks.stonebrick);
		world.setBlock(i + 5, j + 4, k + 3, Blocks.stonebrick);
		world.setBlock(i + 5, j + 4, k + 4, Blocks.stonebrick);
		world.setBlock(i + 5, j + 4, k + 5, Blocks.stonebrick);
		world.setBlock(i + 5, j + 4, k + 6, Blocks.stonebrick);
		world.setBlock(i + 5, j + 4, k + 7, Blocks.stonebrick);
		world.setBlock(i + 5, j + 4, k + 8, Blocks.stonebrick);
		world.setBlock(i + 5, j + 4, k + 9, Blocks.stonebrick);
		world.setBlock(i + 5, j + 4, k + 10, Blocks.stonebrick);
		world.setBlock(i + 5, j + 4, k + 11, Blocks.stonebrick);
		world.setBlock(i + 5, j + 4, k + 12, Blocks.stonebrick);
		world.setBlock(i + 5, j + 4, k + 13, Blocks.stonebrick);
		world.setBlock(i + 5, j + 4, k + 14, Blocks.stonebrick);
		world.setBlock(i + 5, j + 4, k + 15, Blocks.stonebrick);
		world.setBlock(i + 5, j + 5, k + 0, Blocks.stonebrick);
		world.setBlock(i + 5, j + 5, k + 1, Blocks.redstone_block);// MOB
		// SPAWNER
		world.setBlock(i + 5, j + 5, k + 2, Blocks.air);
		world.setBlock(i + 5, j + 5, k + 3, Blocks.air);
		world.setBlock(i + 5, j + 5, k + 4, Blocks.air);
		world.setBlock(i + 5, j + 5, k + 5, Blocks.air);
		world.setBlock(i + 5, j + 5, k + 6, Blocks.air);
		world.setBlock(i + 5, j + 5, k + 7, Blocks.stonebrick);
		world.setBlock(i + 5, j + 5, k + 8, Blocks.air);
		world.setBlock(i + 5, j + 5, k + 9, Blocks.air);
		world.setBlock(i + 5, j + 5, k + 10, Blocks.air);
		world.setBlock(i + 5, j + 5, k + 11, Blocks.air);
		world.setBlock(i + 5, j + 5, k + 12, Blocks.air);
		world.setBlock(i + 5, j + 5, k + 13, Blocks.air);
		world.setBlock(i + 5, j + 5, k + 14, Blocks.air);
		world.setBlock(i + 5, j + 5, k + 15, Blocks.stonebrick);
		world.setBlock(i + 5, j + 6, k + 0, Blocks.stonebrick);
		world.setBlock(i + 5, j + 6, k + 1, Blocks.air);
		world.setBlock(i + 5, j + 6, k + 2, Blocks.air);
		world.setBlock(i + 5, j + 6, k + 3, Blocks.air);
		world.setBlock(i + 5, j + 6, k + 4, Blocks.air);
		world.setBlock(i + 5, j + 6, k + 5, Blocks.air);
		world.setBlock(i + 5, j + 6, k + 6, Blocks.air);
		world.setBlock(i + 5, j + 6, k + 7, Blocks.stonebrick);
		world.setBlock(i + 5, j + 6, k + 8, Blocks.air);
